Workbook

Sheet Entry1
A1: Page # | B1: Year | C1: Date | D1: Team | E1: Site | F1: Block # | G1: Treatment | H1: Point | I1: Transect | J1: Distance | K1: Code | L1: Species | N1: Notes
A2: (#) | B2: 2023 | C2: mm/dd/yy | D2: initials | E2: CU/VB/GB | F2: 43469 | G2: LS/LU/SS/SU | H2: 1-30 | I2: 1 or 2 | J2: 0-12m | K2: six-letter code | L2: full name | N2: enter as written
A3: 1 | B3: 2023 | C3: 45197 | D3: MG, TL | E3: GB | F3: 1 | G3: SS | H3: 1 | I3: 1 | J3: 0 | K3: L | L3: =VLOOKUP(K3, 'Alphabetical by species code'!A:B, 2, FALSE) -> Litter | M3: =VLOOKUP(L3, 'Alphabetical by species code'!B:C, 2, FALSE) -> Ground Cover
A4: 1 | B4: 2023 | C4: 45197 | D4: MG, TL | E4: GB | F4: 1 | G4: SS | H4: 1 | I4: 1 | J4: 0 | K4: STEDIE | L4: =VLOOKUP(K4, 'Alphabetical by species code'!A:B, 2, FALSE) -> Stephanomeria diegensis | M4: =VLOOKUP(L4, 'Alphabetical by species code'!B:C, 2, FALSE) -> Native
A5: 1 | B5: 2023 | C5: 45197 | D5: MG, TL | E5: GB | F5: 1 | G5: SS | H5: 2 | I5: 1 | J5: 1 | K5: L | L5: =VLOOKUP(K5, 'Alphabetical by species code'!A:B, 2, FALSE) -> Litter | M5: =VLOOKUP(L5, 'Alphabetical by species code'!B:C, 2, FALSE) -> Ground Cover
A6: 1 | B6: 2023 | C6: 45197 | D6: MG, TL | E6: GB | F6: 1 | G6: SS | H6: 2 | I6: 1 | J6: 1 | K6: OPULIT | L6: =VLOOKUP(K6, 'Alphabetical by species code'!A:B, 2, FALSE) -> Opuntia littoralis | M6: =VLOOKUP(L6, 'Alphabetical by species code'!B:C, 2, FALSE) -> Native
A7: 1 | B7: 2023 | C7: 45197 | D7: MG, TL | E7: GB | F7: 1 | G7: SS | H7: 2 | I7: 1 | J7: 1 | K7: NNG | L7: =VLOOKUP(K7, 'Alphabetical by species code'!A:B, 2, FALSE) -> Non Native Grass | M7: =VLOOKUP(L7, 'Alphabetical by species code'!B:C, 2, FALSE) -> Non-Native | N7: NNG - non-native grass
A8: 1 | B8: 2023 | C8: 45197 | D8: MG, TL | E8: GB | F8: 1 | G8: SS | H8: 3 | I8: 1 | J8: 1.5 | K8: R | L8: =VLOOKUP(K8, 'Alphabetical by species code'!A:B, 2, FALSE) -> Rock | M8: =VLOOKUP(L8, 'Alphabetical by species code'!B:C, 2, FALSE) -> Ground Cover
A9: 1 | B9: 2023 | C9: 45197 | D9: MG, TL | E9: GB | F9: 1 | G9: SS | H9: 3 | I9: 1 | J9: 1.5 | K9: STEDIE | L9: =VLOOKUP(K9, 'Alphabetical by species code'!A:B, 2, FALSE) -> Stephanomeria diegensis | M9: =VLOOKUP(L9, 'Alphabetical by species code'!B:C, 2, FALSE) -> Native
A10: 1 | B10: 2023 | C10: 45197 | D10: MG, TL | E10: GB | F10: 1 | G10: SS | H10: 4 | I10: 1 | J10: 2 | K10: L | L10: =VLOOKUP(K10, 'Alphabetical by species code'!A:B, 2, FALSE) -> Litter | M10: =VLOOKUP(L10, 'Alphabetical by species code'!B:C, 2, FALSE) -> Ground Cover
A11: 1 | B11: 2023 | C11: 45197 | D11: MG, TL | E11: GB | F11: 1 | G11: SS | H11: 4 | I11: 1 | J11: 2 | K11: STEDIE | L11: =VLOOKUP(K11, 'Alphabetical by species code'!A:B, 2, FALSE) -> Stephanomeria diegensis | M11: =VLOOKUP(L11, 'Alphabetical by species code'!B:C, 2, FALSE) -> Native
A12: 1 | B12: 2023 | C12: 45197 | D12: MG, TL | E12: GB | F12: 1 | G12: SS | H12: 5 | I12: 1 | J12: 3 | K12: R | L12: =VLOOKUP(K12, 'Alphabetical by species code'!A:B, 2, FALSE) -> Rock | M12: =VLOOKUP(L12, 'Alphabetical by species code'!B:C, 2, FALSE) -> Ground Cover
A13: 1 | B13: 2023 | C13: 45197 | D13: MG, TL | E13: GB | F13: 1 | G13: SS | H13: 6 | I13: 1 | J13: 3.5 | K13: R | L13: =VLOOKUP(K13, 'Alphabetical by species code'!A:B, 2, FALSE) -> Rock | M13: =VLOOKUP(L13, 'Alphabetical by species code'!B:C, 2, FALSE) -> Ground Cover
A14: 1 | B14: 2023 | C14: 45197 | D14: MG, TL | E14: GB | F14: 1 | G14: SS | H14: 6 | I14: 1 | J14: 3.5 | K14: NNG | L14: =VLOOKUP(K14, 'Alphabetical by species code'!A:B, 2, FALSE) -> Non Native Grass | M14: =VLOOKUP(L14, 'Alphabetical by species code'!B:C, 2, FALSE) -> Non-Native
A15: 1 | B15: 2023 | C15: 45197 | D15: MG, TL | E15: GB | F15: 1 | G15: SS | H15: 6 | I15: 1 | J15: 3.5 | K15: STEDIE | L15: =VLOOKUP(K15, 'Alphabetical by species code'!A:B, 2, FALSE) -> Stephanomeria diegensis | M15: =VLOOKUP(L15, 'Alphabetical by species code'!B:C, 2, FALSE) -> Native
A16: 1 | B16: 2023 | C16: 45197 | D16: MG, TL | E16: GB | F16: 1 | G16: SS | H16: 7 | I16: 1 | J16: 4 | K16: L | L16: =VLOOKUP(K16, 'Alphabetical by species code'!A:B, 2, FALSE) -> Litter | M16: =VLOOKUP(L16, 'Alphabetical by species code'!B:C, 2, FALSE) -> Ground Cover
A17: 1 | B17: 2023 | C17: 45197 | D17: MG, TL | E17: GB | F17: 1 | G17: SS | H17: 8 | I17: 1 | J17: 5 | K17: L | L17: =VLOOKUP(K17, 'Alphabetical by species code'!A:B, 2, FALSE) -> Litter | M17: =VLOOKUP(L17, 'Alphabetical by species code'!B:C, 2, FALSE) -> Ground Cover
A18: 1 | B18: 2023 | C18: 45197 | D18: MG, TL | E18: GB | F18: 1 | G18: SS | H18: 9 | I18: 1 | J18: 7 | K18: L | L18: =VLOOKUP(K18, 'Alphabetical by species code'!A:B, 2, FALSE) -> Litter | M18: =VLOOKUP(L18, 'Alphabetical by species code'!B:C, 2, FALSE) -> Ground Cover
A19: 1 | B19: 2023 | C19: 45197 | D19: MG, TL | E19: GB | F19: 1 | G19: SS | H19: 9 | I19: 1 | J19: 7 | K19: STEDIE | L19: =VLOOKUP(K19, 'Alphabetical by species code'!A:B, 2, FALSE) -> Stephanomeria diegensis | M19: =VLOOKUP(L19, 'Alphabetical by species code'!B:C, 2, FALSE) -> Native
... A61: 2 | B61: 2023 | C61: 45197 | D61: MG, TL | E61: GB | F61: 1 | G61: SU | H61: 4 | I61: 1 | J61: 2 | K61: STEDIE | L61: =VLOOKUP(K61, 'Alphabetical by species code'!A:B, 2, FALSE) -> Stephanomeria diegensis | M61: =VLOOKUP(L61, 'Alphabetical by species code'!B:C, 2, FALSE) -> Native
A62: 2 | B62: 2023 | C62: 45197 | D62: MG, TL | E62: GB | F62: 1 | G62: SU | H62: 4 | I62: 1 | J62: 2 | K62: EUPFEN | L62: =VLOOKUP(K62, 'Alphabetical by species code'!A:B, 2, FALSE) -> #N/A | M62: =VLOOKUP(L62, 'Alphabetical by species code'!B:C, 2, FALSE) -> #N/A | N62: * TL took photo
A63: 2 | B63: 2023 | C63: 45197 | D63: MG, TL | E63: GB | F63: 1 | G63: SU | H63: 5 | I63: 1 | J63: 3 | K63: L | L63: =VLOOKUP(K63, 'Alphabetical by species code'!A:B, 2, FALSE) -> Litter | M63: =VLOOKUP(L63, 'Alphabetical by species code'!B:C, 2, FALSE) -> Ground Cover
A64: 2 | B64: 2023 | C64: 45197 | D64: MG, TL | E64: GB | F64: 1 | G64: SU | H64: 5 | I64: 1 | J64: 3 | K64: STEDIE | L64: =VLOOKUP(K64, 'Alphabetical by species code'!A:B, 2, FALSE) -> Stephanomeria diegensis | M64: =VLOOKUP(L64, 'Alphabetical by species code'!B:C, 2, FALSE) -> Native
A65: 2 | B65: 2023 | C65: 45197 | D65: MG, TL | E65: GB | F65: 1 | G65: SU | H65: 6 | I65: 1 | J65: 3.5 | K65: L | L65: =VLOOKUP(K65, 'Alphabetical by species code'!A:B, 2, FALSE) -> Litter | M65: =VLOOKUP(L65, 'Alphabetical by species code'!B:C, 2, FALSE) -> Ground Cover
A66: 2 | B66: 2023 | C66: 45197 | D66: MG, TL | E66: GB | F66: 1 | G66: SU | H66: 6 | I66: 1 | J66: 3.5 | K66: EUPFEN | L66: =VLOOKUP(K66, 'Alphabetical by species code'!A:B, 2, FALSE) -> #N/A | M66: =VLOOKUP(L66, 'Alphabetical by species code'!B:C, 2, FALSE) -> #N/A
A67: 2 | B67: 2023 | C67: 45197 | D67: MG, TL | E67: GB | F67: 1 | G67: SU | H67: 7 | I67: 1 | J67: 4 | K67: B | L67: =VLOOKUP(K67, 'Alphabetical by species code'!A:B, 2, FALSE) -> Bareground | M67: =VLOOKUP(L67, 'Alphabetical by species code'!B:C, 2, FALSE) -> Ground Cover
A68: 2 | B68: 2023 | C68: 45197 | D68: MG, TL | E68: GB | F68: 1 | G68: SU | H68: 8 | I68: 1 | J68: 5 | K68: L | L68: =VLOOKUP(K68, 'Alphabetical by species code'!A:B, 2, FALSE) -> Litter | M68: =VLOOKUP(L68, 'Alphabetical by species code'!B:C, 2, FALSE) -> Ground Cover
A69: 2 | B69: 2023 | C69: 45197 | D69: MG, TL | E69: GB | F69: 1 | G69: SU | H69: 8 | I69: 1 | J69: 5 | K69: NNG | L69: =VLOOKUP(K69, 'Alphabetical by species code'!A:B, 2, FALSE) -> Non Native Grass | M69: =VLOOKUP(L69, 'Alphabetical by species code'!B:C, 2, FALSE) -> Non-Native | N69: NNG = non-native grass
A70: 2 | B70: 2023 | C70: 45197 | D70: MG, TL | E70: GB | F70: 1 | G70: SU | H70: 9 | I70: 1 | J70: 7 | K70: L | L70: =VLOOKUP(K70, 'Alphabetical by species code'!A:B, 2, FALSE) -> Litter | M70: =VLOOKUP(L70, 'Alphabetical by species code'!B:C, 2, FALSE) -> Ground Cover
A71: 2 | B71: 2023 | C71: 45197 | D71: MG, TL | E71: GB | F71: 1 | G71: SU | H71: 9 | I71: 1 | J71: 7 | K71: STEDIE | L71: =VLOOKUP(K71, 'Alphabetical by species code'!A:B, 2, FALSE) -> Stephanomeria diegensis | M71: =VLOOKUP(L71, 'Alphabetical by species code'!B:C, 2, FALSE) -> Native
A72: 2 | B72: 2023 | C72: 45197 | D72: MG, TL | E72: GB | F72: 1 | G72: SU | H72: 10 | I72: 1 | J72: 8 | K72: L | L72: =VLOOKUP(K72, 'Alphabetical by species code'!A:B, 2, FALSE) -> Litter | M72: =VLOOKUP(L72, 'Alphabetical by species code'!B:C, 2, FALSE) -> Ground Cover
A73: 2 | B73: 2023 | C73: 45197 | D73: MG, TL | E73: GB | F73: 1 | G73: SU | H73: 11 | I73: 1 | J73: 8.5 | K73: L | L73: =VLOOKUP(K73, 'Alphabetical by species code'!A:B, 2, FALSE) -> Litter | M73: =VLOOKUP(L73, 'Alphabetical by species code'!B:C, 2, FALSE) -> Ground Cover
A74: 2 | B74: 2023 | C74: 45197 | D74: MG, TL | E74: GB | F74: 1 | G74: SU | H74: 11 | I74: 1 | J74: 8.5 | K74: STEDIE | L74: =VLOOKUP(K74, 'Alphabetical by species code'!A:B, 2, FALSE) -> Stephanomeria diegensis | M74: =VLOOKUP(L74, 'Alphabetical by species code'!B:C, 2, FALSE) -> Native
A75: 2 | B75: 2023 | C75: 45197 | D75: MG, TL | E75: GB | F75: 1 | G75: SU | H75: 12 | I75: 1 | J75: 9 | K75: L | L75: =VLOOKUP(K75, 'Alphabetical by species code'!A:B, 2, FALSE) -> Litter | M75: =VLOOKUP(L75, 'Alphabetical by species code'!B:C, 2, FALSE) -> Ground Cover
A76: 2 | B76: 2023 | C76: 45197 | D76: MG, TL | E76: GB | F76: 1 | G76: SU | H76: 12 | I76: 1 | J76: 9 | K76: EUPMAC | L76: =VLOOKUP(K76, 'Alphabetical by species code'!A:B, 2, FALSE) -> #N/A | M76: =VLOOKUP(L76, 'Alphabetical by species code'!B:C, 2, FALSE) -> #N/A | N76: * Euphorbia maculata
A77: 2 | B77: 2023 | C77: 45197 | D77: MG, TL | E77: GB | F77: 1 | G77: SU | H77: 13 | I77: 1 | J77: 10 | K77: B | L77: =VLOOKUP(K77, 'Alphabetical by species code'!A:B, 2, FALSE) -> Bareground | M77: =VLOOKUP(L77, 'Alphabetical by species code'!B:C, 2, FALSE) -> Ground Cover
A78: 2 | B78: 2023 | C78: 45197 | D78: MG, TL | E78: GB | F78: 1 | G78: SU | H78: 13 | I78: 1 | J78: 10 | K78: MALLAU | L78: =VLOOKUP(K78, 'Alphabetical by species code'!A:B, 2, FALSE) -> Malosma laurina | M78: =VLOOKUP(L78, 'Alphabetical by species code'!B:C, 2, FALSE) -> Native
A79: 2 | B79: 2023 | C79: 45197 | D79: MG, TL | E79: GB | F79: 1 | G79: SU | H79: 14 | I79: 1 | J79: 11 | K79: B | L79: =VLOOKUP(K79, 'Alphabetical by species code'!A:B, 2, FALSE) -> Bareground | M79: =VLOOKUP(L79, 'Alphabetical by species code'!B:C, 2, FALSE) -> Ground Cover
A80: 2 | B80: 2023 | C80: 45197 | D80: MG, TL | E80: GB | F80: 1 | G80: SU | H80: 15 | I80: 1 | J80: 12 | K80: L | L80: =VLOOKUP(K80, 'Alphabetical by species code'!A:B, 2, FALSE) -> Litter | M80: =VLOOKUP(L80, 'Alphabetical by species code'!B:C, 2, FALSE) -> Ground Cover
A81: 2 | B81: 2023 | C81: 45197 | D81: MG, TL | E81: GB | F81: 1 | G81: SU | H81: 1 | I81: 2 | J81: 0 | K81: B | L81: =VLOOKUP(K81, 'Alphabetical by species code'!A:B, 2, FALSE) -> Bareground | M81: =VLOOKUP(L81, 'Alphabetical by species code'!B:C, 2, FALSE) -> Ground Cover
...

Sheet Entry2
A1: Page # | B1: Year | C1: Date | D1: Team | E1: Site | F1: Block # | G1: Treatment | H1: Point | I1: Transect | J1: Distance | K1: Code | L1: Species | M1: Notes
A2: (#) | B2: 2023 | C2: mm/dd/yy | D2: initials | E2: CU/VB/GB | F2: 43469 | G2: LS/LU/SS/SU | H2: 1-30 | I2: 1 or 2 | J2: 0-12m | K2: six-letter code | L2: full name | M2: enter as written
A3: 1 | B3: 2023 | C3: 45197 | D3: MG, TL | E3: GB | F3: 1 | G3: SS | H3: 1 | I3: 1 | J3: 0 | K3: L
A4: 1 | B4: 2023 | C4: 45197 | D4: MG, TL | E4: GB | F4: 1 | G4: SS | H4: 1 | I4: 1 | J4: 0 | K4: STEDIE
A5: 1 | B5: 2023 | C5: 45197 | D5: MG, TL | E5: GB | F5: 1 | G5: SS | H5: 2 | I5: 1 | J5: 1 | K5: L
A6: 1 | B6: 2023 | C6: 45197 | D6: MG, TL | E6: GB | F6: 1 | G6: SS | H6: 2 | I6: 1 | J6: 1 | K6: OPULIT
A7: 1 | B7: 2023 | C7: 45197 | D7: MG, TL | E7: GB | F7: 1 | G7: SS | H7: 2 | I7: 1 | J7: 1 | K7: NNG | M7: NNG - non-native grass
A8: 1 | B8: 2023 | C8: 45197 | D8: MG, TL | E8: GB | F8: 1 | G8: SS | H8: 3 | I8: 1 | J8: 1.5 | K8: R
A9: 1 | B9: 2023 | C9: 45197 | D9: MG, TL | E9: GB | F9: 1 | G9: SS | H9: 3 | I9: 1 | J9: 1.5 | K9: STEDIE
A10: 1 | B10: 2023 | C10: 45197 | D10: MG, TL | E10: GB | F10: 1 | G10: SS | H10: 4 | I10: 1 | J10: 2 | K10: L
A11: 1 | B11: 2023 | C11: 45197 | D11: MG, TL | E11: GB | F11: 1 | G11: SS | H11: 4 | I11: 1 | J11: 2 | K11: STEDIE
A12: 1 | B12: 2023 | C12: 45197 | D12: MG, TL | E12: GB | F12: 1 | G12: SS | H12: 5 | I12: 1 | J12: 3 | K12: R
A13: 1 | B13: 2023 | C13: 45197 | D13: MG, TL | E13: GB | F13: 1 | G13: SS | H13: 6 | I13: 1 | J13: 3.5 | K13: R
A14: 1 | B14: 2023 | C14: 45197 | D14: MG, TL | E14: GB | F14: 1 | G14: SS | H14: 6 | I14: 1 | J14: 3.5 | K14: NNG
A15: 1 | B15: 2023 | C15: 45197 | D15: MG, TL | E15: GB | F15: 1 | G15: SS | H15: 6 | I15: 1 | J15: 3.5 | K15: STEDIE
A16: 1 | B16: 2023 | C16: 45197 | D16: MG, TL | E16: GB | F16: 1 | G16: SS | H16: 7 | I16: 1 | J16: 4 | K16: L
A17: 1 | B17: 2023 | C17: 45197 | D17: MG, TL | E17: GB | F17: 1 | G17: SS | H17: 8 | I17: 1 | J17: 5 | K17: L
A18: 1 | B18: 2023 | C18: 45197 | D18: MG, TL | E18: GB | F18: 1 | G18: SS | H18: 9 | I18: 1 | J18: 7 | K18: L
A19: 1 | B19: 2023 | C19: 45197 | D19: MG, TL | E19: GB | F19: 1 | G19: SS | H19: 9 | I19: 1 | J19: 7 | K19: STEDIE
... A61: 2 | B61: 2023 | C61: 45197 | D61: MG, TL | E61: GB | F61: 1 | G61: SU | H61: 4 | I61: 1 | J61: 2 | K61: STEDIE
A62: 2 | B62: 2023 | C62: 45197 | D62: MG, TL | E62: GB | F62: 1 | G62: SU | H62: 4 | I62: 1 | J62: 2 | K62: EUPFEN | M62: TL took photo
A63: 2 | B63: 2023 | C63: 45197 | D63: MG, TL | E63: GB | F63: 1 | G63: SU | H63: 5 | I63: 1 | J63: 3 | K63: L
A64: 2 | B64: 2023 | C64: 45197 | D64: MG, TL | E64: GB | F64: 1 | G64: SU | H64: 5 | I64: 1 | J64: 3 | K64: STEDIE
A65: 2 | B65: 2023 | C65: 45197 | D65: MG, TL | E65: GB | F65: 1 | G65: SU | H65: 6 | I65: 1 | J65: 3.5 | K65: L
A66: 2 | B66: 2023 | C66: 45197 | D66: MG, TL | E66: GB | F66: 1 | G66: SU | H66: 6 | I66: 1 | J66: 3.5 | K66: EUPFEN
A67: 2 | B67: 2023 | C67: 45197 | D67: MG, TL | E67: GB | F67: 1 | G67: SU | H67: 7 | I67: 1 | J67: 4 | K67: B
A68: 2 | B68: 2023 | C68: 45197 | D68: MG, TL | E68: GB | F68: 1 | G68: SU | H68: 8 | I68: 1 | J68: 5 | K68: L
A69: 2 | B69: 2023 | C69: 45197 | D69: MG, TL | E69: GB | F69: 1 | G69: SU | H69: 8 | I69: 1 | J69: 5 | K69: NNG | M69: non native grass
A70: 2 | B70: 2023 | C70: 45197 | D70: MG, TL | E70: GB | F70: 1 | G70: SU | H70: 9 | I70: 1 | J70: 7 | K70: L
A71: 2 | B71: 2023 | C71: 45197 | D71: MG, TL | E71: GB | F71: 1 | G71: SU | H71: 9 | I71: 1 | J71: 7 | K71: STEDIE
A72: 2 | B72: 2023 | C72: 45197 | D72: MG, TL | E72: GB | F72: 1 | G72: SU | H72: 10 | I72: 1 | J72: 8 | K72: L
A73: 2 | B73: 2023 | C73: 45197 | D73: MG, TL | E73: GB | F73: 1 | G73: SU | H73: 11 | I73: 1 | J73: 8.5 | K73: L
A74: 2 | B74: 2023 | C74: 45197 | D74: MG, TL | E74: GB | F74: 1 | G74: SU | H74: 11 | I74: 1 | J74: 8.5 | K74: STEDIE
A75: 2 | B75: 2023 | C75: 45197 | D75: MG, TL | E75: GB | F75: 1 | G75: SU | H75: 12 | I75: 1 | J75: 9 | K75: L
A76: 2 | B76: 2023 | C76: 45197 | D76: MG, TL | E76: GB | F76: 1 | G76: SU | H76: 12 | I76: 1 | J76: 9 | K76: EUPMAC | M76: euphorbia masculata?
A77: 2 | B77: 2023 | C77: 45197 | D77: MG, TL | E77: GB | F77: 1 | G77: SU | H77: 13 | I77: 1 | J77: 10 | K77: B
A78: 2 | B78: 2023 | C78: 45197 | D78: MG, TL | E78: GB | F78: 1 | G78: SU | H78: 13 | I78: 1 | J78: 10 | K78: MALLAU
A79: 2 | B79: 2023 | C79: 45197 | D79: MG, TL | E79: GB | F79: 1 | G79: SU | H79: 14 | I79: 1 | J79: 11 | K79: B
A80: 2 | B80: 2023 | C80: 45197 | D80: MG, TL | E80: GB | F80: 1 | G80: SU | H80: 15 | I80: 1 | J80: 12 | K80: L
A81: 2 | B81: 2023 | C81: 45197 | D81: MG, TL | E81: GB | F81: 1 | G81: SU | H81: 1 | I81: 2 | J81: 0 | K81: B
...

Sheet Data Validation
A1: Page # | B1: Year | C1: Date | D1: Team | E1: Site | F1: Block # | G1: Treatment | H1: Point | I1: Transect | J1: Distance | K1: Code | L1: Species | M1: Notes
A2: (#) | B2: 2023 | C2: mm/dd/yy | D2: initials | E2: CU/VB/GB | F2: 43469 | G2: LS/LU/SS/SU | H2: 1-30 | I2: 1 or 2 | J2: 0-12m | K2: six-letter code | L2: full name | M2: enter as written
A3: =if(Entry1!A3=Entry2!A3,Entry1!A3,"ERROR") -> 1 | B3: =if(Entry1!B3=Entry2!B3,Entry1!B3,"ERROR") -> 2023 | C3: =if(Entry1!C3=Entry2!C3,Entry1!C3,"ERROR") -> 45197 | D3: =if(Entry1!D3=Entry2!D3,Entry1!D3,"ERROR") -> MG, TL | E3: =if(Entry1!E3=Entry2!E3,Entry1!E3,"ERROR") -> GB | F3: =if(Entry1!F3=Entry2!F3,Entry1!F3,"ERROR") -> 1 | G3: =if(Entry1!G3=Entry2!G3,Entry1!G3,"ERROR") -> SS | H3: =if(Entry1!H3=Entry2!H3,Entry1!H3,"ERROR") -> 1 | ... L3: =if(Entry1!L3=Entry2!L3,Entry1!L3,"ERROR") -> ERROR | M3: =if(Entry1!N3=Entry2!M3,Entry1!N3,"ERROR")
A4: =if(Entry1!A4=Entry2!A4,Entry1!A4,"ERROR") -> 1 | B4: =if(Entry1!B4=Entry2!B4,Entry1!B4,"ERROR") -> 2023 | C4: =if(Entry1!C4=Entry2!C4,Entry1!C4,"ERROR") -> 45197 | D4: =if(Entry1!D4=Entry2!D4,Entry1!D4,"ERROR") -> MG, TL | E4: =if(Entry1!E4=Entry2!E4,Entry1!E4,"ERROR") -> GB | F4: =if(Entry1!F4=Entry2!F4,Entry1!F4,"ERROR") -> 1 | G4: =if(Entry1!G4=Entry2!G4,Entry1!G4,"ERROR") -> SS | H4: =if(Entry1!H4=Entry2!H4,Entry1!H4,"ERROR") -> 1 | ... L4: =if(Entry1!L4=Entry2!L4,Entry1!L4,"ERROR") -> ERROR | M4: =if(Entry1!N4=Entry2!M4,Entry1!N4,"ERROR")
A5: =if(Entry1!A5=Entry2!A5,Entry1!A5,"ERROR") -> 1 | B5: =if(Entry1!B5=Entry2!B5,Entry1!B5,"ERROR") -> 2023 | C5: =if(Entry1!C5=Entry2!C5,Entry1!C5,"ERROR") -> 45197 | D5: =if(Entry1!D5=Entry2!D5,Entry1!D5,"ERROR") -> MG, TL | E5: =if(Entry1!E5=Entry2!E5,Entry1!E5,"ERROR") -> GB | F5: =if(Entry1!F5=Entry2!F5,Entry1!F5,"ERROR") -> 1 | G5: =if(Entry1!G5=Entry2!G5,Entry1!G5,"ERROR") -> SS | H5: =if(Entry1!H5=Entry2!H5,Entry1!H5,"ERROR") -> 2 | ... L5: =if(Entry1!L5=Entry2!L5,Entry1!L5,"ERROR") -> ERROR | M5: =if(Entry1!N5=Entry2!M5,Entry1!N5,"ERROR")
A6: =if(Entry1!A6=Entry2!A6,Entry1!A6,"ERROR") -> 1 | B6: =if(Entry1!B6=Entry2!B6,Entry1!B6,"ERROR") -> 2023 | C6: =if(Entry1!C6=Entry2!C6,Entry1!C6,"ERROR") -> 45197 | D6: =if(Entry1!D6=Entry2!D6,Entry1!D6,"ERROR") -> MG, TL | E6: =if(Entry1!E6=Entry2!E6,Entry1!E6,"ERROR") -> GB | F6: =if(Entry1!F6=Entry2!F6,Entry1!F6,"ERROR") -> 1 | G6: =if(Entry1!G6=Entry2!G6,Entry1!G6,"ERROR") -> SS | H6: =if(Entry1!H6=Entry2!H6,Entry1!H6,"ERROR") -> 2 | ... L6: =if(Entry1!L6=Entry2!L6,Entry1!L6,"ERROR") -> ERROR | M6: =if(Entry1!N6=Entry2!M6,Entry1!N6,"ERROR")
A7: =if(Entry1!A7=Entry2!A7,Entry1!A7,"ERROR") -> 1 | B7: =if(Entry1!B7=Entry2!B7,Entry1!B7,"ERROR") -> 2023 | C7: =if(Entry1!C7=Entry2!C7,Entry1!C7,"ERROR") -> 45197 | D7: =if(Entry1!D7=Entry2!D7,Entry1!D7,"ERROR") -> MG, TL | E7: =if(Entry1!E7=Entry2!E7,Entry1!E7,"ERROR") -> GB | F7: =if(Entry1!F7=Entry2!F7,Entry1!F7,"ERROR") -> 1 | G7: =if(Entry1!G7=Entry2!G7,Entry1!G7,"ERROR") -> SS | H7: =if(Entry1!H7=Entry2!H7,Entry1!H7,"ERROR") -> 2 | ... L7: =if(Entry1!L7=Entry2!L7,Entry1!L7,"ERROR") -> ERROR | M7: =if(Entry1!N7=Entry2!M7,Entry1!N7,"ERROR") -> NNG - non-native grass
A8: =if(Entry1!A8=Entry2!A8,Entry1!A8,"ERROR") -> 1 | B8: =if(Entry1!B8=Entry2!B8,Entry1!B8,"ERROR") -> 2023 | C8: =if(Entry1!C8=Entry2!C8,Entry1!C8,"ERROR") -> 45197 | D8: =if(Entry1!D8=Entry2!D8,Entry1!D8,"ERROR") -> MG, TL | E8: =if(Entry1!E8=Entry2!E8,Entry1!E8,"ERROR") -> GB | F8: =if(Entry1!F8=Entry2!F8,Entry1!F8,"ERROR") -> 1 | G8: =if(Entry1!G8=Entry2!G8,Entry1!G8,"ERROR") -> SS | H8: =if(Entry1!H8=Entry2!H8,Entry1!H8,"ERROR") -> 3 | ... L8: =if(Entry1!L8=Entry2!L8,Entry1!L8,"ERROR") -> ERROR | M8: =if(Entry1!N8=Entry2!M8,Entry1!N8,"ERROR")
A9: =if(Entry1!A9=Entry2!A9,Entry1!A9,"ERROR") -> 1 | B9: =if(Entry1!B9=Entry2!B9,Entry1!B9,"ERROR") -> 2023 | C9: =if(Entry1!C9=Entry2!C9,Entry1!C9,"ERROR") -> 45197 | D9: =if(Entry1!D9=Entry2!D9,Entry1!D9,"ERROR") -> MG, TL | E9: =if(Entry1!E9=Entry2!E9,Entry1!E9,"ERROR") -> GB | F9: =if(Entry1!F9=Entry2!F9,Entry1!F9,"ERROR") -> 1 | G9: =if(Entry1!G9=Entry2!G9,Entry1!G9,"ERROR") -> SS | H9: =if(Entry1!H9=Entry2!H9,Entry1!H9,"ERROR") -> 3 | ... L9: =if(Entry1!L9=Entry2!L9,Entry1!L9,"ERROR") -> ERROR | M9: =if(Entry1!N9=Entry2!M9,Entry1!N9,"ERROR")
A10: =if(Entry1!A10=Entry2!A10,Entry1!A10,"ERROR") -> 1 | B10: =if(Entry1!B10=Entry2!B10,Entry1!B10,"ERROR") -> 2023 | C10: =if(Entry1!C10=Entry2!C10,Entry1!C10,"ERROR") -> 45197 | D10: =if(Entry1!D10=Entry2!D10,Entry1!D10,"ERROR") -> MG, TL | E10: =if(Entry1!E10=Entry2!E10,Entry1!E10,"ERROR") -> GB | F10: =if(Entry1!F10=Entry2!F10,Entry1!F10,"ERROR") -> 1 | G10: =if(Entry1!G10=Entry2!G10,Entry1!G10,"ERROR") -> SS | H10: =if(Entry1!H10=Entry2!H10,Entry1!H10,"ERROR") -> 4 | ... L10: =if(Entry1!L10=Entry2!L10,Entry1!L10,"ERROR") -> ERROR | M10: =if(Entry1!N10=Entry2!M10,Entry1!N10,"ERROR")
A11: =if(Entry1!A11=Entry2!A11,Entry1!A11,"ERROR") -> 1 | B11: =if(Entry1!B11=Entry2!B11,Entry1!B11,"ERROR") -> 2023 | C11: =if(Entry1!C11=Entry2!C11,Entry1!C11,"ERROR") -> 45197 | D11: =if(Entry1!D11=Entry2!D11,Entry1!D11,"ERROR") -> MG, TL | E11: =if(Entry1!E11=Entry2!E11,Entry1!E11,"ERROR") -> GB | F11: =if(Entry1!F11=Entry2!F11,Entry1!F11,"ERROR") -> 1 | G11: =if(Entry1!G11=Entry2!G11,Entry1!G11,"ERROR") -> SS | H11: =if(Entry1!H11=Entry2!H11,Entry1!H11,"ERROR") -> 4 | ... L11: =if(Entry1!L11=Entry2!L11,Entry1!L11,"ERROR") -> ERROR | M11: =if(Entry1!N11=Entry2!M11,Entry1!N11,"ERROR")
A12: =if(Entry1!A12=Entry2!A12,Entry1!A12,"ERROR") -> 1 | B12: =if(Entry1!B12=Entry2!B12,Entry1!B12,"ERROR") -> 2023 | C12: =if(Entry1!C12=Entry2!C12,Entry1!C12,"ERROR") -> 45197 | D12: =if(Entry1!D12=Entry2!D12,Entry1!D12,"ERROR") -> MG, TL | E12: =if(Entry1!E12=Entry2!E12,Entry1!E12,"ERROR") -> GB | F12: =if(Entry1!F12=Entry2!F12,Entry1!F12,"ERROR") -> 1 | G12: =if(Entry1!G12=Entry2!G12,Entry1!G12,"ERROR") -> SS | H12: =if(Entry1!H12=Entry2!H12,Entry1!H12,"ERROR") -> 5 | ... L12: =if(Entry1!L12=Entry2!L12,Entry1!L12,"ERROR") -> ERROR | M12: =if(Entry1!N12=Entry2!M12,Entry1!N12,"ERROR")
A13: =if(Entry1!A13=Entry2!A13,Entry1!A13,"ERROR") -> 1 | B13: =if(Entry1!B13=Entry2!B13,Entry1!B13,"ERROR") -> 2023 | C13: =if(Entry1!C13=Entry2!C13,Entry1!C13,"ERROR") -> 45197 | D13: =if(Entry1!D13=Entry2!D13,Entry1!D13,"ERROR") -> MG, TL | E13: =if(Entry1!E13=Entry2!E13,Entry1!E13,"ERROR") -> GB | F13: =if(Entry1!F13=Entry2!F13,Entry1!F13,"ERROR") -> 1 | G13: =if(Entry1!G13=Entry2!G13,Entry1!G13,"ERROR") -> SS | H13: =if(Entry1!H13=Entry2!H13,Entry1!H13,"ERROR") -> 6 | ... L13: =if(Entry1!L13=Entry2!L13,Entry1!L13,"ERROR") -> ERROR | M13: =if(Entry1!N13=Entry2!M13,Entry1!N13,"ERROR")
A14: =if(Entry1!A14=Entry2!A14,Entry1!A14,"ERROR") -> 1 | B14: =if(Entry1!B14=Entry2!B14,Entry1!B14,"ERROR") -> 2023 | C14: =if(Entry1!C14=Entry2!C14,Entry1!C14,"ERROR") -> 45197 | D14: =if(Entry1!D14=Entry2!D14,Entry1!D14,"ERROR") -> MG, TL | E14: =if(Entry1!E14=Entry2!E14,Entry1!E14,"ERROR") -> GB | F14: =if(Entry1!F14=Entry2!F14,Entry1!F14,"ERROR") -> 1 | G14: =if(Entry1!G14=Entry2!G14,Entry1!G14,"ERROR") -> SS | H14: =if(Entry1!H14=Entry2!H14,Entry1!H14,"ERROR") -> 6 | ... L14: =if(Entry1!L14=Entry2!L14,Entry1!L14,"ERROR") -> ERROR | M14: =if(Entry1!N14=Entry2!M14,Entry1!N14,"ERROR")
... A978: =if(Entry1!A978=Entry2!A978,Entry1!A978,"ERROR") -> 20 | B978: =if(Entry1!B978=Entry2!B978,Entry1!B978,"ERROR") -> 2023 | C978: =if(Entry1!C978=Entry2!C978,Entry1!C978,"ERROR") -> 45197 | D978: =if(Entry1!D978=Entry2!D978,Entry1!D978,"ERROR") -> MP, TL | E978: =if(Entry1!E978=Entry2!E978,Entry1!E978,"ERROR") -> VB | F978: =if(Entry1!F978=Entry2!F978,Entry1!F978,"ERROR") -> 1 | G978: =if(Entry1!G978=Entry2!G978,Entry1!G978,"ERROR") -> LU | H978: =if(Entry1!H978=Entry2!H978,Entry1!H978,"ERROR") -> 8 | ... L978: =if(Entry1!L978=Entry2!L978,Entry1!L978,"ERROR") -> ERROR | M978: =if(Entry1!N978=Entry2!M978,Entry1!N978,"ERROR")
A979: =if(Entry1!A1038=Entry2!A986,Entry1!A1038,"ERROR") | B979: =if(Entry1!B1038=Entry2!B986,Entry1!B1038,"ERROR") | C979: =if(Entry1!C1038=Entry2!C986,Entry1!C1038,"ERROR") | D979: =if(Entry1!D1038=Entry2!D986,Entry1!D1038,"ERROR") | E979: =if(Entry1!E1038=Entry2!E986,Entry1!E1038,"ERROR") | F979: =if(Entry1!F1038=Entry2!F986,Entry1!F1038,"ERROR") | G979: =if(Entry1!G1038=Entry2!G986,Entry1!G1038,"ERROR") | H979: =if(Entry1!H1038=Entry2!H986,Entry1!H1038,"ERROR") | ... K979: =if(Entry1!K1038=Entry2!K986,Entry1!K1038,"ERROR") | L979: =if(Entry1!L1038=Entry2!L985,Entry1!L1038,"ERROR") | M979: =if(Entry1!N1038=Entry2!M985,Entry1!N1038,"ERROR")

Sheet Example Data
A1: Page # | B1: Year | C1: Date | D1: Team | E1: Site | F1: Block # | G1: Treatment | H1: Point | I1: Transect | J1: Distance | K1: Code | L1: Species | M1: Notes
A2: (#) | B2: 2023 | C2: mm/dd/yy | D2: initials | E2: CU/VB/GB | F2: 43469 | G2: LS/LU/SS/SU | H2: 1-30 | I2: 1 or 2 | J2: 0-12m | K2: six-letter code | L2: full name | M2: enter as written
A3: 1 | B3: 2023 | C3: 45197 | D3: MG, TL | E3: GB | F3: 1 | G3: SS | H3: 1 | I3: 1 | J3: 0 | K3: L
A4: 1 | B4: 2023 | C4: 45197 | D4: MG, TL | E4: GB | F4: 1 | G4: SS | H4: 1 | I4: 1 | J4: 0 | K4: STEDIE
A5: 1 | B5: 2023 | C5: 45197 | D5: MG, TL | E5: GB | F5: 1 | G5: SS | H5: 2 | I5: 1 | J5: 1 | K5: L
A6: 1 | B6: 2023 | C6: 45197 | D6: MG, TL | E6: GB | F6: 1 | G6: SS | H6: 2 | I6: 1 | J6: 1 | K6: OPULIT
A7: 1 | B7: 2023 | C7: 45197 | D7: MG, TL | E7: GB | F7: 1 | G7: SS | H7: 2 | I7: 1 | J7: 1 | K7: NNG | M7: NNG - non-native grass
A8: 1 | B8: 2023 | C8: 45197 | D8: MG, TL | E8: GB | F8: 1 | G8: SS | H8: 3 | I8: 1 | J8: 1.5 | K8: R
A9: 1 | B9: 2023 | C9: 45197 | D9: MG, TL | E9: GB | F9: 1 | G9: SS | H9: 3 | I9: 1 | J9: 1.5 | K9: STEDIE
A10: 1 | B10: 2023 | C10: 45197 | D10: MG, TL | E10: GB | F10: 1 | G10: SS | H10: 4 | I10: 1 | J10: 2 | K10: L
A11: 1 | B11: 2023 | C11: 45197 | D11: MG, TL | E11: GB | F11: 1 | G11: SS | H11: 4 | I11: 1 | J11: 2 | K11: STEDIE
A12: 1 | B12: 2023 | C12: 45197 | D12: MG, TL | E12: GB | F12: 1 | G12: SS | H12: 5 | I12: 1 | J12: 3 | K12: R
A13: 1 | B13: 2023 | C13: 45197 | D13: MG, TL | E13: GB | F13: 1 | G13: SS | H13: 6 | I13: 1 | J13: 3.5 | K13: R
A14: 1 | B14: 2023 | C14: 45197 | D14: MG, TL | E14: GB | F14: 1 | G14: SS | H14: 6 | I14: 1 | J14: 3.5 | K14: NNG
A15: 1 | B15: 2023 | C15: 45197 | D15: MG, TL | E15: GB | F15: 1 | G15: SS | H15: 6 | I15: 1 | J15: 3.5 | K15: STEDIE
A16: 1 | B16: 2023 | C16: 45197 | D16: MG, TL | E16: GB | F16: 1 | G16: SS | H16: 7 | I16: 1 | J16: 4 | K16: L
A17: 1 | B17: 2023 | C17: 45197 | D17: MG, TL | E17: GB | F17: 1 | G17: SS | H17: 8 | I17: 1 | J17: 5 | K17: L
A18: 1 | B18: 2023 | C18: 45197 | D18: MG, TL | E18: GB | F18: 1 | G18: SS | H18: 9 | I18: 1 | J18: 7 | K18: L
A19: 1 | B19: 2023 | C19: 45197 | D19: MG, TL | E19: GB | F19: 1 | G19: SS | H19: 9 | I19: 1 | J19: 7 | K19: STEDIE
... A52: 1 | B52: 2023 | C52: 45197 | D52: MG, TL | E52: GB | F52: 1 | G52: SS | H52: 15 | I52: 2 | J52: 12 | K52: L

Sheet Species List
A1: AMAALB
A2: B | B2: Bare ground
A3: C | B3: Cryptobiotic crust
A4: CALMAC | B4: Calystegia macrostegia
A5: CYLPRO | B5: Cylindropuntia prolifera
A6: ERIFAS | B6: Eriogonum fasciculatum
A7: F | B7: Fine woody debris
A8: L | B8: Litter
A9: LAECOU | B9: Laennecia coulteri
A10: M | B10: Moss
A11: OPULIT | B11: Opuntia littoralis
A12: PSECAL | B12: Pseudognaphalium californicum
A13: R | B13: Rock
... A17: W | B17: Coarse woody debris

Sheet Alphabetical by species code
A1: Species Code (A-Z) | B1: Full Scientific Name (Genus species) | C1: Native/Non-Native | D1: Common Name | E1: other scientific names | F1: Plant Family
A2: . | B2: . | C2: . | D2: . | E2: . | F2: .
A3: ACHMIL | B3: Achillea millefolium | C3: Native | D3: Yarrow | E3: . | F3: Asteraceae
A4: ACMAME | B4: Acmispon americanus | C4: Native | D4: American bird's foot trefoil | E4: Lotus purshianus | F4: Fabaceae
A5: ACMGLA | B5: Acmispon glaber | C5: Native | D5: Deerweed, California Broom | E5: Lotus scoparius | F5: Fabaceae
A6: ACMMAR | B6: Acmispon maritimus | C6: Native | D6: Coastal Lotus | E6: Lotus salsuginosus | F6: Fabaceae
A7: ACMMIC | B7: Acmicspon micranthus | C7: Native | D7: Small flowered lotus, grab lotus | E7: Lotus hamatus | F7: Fabaceae
A8: ACMPRO | B8: Acmispon prostratus | C8: Native | D8: prostrate lotus | F8: Fabaceae
A9: ACMSPP | B9: Acmispon species | C9: Native | D9: bird's foot trefoil | E9: . | F9: Fabaceae
A10: ACMSTR | B10: Acmispon strigosus | C10: Native | D10: Strigose lotus | E10: Lotus strigosus | F10: Fabaceae
A11: ACMWRA | B11: Acmispon wrangelianus | C11: Native | F11: Fabaceae
A12: ACOMIC | B12: Acourtia microcephala | C12: Native | D12: Sacapellote | E12: . | F12: Asteraceae
A13: ADEFAS | B13: Adenostoma fasciculatum | C13: Native | D13: Chamise | E13: . | F13: Rosaceae
A14: AGOGRA | B14: Agoseris grandiflora | C14: Native | D14: Large-flowered Mountain Dandelion | F14: Asteraceae
A15: AGOSPP | B15: Agoseris species | C15: Native | F15: Asteraceae
A16: AGRPAL | B16: Agrostis pallens | C16: Native | D16: bent grass | E16: . | F16: Poaceae
A17: ALLAMP | B17: Allium amplectens | C17: Native | D17: onion | F17: Alliaceae
A18: ALLGLU | B18: Allophyllum glutinosum | C18: Native | D18: sticky false gilia | F18: Polemoniaceae
A19: ALLPEN | B19: Allium peninsulare | C19: Native | D19: onion | F19: Alliaceae
A20: ALLPRA | B20: Allium praecox | C20: Native | D20: onion | F20: Alliaceae
A21: ALLSPP | B21: Allium species | C21: Native | D21: onion | F21: Alliaceae
A22: AMAALB | B22: Amaranthus albus | C22: Non-Native | D22: pigweed | E22: . | F22: Amaranthaceae
A23: AMBACA | B23: Ambrosia acanthicarpa | C23: Native | D23: ragweed | E23: . | F23: Asteraceae
A24: AMBCON | B24: Ambrosia confertiflora | C24: Native | D24: weak leaf burweed/ragweed | F24: Asteraceae
A25: AMBPSI | B25: Ambrosia psilostachya | C25: Native | D25: ragweed | E25: . | F25: Asteraceae
A26: AMOCAL | B26: Amorpha californica | C26: Native | D26: false indigo | E26: . | F26: Fabaceae
A27: AMOFRU | B27: Amorpha fruticosa | C27: Native | D27: western false indigo | E27: . | F27: Fabaceae
A28: AMSINT | B28: Amsinckia intermedia | C28: Native | D28: common fiddleneck | E28: . | F28: Boraginaceae
A29: AMSMEN | B29: Amsinckia menziesii | C29: Native | D29: fiddleneck | E29: . | F29: Boraginaceae
A30: AMSRET | B30: Amsinckia retrorsa | C30: Native | D30: Gray Fiddleneck | F30: Boraginaceae
A31: ANAARV | B31: Anagallis arvensis | C31: Non-Native | D31: scarlet pimpernel | E31: . | F31: Primulaceae
A32: ANECAL | B32: Anemopsis californica | C32: Native | D32: Yerba mansa | E32: . | F32: Saururaceae
A33: ANTCAU | B33: Anthriscus caucalis | C33: Non-Native | D33: Bur chervil | E33: . | F33: Apiaceae
A34: ANTCOU | B34: Antirrhinum coulterianum | C34: Native | D34: Coulter's snapdragon | E34: . | F34: Plantaginaceae
A35: ANTKEL | B35: Antirrhinum kelloggii | C35: Native | D35: climbing snapdragon | E35: . | F35: Plantaginaceae
A36: ANTNUT | B36: Antirrhinum nuttallianum | C36: Native | D36: Nuttall's snapdragon | E36: . | F36: Plantaginaceae
A37: APIANG | B37: Apiastrum angustifolium | C37: Native | D37: wild celery | E37: . | F37: Apiaceae
A38: APIGRA | B38: Apium graveolens | C38: Non-Native | D38: celery | E38: . | F38: Apiaceae
A39: APOCAN | B39: Apocynum cannabinum | C39: Native | D39: Indian hemp | E39: . | F39: Apocynaceae
A40: ARASER | B40: Araujia sericifera | C40: Non-Native | D40: bladder flower | E40: . | F40: Apocynaceae
...
