Workbook

Sheet Point Intercept 1
A1: Page # | B1: Year | C1: Date | D1: Team | E1: Site | F1: Block # | G1: Treatment | H1: Transect | I1: Point | J1: Distance | K1: Code | L1: Species | M1: Native/Non-Native | N1: Notes
A2: (#) | B2: 2025 | C2: mm/dd/yy | D2: initials | E2: CU/VB/GB | F2: 43469 | G2: LS/LU/SS/SU | H2: 1 or 2 | I2: 1-30 | J2: 0-12m | K2: six-letter code | L2: do not enter - autofill formula | N2: enter as written
A3: 1 | B3: 2025 | C3: 45764 | D3: TL, CG, BN | E3: VB | F3: 1 | G3: LS | H3: 1 | I3: 1 | J3: 0 | K3: L | L3: =VLOOKUP(K3, 'Alphabetical by species code'!A:B, 2, FALSE) -> Litter | M3: =VLOOKUP(L3, 'Alphabetical by species code'!B:C, 2, FALSE) -> Ground Cover
A4: 1 | B4: 2025 | C4: 45764 | D4: TL, CG, BN | E4: VB | F4: 1 | G4: LS | H4: 1 | I4: 1 | J4: 0 | K4: OPULIT | L4: =VLOOKUP(K4, 'Alphabetical by species code'!A:B, 2, FALSE) -> Opuntia littoralis | M4: =VLOOKUP(L4, 'Alphabetical by species code'!B:C, 2, FALSE) -> Native | N4: =VLOOKUP(L4, 'Alphabetical by species code'!B:C, 2, FALSE) -> Native
A5: 1 | B5: 2025 | C5: 45764 | D5: TL, CG, BN | E5: VB | F5: 1 | G5: LS | H5: 1 | I5: 1 | J5: 0 | K5: EROMOS | L5: =VLOOKUP(K5, 'Alphabetical by species code'!A:B, 2, FALSE) -> Erodium moschatum | M5: =VLOOKUP(L5, 'Alphabetical by species code'!B:C, 2, FALSE) -> Non-Native
A6: 1 | B6: 2025 | C6: 45764 | D6: TL, CG, BN | E6: VB | F6: 1 | G6: LS | H6: 1 | I6: 1 | J6: 0 | K6: FESMYU | L6: =VLOOKUP(K6, 'Alphabetical by species code'!A:B, 2, FALSE) -> Festuca myuros | M6: =VLOOKUP(L6, 'Alphabetical by species code'!B:C, 2, FALSE) -> Non-Native
A7: 1 | B7: 2025 | C7: 45764 | D7: TL, CG, BN | E7: VB | F7: 1 | G7: LS | H7: 1 | I7: 2 | J7: 0.5 | K7: L | L7: =VLOOKUP(K7, 'Alphabetical by species code'!A:B, 2, FALSE) -> Litter | M7: =VLOOKUP(L7, 'Alphabetical by species code'!B:C, 2, FALSE) -> Ground Cover
A8: 1 | B8: 2025 | C8: 45764 | D8: TL, CG, BN | E8: VB | F8: 1 | G8: LS | H8: 1 | I8: 2 | J8: 0.5 | K8: MEDPOL | L8: =VLOOKUP(K8, 'Alphabetical by species code'!A:B, 2, FALSE) -> Medicago polymorpha | M8: =VLOOKUP(L8, 'Alphabetical by species code'!B:C, 2, FALSE) -> Non-Native
A9: 1 | B9: 2025 | C9: 45764 | D9: TL, CG, BN | E9: VB | F9: 1 | G9: LS | H9: 1 | I9: 2 | J9: 0.5 | K9: OPULIT | L9: =VLOOKUP(K9, 'Alphabetical by species code'!A:B, 2, FALSE) -> Opuntia littoralis | M9: =VLOOKUP(L9, 'Alphabetical by species code'!B:C, 2, FALSE) -> Native
A10: 1 | B10: 2025 | C10: 45764 | D10: TL, CG, BN | E10: VB | F10: 1 | G10: LS | H10: 1 | I10: 2 | J10: 0.5 | K10: UNKNNGRASS | L10: =VLOOKUP(K10, 'Alphabetical by species code'!A:B, 2, FALSE) -> Unknown non-native grass | M10: =VLOOKUP(L10, 'Alphabetical by species code'!B:C, 2, FALSE)
A11: 1 | B11: 2025 | C11: 45764 | D11: TL, CG, BN | E11: VB | F11: 1 | G11: LS | H11: 1 | I11: 3 | J11: 1 | K11: L | L11: =VLOOKUP(K11, 'Alphabetical by species code'!A:B, 2, FALSE) -> Litter | M11: =VLOOKUP(L11, 'Alphabetical by species code'!B:C, 2, FALSE) -> Ground Cover
A12: 1 | B12: 2025 | C12: 45764 | D12: TL, CG, BN | E12: VB | F12: 1 | G12: LS | H12: 1 | I12: 3 | J12: 1 | K12: MEDPOL | L12: =VLOOKUP(K12, 'Alphabetical by species code'!A:B, 2, FALSE) -> Medicago polymorpha | M12: =VLOOKUP(L12, 'Alphabetical by species code'!B:C, 2, FALSE) -> Non-Native
A13: 1 | B13: 2025 | C13: 45764 | D13: TL, CG, BN | E13: VB | F13: 1 | G13: LS | H13: 1 | I13: 3 | J13: 1 | K13: FESMYU | L13: =VLOOKUP(K13, 'Alphabetical by species code'!A:B, 2, FALSE) -> Festuca myuros | M13: =VLOOKUP(L13, 'Alphabetical by species code'!B:C, 2, FALSE) -> Non-Native
A14: 1 | B14: 2025 | C14: 45764 | D14: TL, CG, BN | E14: VB | F14: 1 | G14: LS | H14: 1 | I14: 3 | J14: 1 | K14: EROCIC | L14: =VLOOKUP(K14, 'Alphabetical by species code'!A:B, 2, FALSE) -> Erodium cicutarium | M14: =VLOOKUP(L14, 'Alphabetical by species code'!B:C, 2, FALSE) -> Non-Native
A15: 1 | B15: 2025 | C15: 45764 | D15: TL, CG, BN | E15: VB | F15: 1 | G15: LS | H15: 1 | I15: 4 | J15: 1.5 | K15: L | L15: =VLOOKUP(K15, 'Alphabetical by species code'!A:B, 2, FALSE) -> Litter | M15: =VLOOKUP(L15, 'Alphabetical by species code'!B:C, 2, FALSE) -> Ground Cover
A16: 1 | B16: 2025 | C16: 45764 | D16: TL, CG, BN | E16: VB | F16: 1 | G16: LS | H16: 1 | I16: 4 | J16: 1.5 | K16: OPULIT | L16: =VLOOKUP(K16, 'Alphabetical by species code'!A:B, 2, FALSE) -> Opuntia littoralis | M16: =VLOOKUP(L16, 'Alphabetical by species code'!B:C, 2, FALSE) -> Native
... A1374: 16 | B1374: 2025 | C1374: 45790 | D1374: JV, MP | E1374: GB | F1374: 3 | G1374: SU | H1374: 2 | I1374: 15 | J1374: 12 | K1374: UNKPLANT | L1374: =VLOOKUP(K1374, 'Alphabetical by species code'!A:B, 2, FALSE) -> #N/A | M1374: =VLOOKUP(L1374, 'Alphabetical by species code'!B:C, 2, FALSE) -> #N/A

Sheet Point Intercept 2
A1: Page # | B1: Year | C1: Date | D1: Team | E1: Site | F1: Block # | G1: Treatment | H1: Transect | I1: Point | J1: Distance | K1: Code | L1: Species | M1: Notes
A2: (#) | B2: 2025 | C2: mm/dd/yy | D2: initials | E2: CU/VB/GB | F2: 43469 | G2: LS/LU/SS/SU | H2: 1 or 2 | I2: 1-30 | J2: 0-12m | K2: six-letter code | L2: full name | M2: enter as written
A3: 1 | B3: 2025 | C3: 45764 | D3: TL, CG, BN | E3: VB | F3: 1 | G3: LS | H3: 1 | I3: 1 | J3: 0 | K3: L | L3: =VLOOKUP(K3, 'Alphabetical by species code'!A:B, 2, FALSE) -> Litter
A4: 1 | B4: 2025 | C4: 45764 | D4: TL, CG, BN | E4: VB | F4: 1 | G4: LS | H4: 1 | I4: 1 | J4: 0 | K4: OPULIT | L4: =VLOOKUP(K4, 'Alphabetical by species code'!A:B, 2, FALSE) -> Opuntia littoralis
A5: 1 | B5: 2025 | C5: 45764 | D5: TL, CG, BN | E5: VB | F5: 1 | G5: LS | H5: 1 | I5: 1 | J5: 0 | K5: EROMOS | L5: =VLOOKUP(K5, 'Alphabetical by species code'!A:B, 2, FALSE) -> Erodium moschatum
A6: 1 | B6: 2025 | C6: 45764 | D6: TL, CG, BN | E6: VB | F6: 1 | G6: LS | H6: 1 | I6: 1 | J6: 0 | K6: FESMYU | L6: =VLOOKUP(K6, 'Alphabetical by species code'!A:B, 2, FALSE) -> Festuca myuros
A7: 1 | B7: 2025 | C7: 45764 | D7: TL, CG, BN | E7: VB | F7: 1 | G7: LS | H7: 1 | I7: 2 | J7: 0.5 | K7: L | L7: =VLOOKUP(K7, 'Alphabetical by species code'!A:B, 2, FALSE) -> Litter
A8: 1 | B8: 2025 | C8: 45764 | D8: TL, CG, BN | E8: VB | F8: 1 | G8: LS | H8: 1 | I8: 2 | J8: 0.5 | K8: MEDPOL | L8: =VLOOKUP(K8, 'Alphabetical by species code'!A:B, 2, FALSE) -> Medicago polymorpha
A9: 1 | B9: 2025 | C9: 45764 | D9: TL, CG, BN | E9: VB | F9: 1 | G9: LS | H9: 1 | I9: 2 | J9: 0.5 | K9: OPULIT | L9: =VLOOKUP(K9, 'Alphabetical by species code'!A:B, 2, FALSE) -> Opuntia littoralis
A10: 1 | B10: 2025 | C10: 45764 | D10: TL, CG, BN | E10: VB | F10: 1 | G10: LS | H10: 1 | I10: 2 | J10: 0.5 | K10: UNKNNGRASS | L10: =VLOOKUP(K10, 'Alphabetical by species code'!A:B, 2, FALSE) -> Unknown non-native grass
A11: 1 | B11: 2025 | C11: 45764 | D11: TL, CG, BN | E11: VB | F11: 1 | G11: LS | H11: 1 | I11: 3 | J11: 1 | K11: L | L11: =VLOOKUP(K11, 'Alphabetical by species code'!A:B, 2, FALSE) -> Litter
A12: 1 | B12: 2025 | C12: 45764 | D12: TL, CG, BN | E12: VB | F12: 1 | G12: LS | H12: 1 | I12: 3 | J12: 1 | K12: MEDPOL | L12: =VLOOKUP(K12, 'Alphabetical by species code'!A:B, 2, FALSE) -> Medicago polymorpha
A13: 1 | B13: 2025 | C13: 45764 | D13: TL, CG, BN | E13: VB | F13: 1 | G13: LS | H13: 1 | I13: 3 | J13: 1 | K13: FESMYU | L13: =VLOOKUP(K13, 'Alphabetical by species code'!A:B, 2, FALSE) -> Festuca myuros
A14: 1 | B14: 2025 | C14: 45764 | D14: TL, CG, BN | E14: VB | F14: 1 | G14: LS | H14: 1 | I14: 3 | J14: 1 | K14: EROCIC | L14: =VLOOKUP(K14, 'Alphabetical by species code'!A:B, 2, FALSE) -> Erodium cicutarium
... A901: 10 | B901: 2025 | C901: 45777 | D901: CG, JD | E901: CU | F901: 1 | G901: LU | H901: 1 | I901: 14 | J901: 7 | K901: R | L901: =VLOOKUP(K901, 'Alphabetical by species code'!A:B, 2, FALSE) -> Rock
A902: 10 | B902: 2025 | C902: 45777 | D902: CG, JD | E902: CU | F902: 1 | G902: LU | H902: 1 | I902: 14 | J902: 7 | K902: LICHEN | L902: =VLOOKUP(K902, 'Alphabetical by species code'!A:B, 2, FALSE) -> #N/A | M902: Moss? No Hit?
A903: 10 | B903: 2025 | C903: 45777 | D903: CG, JD | E903: CU | F903: 1 | G903: LU | H903: 1 | I903: 15 | J903: 7.5 | K903: L | L903: =VLOOKUP(K903, 'Alphabetical by species code'!A:B, 2, FALSE) -> Litter
A904: 10 | B904: 2025 | C904: 45777 | D904: CG, JD | E904: CU | F904: 1 | G904: LU | H904: 1 | I904: 15 | J904: 7.5 | K904: BRANIG | L904: =VLOOKUP(K904, 'Alphabetical by species code'!A:B, 2, FALSE) -> Brassica nigra
A905: 10 | B905: 2025 | C905: 45777 | D905: CG, JD | E905: CU | F905: 1 | G905: LU | H905: 1 | I905: 15 | J905: 7.5 | K905: CENMEL | L905: =VLOOKUP(K905, 'Alphabetical by species code'!A:B, 2, FALSE) -> Centaurea melitensis
A906: 10 | B906: 2025 | C906: 45777 | D906: CG, JD | E906: CU | F906: 1 | G906: LU | H906: 2 | I906: 1 | J906: 0 | K906: R | L906: =VLOOKUP(K906, 'Alphabetical by species code'!A:B, 2, FALSE) -> Rock
A907: 10 | B907: 2025 | C907: 45777 | D907: CG, JD | E907: CU | F907: 1 | G907: LU | H907: 2 | I907: 2 | J907: 0.5 | K907: L | L907: =VLOOKUP(K907, 'Alphabetical by species code'!A:B, 2, FALSE) -> Litter
A908: 10 | B908: 2025 | C908: 45777 | D908: CG, JD | E908: CU | F908: 1 | G908: LU | H908: 2 | I908: 2 | J908: 0.5 | K908: BROMAD | L908: =VLOOKUP(K908, 'Alphabetical by species code'!A:B, 2, FALSE) -> Bromus madritensis
A909: 10 | B909: 2025 | C909: 45777 | D909: CG, JD | E909: CU | F909: 1 | G909: LU | H909: 2 | I909: 3 | J909: 1 | K909: B | L909: =VLOOKUP(K909, 'Alphabetical by species code'!A:B, 2, FALSE) -> Bareground
A910: 10 | B910: 2025 | C910: 45777 | D910: CG, JD | E910: CU | F910: 1 | G910: LU | H910: 2 | I910: 3 | J910: 1 | K910: SENVIL | L910: =VLOOKUP(K910, 'Alphabetical by species code'!A:B, 2, FALSE) -> #N/A
A911: 10 | B911: 2025 | C911: 45777 | D911: CG, JD | E911: CU | F911: 1 | G911: LU | H911: 2 | I911: 3 | J911: 1 | K911: EROSPP | L911: =VLOOKUP(K911, 'Alphabetical by species code'!A:B, 2, FALSE) -> Erodium species
A912: 10 | B912: 2025 | C912: 45777 | D912: CG, JD | E912: CU | F912: 1 | G912: LU | H912: 2 | I912: 4 | J912: 1.5 | K912: L | L912: =VLOOKUP(K912, 'Alphabetical by species code'!A:B, 2, FALSE) -> Litter
A913: 10 | B913: 2025 | C913: 45777 | D913: CG, JD | E913: CU | F913: 1 | G913: LU | H913: 2 | I913: 4 | J913: 1.5 | K913: DEIFAS | L913: =VLOOKUP(K913, 'Alphabetical by species code'!A:B, 2, FALSE) -> Deinandra fasciculata
A914: 10 | B914: 2025 | C914: 45777 | D914: CG, JD | E914: CU | F914: 1 | G914: LU | H914: 2 | I914: 5 | J914: 2.5 | K914: L | L914: =VLOOKUP(K914, 'Alphabetical by species code'!A:B, 2, FALSE) -> Litter
... A1375: 16 | B1375: 2025 | C1375: 45790 | D1375: MP, JV | E1375: GB | F1375: 3 | G1375: SU | H1375: 2 | I1375: 15 | J1375: 12 | K1375: UNKPLANT | L1375: =VLOOKUP(K1375, 'Alphabetical by species code'!A:B, 2, FALSE) -> #N/A

Sheet Data Validation DO NOT EDIT
A1: =if('Point Intercept 1'!A1 = 'Point Intercept 2'!A1, 'Point Intercept 1'!A1, "ERROR") -> Page # | B1: =if('Point Intercept 1'!B1 = 'Point Intercept 2'!B1, 'Point Intercept 1'!B1, "ERROR") -> Year | C1: =if('Point Intercept 1'!C1 = 'Point Intercept 2'!C1, 'Point Intercept 1'!C1, "ERROR") -> Date | D1: =if('Point Intercept 1'!D1 = 'Point Intercept 2'!D1, 'Point Intercept 1'!D1, "ERROR") -> Team | E1: =if('Point Intercept 1'!E1 = 'Point Intercept 2'!E1, 'Point Intercept 1'!E1, "ERROR") -> Site | F1: =if('Point Intercept 1'!F1 = 'Point Intercept 2'!F1, 'Point Intercept 1'!F1, "ERROR") -> Block # | G1: =if('Point Intercept 1'!G1 = 'Point Intercept 2'!G1, 'Point Intercept 1'!G1, "ERROR") -> Treatment | H1: =if('Point Intercept 1'!I1 = 'Point Intercept 2'!I1, 'Point Intercept 1'!I1, "ERROR") -> Point | I1: =if('Point Intercept 1'!H1 = 'Point Intercept 2'!H1, 'Point Intercept 1'!H1, "ERROR") -> Transect | J1: =if('Point Intercept 1'!J1 = 'Point Intercept 2'!J1, 'Point Intercept 1'!J1, "ERROR") -> Distance | K1: =if('Point Intercept 1'!K1 = 'Point Intercept 2'!K1, 'Point Intercept 1'!K1, "ERROR") -> Code | L1: =if('Point Intercept 1'!L1 = 'Point Intercept 2'!L1, 'Point Intercept 1'!L1, "ERROR") -> Species | M1: =if('Point Intercept 1'!N1 = 'Point Intercept 2'!M1, 'Point Intercept 1'!N1, "ERROR") -> Notes | N1: =if('Point Intercept 1'!O1 = 'Point Intercept 2'!N1, 'Point Intercept 1'!O1, "ERROR") | O1: =if('Point Intercept 1'!P1 = 'Point Intercept 2'!O1, 'Point Intercept 1'!P1, "ERROR")
A2: =if('Point Intercept 1'!A2 = 'Point Intercept 2'!A2, 'Point Intercept 1'!A2, "ERROR") -> (#) | B2: =if('Point Intercept 1'!B2 = 'Point Intercept 2'!B2, 'Point Intercept 1'!B2, "ERROR") -> 2025 | C2: =if('Point Intercept 1'!C2 = 'Point Intercept 2'!C2, 'Point Intercept 1'!C2, "ERROR") -> mm/dd/yy | D2: =if('Point Intercept 1'!D2 = 'Point Intercept 2'!D2, 'Point Intercept 1'!D2, "ERROR") -> initials | E2: =if('Point Intercept 1'!E2 = 'Point Intercept 2'!E2, 'Point Intercept 1'!E2, "ERROR") -> CU/VB/GB | F2: =if('Point Intercept 1'!F2 = 'Point Intercept 2'!F2, 'Point Intercept 1'!F2, "ERROR") -> 43469 | G2: =if('Point Intercept 1'!G2 = 'Point Intercept 2'!G2, 'Point Intercept 1'!G2, "ERROR") -> LS/LU/SS/SU | H2: =if('Point Intercept 1'!I2 = 'Point Intercept 2'!I2, 'Point Intercept 1'!I2, "ERROR") -> 1-30 | I2: =if('Point Intercept 1'!H2 = 'Point Intercept 2'!H2, 'Point Intercept 1'!H2, "ERROR") -> 1 or 2 | J2: =if('Point Intercept 1'!J2 = 'Point Intercept 2'!J2, 'Point Intercept 1'!J2, "ERROR") -> 0-12m | K2: =if('Point Intercept 1'!K2 = 'Point Intercept 2'!K2, 'Point Intercept 1'!K2, "ERROR") -> six-letter code | L2: =if('Point Intercept 1'!L2 = 'Point Intercept 2'!L2, 'Point Intercept 1'!L2, "ERROR") -> ERROR | M2: =if('Point Intercept 1'!N2 = 'Point Intercept 2'!M2, 'Point Intercept 1'!N2, "ERROR") -> enter as written | N2: =if('Point Intercept 1'!O2 = 'Point Intercept 2'!N2, 'Point Intercept 1'!O2, "ERROR") | O2: =if('Point Intercept 1'!P2 = 'Point Intercept 2'!O2, 'Point Intercept 1'!P2, "ERROR")
A3: =if('Point Intercept 1'!A3 = 'Point Intercept 2'!A3, 'Point Intercept 1'!A3, "ERROR") -> 1 | B3: =if('Point Intercept 1'!B3 = 'Point Intercept 2'!B3, 'Point Intercept 1'!B3, "ERROR") -> 2025 | C3: =if('Point Intercept 1'!C3 = 'Point Intercept 2'!C3, 'Point Intercept 1'!C3, "ERROR") -> 45764 | D3: =if('Point Intercept 1'!D3 = 'Point Intercept 2'!D3, 'Point Intercept 1'!D3, "ERROR") -> TL, CG, BN | E3: =if('Point Intercept 1'!E3 = 'Point Intercept 2'!E3, 'Point Intercept 1'!E3, "ERROR") -> VB | F3: =if('Point Intercept 1'!F3 = 'Point Intercept 2'!F3, 'Point Intercept 1'!F3, "ERROR") -> 1 | G3: =if('Point Intercept 1'!G3 = 'Point Intercept 2'!G3, 'Point Intercept 1'!G3, "ERROR") -> LS | H3: =if('Point Intercept 1'!I3 = 'Point Intercept 2'!I3, 'Point Intercept 1'!I3, "ERROR") -> 1 | I3: =if('Point Intercept 1'!H3 = 'Point Intercept 2'!H3, 'Point Intercept 1'!H3, "ERROR") -> 1 | J3: =if('Point Intercept 1'!J3 = 'Point Intercept 2'!J3, 'Point Intercept 1'!J3, "ERROR") -> 0 | K3: =if('Point Intercept 1'!K3 = 'Point Intercept 2'!K3, 'Point Intercept 1'!K3, "ERROR") -> L | L3: =if('Point Intercept 1'!L3 = 'Point Intercept 2'!L3, 'Point Intercept 1'!L3, "ERROR") -> Litter | M3: =if('Point Intercept 1'!N3 = 'Point Intercept 2'!M3, 'Point Intercept 1'!N3, "ERROR") | N3: =if('Point Intercept 1'!O3 = 'Point Intercept 2'!N3, 'Point Intercept 1'!O3, "ERROR") | O3: =if('Point Intercept 1'!P3 = 'Point Intercept 2'!O3, 'Point Intercept 1'!P3, "ERROR")
A4: =if('Point Intercept 1'!A4 = 'Point Intercept 2'!A4, 'Point Intercept 1'!A4, "ERROR") -> 1 | B4: =if('Point Intercept 1'!B4 = 'Point Intercept 2'!B4, 'Point Intercept 1'!B4, "ERROR") -> 2025 | C4: =if('Point Intercept 1'!C4 = 'Point Intercept 2'!C4, 'Point Intercept 1'!C4, "ERROR") -> 45764 | D4: =if('Point Intercept 1'!D4 = 'Point Intercept 2'!D4, 'Point Intercept 1'!D4, "ERROR") -> TL, CG, BN | E4: =if('Point Intercept 1'!E4 = 'Point Intercept 2'!E4, 'Point Intercept 1'!E4, "ERROR") -> VB | F4: =if('Point Intercept 1'!F4 = 'Point Intercept 2'!F4, 'Point Intercept 1'!F4, "ERROR") -> 1 | G4: =if('Point Intercept 1'!G4 = 'Point Intercept 2'!G4, 'Point Intercept 1'!G4, "ERROR") -> LS | H4: =if('Point Intercept 1'!I4 = 'Point Intercept 2'!I4, 'Point Intercept 1'!I4, "ERROR") -> 1 | I4: =if('Point Intercept 1'!H4 = 'Point Intercept 2'!H4, 'Point Intercept 1'!H4, "ERROR") -> 1 | J4: =if('Point Intercept 1'!J4 = 'Point Intercept 2'!J4, 'Point Intercept 1'!J4, "ERROR") -> 0 | K4: =if('Point Intercept 1'!K4 = 'Point Intercept 2'!K4, 'Point Intercept 1'!K4, "ERROR") -> OPULIT | L4: =if('Point Intercept 1'!L4 = 'Point Intercept 2'!L4, 'Point Intercept 1'!L4, "ERROR") -> Opuntia littoralis | M4: =if('Point Intercept 1'!N4 = 'Point Intercept 2'!M4, 'Point Intercept 1'!N4, "ERROR") -> ERROR | N4: =if('Point Intercept 1'!O4 = 'Point Intercept 2'!N4, 'Point Intercept 1'!O4, "ERROR") | O4: =if('Point Intercept 1'!P4 = 'Point Intercept 2'!O4, 'Point Intercept 1'!P4, "ERROR")
A5: =if('Point Intercept 1'!A5 = 'Point Intercept 2'!A5, 'Point Intercept 1'!A5, "ERROR") -> 1 | B5: =if('Point Intercept 1'!B5 = 'Point Intercept 2'!B5, 'Point Intercept 1'!B5, "ERROR") -> 2025 | C5: =if('Point Intercept 1'!C5 = 'Point Intercept 2'!C5, 'Point Intercept 1'!C5, "ERROR") -> 45764 | D5: =if('Point Intercept 1'!D5 = 'Point Intercept 2'!D5, 'Point Intercept 1'!D5, "ERROR") -> TL, CG, BN | E5: =if('Point Intercept 1'!E5 = 'Point Intercept 2'!E5, 'Point Intercept 1'!E5, "ERROR") -> VB | F5: =if('Point Intercept 1'!F5 = 'Point Intercept 2'!F5, 'Point Intercept 1'!F5, "ERROR") -> 1 | G5: =if('Point Intercept 1'!G5 = 'Point Intercept 2'!G5, 'Point Intercept 1'!G5, "ERROR") -> LS | H5: =if('Point Intercept 1'!I5 = 'Point Intercept 2'!I5, 'Point Intercept 1'!I5, "ERROR") -> 1 | I5: =if('Point Intercept 1'!H5 = 'Point Intercept 2'!H5, 'Point Intercept 1'!H5, "ERROR") -> 1 | J5: =if('Point Intercept 1'!J5 = 'Point Intercept 2'!J5, 'Point Intercept 1'!J5, "ERROR") -> 0 | K5: =if('Point Intercept 1'!K5 = 'Point Intercept 2'!K5, 'Point Intercept 1'!K5, "ERROR") -> EROMOS | L5: =if('Point Intercept 1'!L5 = 'Point Intercept 2'!L5, 'Point Intercept 1'!L5, "ERROR") -> Erodium moschatum | M5: =if('Point Intercept 1'!N5 = 'Point Intercept 2'!M5, 'Point Intercept 1'!N5, "ERROR") | N5: =if('Point Intercept 1'!O5 = 'Point Intercept 2'!N5, 'Point Intercept 1'!O5, "ERROR") | O5: =if('Point Intercept 1'!P5 = 'Point Intercept 2'!O5, 'Point Intercept 1'!P5, "ERROR")
A6: =if('Point Intercept 1'!A6 = 'Point Intercept 2'!A6, 'Point Intercept 1'!A6, "ERROR") -> 1 | B6: =if('Point Intercept 1'!B6 = 'Point Intercept 2'!B6, 'Point Intercept 1'!B6, "ERROR") -> 2025 | C6: =if('Point Intercept 1'!C6 = 'Point Intercept 2'!C6, 'Point Intercept 1'!C6, "ERROR") -> 45764 | D6: =if('Point Intercept 1'!D6 = 'Point Intercept 2'!D6, 'Point Intercept 1'!D6, "ERROR") -> TL, CG, BN | E6: =if('Point Intercept 1'!E6 = 'Point Intercept 2'!E6, 'Point Intercept 1'!E6, "ERROR") -> VB | F6: =if('Point Intercept 1'!F6 = 'Point Intercept 2'!F6, 'Point Intercept 1'!F6, "ERROR") -> 1 | G6: =if('Point Intercept 1'!G6 = 'Point Intercept 2'!G6, 'Point Intercept 1'!G6, "ERROR") -> LS | H6: =if('Point Intercept 1'!I6 = 'Point Intercept 2'!I6, 'Point Intercept 1'!I6, "ERROR") -> 1 | I6: =if('Point Intercept 1'!H6 = 'Point Intercept 2'!H6, 'Point Intercept 1'!H6, "ERROR") -> 1 | J6: =if('Point Intercept 1'!J6 = 'Point Intercept 2'!J6, 'Point Intercept 1'!J6, "ERROR") -> 0 | K6: =if('Point Intercept 1'!K6 = 'Point Intercept 2'!K6, 'Point Intercept 1'!K6, "ERROR") -> FESMYU | L6: =if('Point Intercept 1'!L6 = 'Point Intercept 2'!L6, 'Point Intercept 1'!L6, "ERROR") -> Festuca myuros | M6: =if('Point Intercept 1'!N6 = 'Point Intercept 2'!M6, 'Point Intercept 1'!N6, "ERROR") | N6: =if('Point Intercept 1'!O6 = 'Point Intercept 2'!N6, 'Point Intercept 1'!O6, "ERROR") | O6: =if('Point Intercept 1'!P6 = 'Point Intercept 2'!O6, 'Point Intercept 1'!P6, "ERROR")
A7: =if('Point Intercept 1'!A7 = 'Point Intercept 2'!A7, 'Point Intercept 1'!A7, "ERROR") -> 1 | B7: =if('Point Intercept 1'!B7 = 'Point Intercept 2'!B7, 'Point Intercept 1'!B7, "ERROR") -> 2025 | C7: =if('Point Intercept 1'!C7 = 'Point Intercept 2'!C7, 'Point Intercept 1'!C7, "ERROR") -> 45764 | D7: =if('Point Intercept 1'!D7 = 'Point Intercept 2'!D7, 'Point Intercept 1'!D7, "ERROR") -> TL, CG, BN | E7: =if('Point Intercept 1'!E7 = 'Point Intercept 2'!E7, 'Point Intercept 1'!E7, "ERROR") -> VB | F7: =if('Point Intercept 1'!F7 = 'Point Intercept 2'!F7, 'Point Intercept 1'!F7, "ERROR") -> 1 | G7: =if('Point Intercept 1'!G7 = 'Point Intercept 2'!G7, 'Point Intercept 1'!G7, "ERROR") -> LS | H7: =if('Point Intercept 1'!I7 = 'Point Intercept 2'!I7, 'Point Intercept 1'!I7, "ERROR") -> 2 | I7: =if('Point Intercept 1'!H7 = 'Point Intercept 2'!H7, 'Point Intercept 1'!H7, "ERROR") -> 1 | J7: =if('Point Intercept 1'!J7 = 'Point Intercept 2'!J7, 'Point Intercept 1'!J7, "ERROR") -> 0.5 | K7: =if('Point Intercept 1'!K7 = 'Point Intercept 2'!K7, 'Point Intercept 1'!K7, "ERROR") -> L | L7: =if('Point Intercept 1'!L7 = 'Point Intercept 2'!L7, 'Point Intercept 1'!L7, "ERROR") -> Litter | M7: =if('Point Intercept 1'!N7 = 'Point Intercept 2'!M7, 'Point Intercept 1'!N7, "ERROR") | N7: =if('Point Intercept 1'!O7 = 'Point Intercept 2'!N7, 'Point Intercept 1'!O7, "ERROR") | O7: =if('Point Intercept 1'!P7 = 'Point Intercept 2'!O7, 'Point Intercept 1'!P7, "ERROR")
A8: =if('Point Intercept 1'!A8 = 'Point Intercept 2'!A8, 'Point Intercept 1'!A8, "ERROR") -> 1 | B8: =if('Point Intercept 1'!B8 = 'Point Intercept 2'!B8, 'Point Intercept 1'!B8, "ERROR") -> 2025 | C8: =if('Point Intercept 1'!C8 = 'Point Intercept 2'!C8, 'Point Intercept 1'!C8, "ERROR") -> 45764 | D8: =if('Point Intercept 1'!D8 = 'Point Intercept 2'!D8, 'Point Intercept 1'!D8, "ERROR") -> TL, CG, BN | E8: =if('Point Intercept 1'!E8 = 'Point Intercept 2'!E8, 'Point Intercept 1'!E8, "ERROR") -> VB | F8: =if('Point Intercept 1'!F8 = 'Point Intercept 2'!F8, 'Point Intercept 1'!F8, "ERROR") -> 1 | G8: =if('Point Intercept 1'!G8 = 'Point Intercept 2'!G8, 'Point Intercept 1'!G8, "ERROR") -> LS | H8: =if('Point Intercept 1'!I8 = 'Point Intercept 2'!I8, 'Point Intercept 1'!I8, "ERROR") -> 2 | I8: =if('Point Intercept 1'!H8 = 'Point Intercept 2'!H8, 'Point Intercept 1'!H8, "ERROR") -> 1 | J8: =if('Point Intercept 1'!J8 = 'Point Intercept 2'!J8, 'Point Intercept 1'!J8, "ERROR") -> 0.5 | K8: =if('Point Intercept 1'!K8 = 'Point Intercept 2'!K8, 'Point Intercept 1'!K8, "ERROR") -> MEDPOL | L8: =if('Point Intercept 1'!L8 = 'Point Intercept 2'!L8, 'Point Intercept 1'!L8, "ERROR") -> Medicago polymorpha | M8: =if('Point Intercept 1'!N8 = 'Point Intercept 2'!M8, 'Point Intercept 1'!N8, "ERROR") | N8: =if('Point Intercept 1'!O8 = 'Point Intercept 2'!N8, 'Point Intercept 1'!O8, "ERROR") | O8: =if('Point Intercept 1'!P8 = 'Point Intercept 2'!O8, 'Point Intercept 1'!P8, "ERROR")
A9: =if('Point Intercept 1'!A9 = 'Point Intercept 2'!A9, 'Point Intercept 1'!A9, "ERROR") -> 1 | B9: =if('Point Intercept 1'!B9 = 'Point Intercept 2'!B9, 'Point Intercept 1'!B9, "ERROR") -> 2025 | C9: =if('Point Intercept 1'!C9 = 'Point Intercept 2'!C9, 'Point Intercept 1'!C9, "ERROR") -> 45764 | D9: =if('Point Intercept 1'!D9 = 'Point Intercept 2'!D9, 'Point Intercept 1'!D9, "ERROR") -> TL, CG, BN | E9: =if('Point Intercept 1'!E9 = 'Point Intercept 2'!E9, 'Point Intercept 1'!E9, "ERROR") -> VB | F9: =if('Point Intercept 1'!F9 = 'Point Intercept 2'!F9, 'Point Intercept 1'!F9, "ERROR") -> 1 | G9: =if('Point Intercept 1'!G9 = 'Point Intercept 2'!G9, 'Point Intercept 1'!G9, "ERROR") -> LS | H9: =if('Point Intercept 1'!I9 = 'Point Intercept 2'!I9, 'Point Intercept 1'!I9, "ERROR") -> 2 | I9: =if('Point Intercept 1'!H9 = 'Point Intercept 2'!H9, 'Point Intercept 1'!H9, "ERROR") -> 1 | J9: =if('Point Intercept 1'!J9 = 'Point Intercept 2'!J9, 'Point Intercept 1'!J9, "ERROR") -> 0.5 | K9: =if('Point Intercept 1'!K9 = 'Point Intercept 2'!K9, 'Point Intercept 1'!K9, "ERROR") -> OPULIT | L9: =if('Point Intercept 1'!L9 = 'Point Intercept 2'!L9, 'Point Intercept 1'!L9, "ERROR") -> Opuntia littoralis | M9: =if('Point Intercept 1'!N9 = 'Point Intercept 2'!M9, 'Point Intercept 1'!N9, "ERROR") | N9: =if('Point Intercept 1'!O9 = 'Point Intercept 2'!N9, 'Point Intercept 1'!O9, "ERROR") | O9: =if('Point Intercept 1'!P9 = 'Point Intercept 2'!O9, 'Point Intercept 1'!P9, "ERROR")
A10: =if('Point Intercept 1'!A10 = 'Point Intercept 2'!A10, 'Point Intercept 1'!A10, "ERROR") -> 1 | B10: =if('Point Intercept 1'!B10 = 'Point Intercept 2'!B10, 'Point Intercept 1'!B10, "ERROR") -> 2025 | C10: =if('Point Intercept 1'!C10 = 'Point Intercept 2'!C10, 'Point Intercept 1'!C10, "ERROR") -> 45764 | D10: =if('Point Intercept 1'!D10 = 'Point Intercept 2'!D10, 'Point Intercept 1'!D10, "ERROR") -> TL, CG, BN | E10: =if('Point Intercept 1'!E10 = 'Point Intercept 2'!E10, 'Point Intercept 1'!E10, "ERROR") -> VB | F10: =if('Point Intercept 1'!F10 = 'Point Intercept 2'!F10, 'Point Intercept 1'!F10, "ERROR") -> 1 | G10: =if('Point Intercept 1'!G10 = 'Point Intercept 2'!G10, 'Point Intercept 1'!G10, "ERROR") -> LS | H10: =if('Point Intercept 1'!I10 = 'Point Intercept 2'!I10, 'Point Intercept 1'!I10, "ERROR") -> 2 | I10: =if('Point Intercept 1'!H10 = 'Point Intercept 2'!H10, 'Point Intercept 1'!H10, "ERROR") -> 1 | J10: =if('Point Intercept 1'!J10 = 'Point Intercept 2'!J10, 'Point Intercept 1'!J10, "ERROR") -> 0.5 | K10: =if('Point Intercept 1'!K10 = 'Point Intercept 2'!K10, 'Point Intercept 1'!K10, "ERROR") -> UNKNNGRASS | L10: =if('Point Intercept 1'!L10 = 'Point Intercept 2'!L10, 'Point Intercept 1'!L10, "ERROR") -> Unknown non-native grass | M10: =if('Point Intercept 1'!N10 = 'Point Intercept 2'!M10, 'Point Intercept 1'!N10, "ERROR") | N10: =if('Point Intercept 1'!O10 = 'Point Intercept 2'!N10, 'Point Intercept 1'!O10, "ERROR") | O10: =if('Point Intercept 1'!P10 = 'Point Intercept 2'!O10, 'Point Intercept 1'!P10, "ERROR")
A11: =if('Point Intercept 1'!A11 = 'Point Intercept 2'!A11, 'Point Intercept 1'!A11, "ERROR") -> 1 | B11: =if('Point Intercept 1'!B11 = 'Point Intercept 2'!B11, 'Point Intercept 1'!B11, "ERROR") -> 2025 | C11: =if('Point Intercept 1'!C11 = 'Point Intercept 2'!C11, 'Point Intercept 1'!C11, "ERROR") -> 45764 | D11: =if('Point Intercept 1'!D11 = 'Point Intercept 2'!D11, 'Point Intercept 1'!D11, "ERROR") -> TL, CG, BN | E11: =if('Point Intercept 1'!E11 = 'Point Intercept 2'!E11, 'Point Intercept 1'!E11, "ERROR") -> VB | F11: =if('Point Intercept 1'!F11 = 'Point Intercept 2'!F11, 'Point Intercept 1'!F11, "ERROR") -> 1 | G11: =if('Point Intercept 1'!G11 = 'Point Intercept 2'!G11, 'Point Intercept 1'!G11, "ERROR") -> LS | H11: =if('Point Intercept 1'!I11 = 'Point Intercept 2'!I11, 'Point Intercept 1'!I11, "ERROR") -> 3 | I11: =if('Point Intercept 1'!H11 = 'Point Intercept 2'!H11, 'Point Intercept 1'!H11, "ERROR") -> 1 | J11: =if('Point Intercept 1'!J11 = 'Point Intercept 2'!J11, 'Point Intercept 1'!J11, "ERROR") -> 1 | K11: =if('Point Intercept 1'!K11 = 'Point Intercept 2'!K11, 'Point Intercept 1'!K11, "ERROR") -> L | L11: =if('Point Intercept 1'!L11 = 'Point Intercept 2'!L11, 'Point Intercept 1'!L11, "ERROR") -> Litter | M11: =if('Point Intercept 1'!N11 = 'Point Intercept 2'!M11, 'Point Intercept 1'!N11, "ERROR") | N11: =if('Point Intercept 1'!O11 = 'Point Intercept 2'!N11, 'Point Intercept 1'!O11, "ERROR") | O11: =if('Point Intercept 1'!P11 = 'Point Intercept 2'!O11, 'Point Intercept 1'!P11, "ERROR")
A12: =if('Point Intercept 1'!A12 = 'Point Intercept 2'!A12, 'Point Intercept 1'!A12, "ERROR") -> 1 | B12: =if('Point Intercept 1'!B12 = 'Point Intercept 2'!B12, 'Point Intercept 1'!B12, "ERROR") -> 2025 | C12: =if('Point Intercept 1'!C12 = 'Point Intercept 2'!C12, 'Point Intercept 1'!C12, "ERROR") -> 45764 | D12: =if('Point Intercept 1'!D12 = 'Point Intercept 2'!D12, 'Point Intercept 1'!D12, "ERROR") -> TL, CG, BN | E12: =if('Point Intercept 1'!E12 = 'Point Intercept 2'!E12, 'Point Intercept 1'!E12, "ERROR") -> VB | F12: =if('Point Intercept 1'!F12 = 'Point Intercept 2'!F12, 'Point Intercept 1'!F12, "ERROR") -> 1 | G12: =if('Point Intercept 1'!G12 = 'Point Intercept 2'!G12, 'Point Intercept 1'!G12, "ERROR") -> LS | H12: =if('Point Intercept 1'!I12 = 'Point Intercept 2'!I12, 'Point Intercept 1'!I12, "ERROR") -> 3 | I12: =if('Point Intercept 1'!H12 = 'Point Intercept 2'!H12, 'Point Intercept 1'!H12, "ERROR") -> 1 | J12: =if('Point Intercept 1'!J12 = 'Point Intercept 2'!J12, 'Point Intercept 1'!J12, "ERROR") -> 1 | K12: =if('Point Intercept 1'!K12 = 'Point Intercept 2'!K12, 'Point Intercept 1'!K12, "ERROR") -> MEDPOL | L12: =if('Point Intercept 1'!L12 = 'Point Intercept 2'!L12, 'Point Intercept 1'!L12, "ERROR") -> Medicago polymorpha | M12: =if('Point Intercept 1'!N12 = 'Point Intercept 2'!M12, 'Point Intercept 1'!N12, "ERROR") | N12: =if('Point Intercept 1'!O12 = 'Point Intercept 2'!N12, 'Point Intercept 1'!O12, "ERROR") | O12: =if('Point Intercept 1'!P12 = 'Point Intercept 2'!O12, 'Point Intercept 1'!P12, "ERROR")
... A330: =if('Point Intercept 1'!A330 = 'Point Intercept 2'!A330, 'Point Intercept 1'!A330, "ERROR") -> 4 | B330: =if('Point Intercept 1'!B330 = 'Point Intercept 2'!B330, 'Point Intercept 1'!B330, "ERROR") -> 2025 | C330: =if('Point Intercept 1'!C330 = 'Point Intercept 2'!C330, 'Point Intercept 1'!C330, "ERROR") -> 45755 | D330: =if('Point Intercept 1'!D330 = 'Point Intercept 2'!D330, 'Point Intercept 1'!D330, "ERROR") -> JC, TL | E330: =if('Point Intercept 1'!E330 = 'Point Intercept 2'!E330, 'Point Intercept 1'!E330, "ERROR") -> VB | F330: =if('Point Intercept 1'!F330 = 'Point Intercept 2'!F330, 'Point Intercept 1'!F330, "ERROR") -> 3 | G330: =if('Point Intercept 1'!G330 = 'Point Intercept 2'!G330, 'Point Intercept 1'!G330, "ERROR") -> LS | H330: =if('Point Intercept 1'!I330 = 'Point Intercept 2'!I330, 'Point Intercept 1'!I330, "ERROR") -> 7 | I330: =if('Point Intercept 1'!H330 = 'Point Intercept 2'!H330, 'Point Intercept 1'!H330, "ERROR") -> 1 | J330: =if('Point Intercept 1'!J330 = 'Point Intercept 2'!J330, 'Point Intercept 1'!J330, "ERROR") -> 3 | K330: =if('Point Intercept 1'!K330 = 'Point Intercept 2'!K330, 'Point Intercept 1'!K330, "ERROR") -> SONOLE | L330: =if('Point Intercept 1'!L330 = 'Point Intercept 2'!L330, 'Point Intercept 1'!L330, "ERROR") -> Sonchus oleraceus | M330: =if('Point Intercept 1'!N330 = 'Point Intercept 2'!M330, 'Point Intercept 1'!N330, "ERROR") | N330: =if('Point Intercept 1'!O330 = 'Point Intercept 2'!N330, 'Point Intercept 1'!O330, "ERROR") | O330: =if('Point Intercept 1'!P330 = 'Point Intercept 2'!O330, 'Point Intercept 1'!P330, "ERROR")
A331: =if('Point Intercept 1'!A331 = 'Point Intercept 2'!A331, 'Point Intercept 1'!A331, "ERROR") -> 4 | B331: =if('Point Intercept 1'!B331 = 'Point Intercept 2'!B331, 'Point Intercept 1'!B331, "ERROR") -> 2025 | C331: =if('Point Intercept 1'!C331 = 'Point Intercept 2'!C331, 'Point Intercept 1'!C331, "ERROR") -> 45755 | D331: =if('Point Intercept 1'!D331 = 'Point Intercept 2'!D331, 'Point Intercept 1'!D331, "ERROR") -> JC, TL | E331: =if('Point Intercept 1'!E331 = 'Point Intercept 2'!E331, 'Point Intercept 1'!E331, "ERROR") -> VB | F331: =if('Point Intercept 1'!F331 = 'Point Intercept 2'!F331, 'Point Intercept 1'!F331, "ERROR") -> 3 | G331: =if('Point Intercept 1'!G331 = 'Point Intercept 2'!G331, 'Point Intercept 1'!G331, "ERROR") -> LS | H331: =if('Point Intercept 1'!I331 = 'Point Intercept 2'!I331, 'Point Intercept 1'!I331, "ERROR") -> 8 | I331: =if('Point Intercept 1'!H331 = 'Point Intercept 2'!H331, 'Point Intercept 1'!H331, "ERROR") -> 1 | J331: =if('Point Intercept 1'!J331 = 'Point Intercept 2'!J331, 'Point Intercept 1'!J331, "ERROR") -> 3.5 | K331: =if('Point Intercept 1'!K331 = 'Point Intercept 2'!K331, 'Point Intercept 1'!K331, "ERROR") -> L | L331: =if('Point Intercept 1'!L331 = 'Point Intercept 2'!L331, 'Point Intercept 1'!L331, "ERROR") -> Litter | M331: =if('Point Intercept 1'!N331 = 'Point Intercept 2'!M332, 'Point Intercept 1'!N331, "ERROR") | N331: =if('Point Intercept 1'!O331 = 'Point Intercept 2'!N332, 'Point Intercept 1'!O331, "ERROR") | O331: =if('Point Intercept 1'!P331 = 'Point Intercept 2'!O332, 'Point Intercept 1'!P331, "ERROR")
A332: =if('Point Intercept 1'!A332 = 'Point Intercept 2'!A332, 'Point Intercept 1'!A332, "ERROR") -> 4 | B332: =if('Point Intercept 1'!B332 = 'Point Intercept 2'!B332, 'Point Intercept 1'!B332, "ERROR") -> 2025 | C332: =if('Point Intercept 1'!C332 = 'Point Intercept 2'!C332, 'Point Intercept 1'!C332, "ERROR") -> 45755 | D332: =if('Point Intercept 1'!D332 = 'Point Intercept 2'!D332, 'Point Intercept 1'!D332, "ERROR") -> JC, TL | E332: =if('Point Intercept 1'!E332 = 'Point Intercept 2'!E332, 'Point Intercept 1'!E332, "ERROR") -> VB | F332: =if('Point Intercept 1'!F332 = 'Point Intercept 2'!F332, 'Point Intercept 1'!F332, "ERROR") -> 3 | G332: =if('Point Intercept 1'!G332 = 'Point Intercept 2'!G332, 'Point Intercept 1'!G332, "ERROR") -> LS | H332: =if('Point Intercept 1'!I332 = 'Point Intercept 2'!I332, 'Point Intercept 1'!I332, "ERROR") -> 8 | I332: =if('Point Intercept 1'!H332 = 'Point Intercept 2'!H332, 'Point Intercept 1'!H332, "ERROR") -> 1 | J332: =if('Point Intercept 1'!J332 = 'Point Intercept 2'!J332, 'Point Intercept 1'!J332, "ERROR") -> 3.5 | K332: =if('Point Intercept 1'!K332 = 'Point Intercept 2'!K332, 'Point Intercept 1'!K332, "ERROR") -> FESMYU | L332: =if('Point Intercept 1'!L332 = 'Point Intercept 2'!L332, 'Point Intercept 1'!L332, "ERROR") -> Festuca myuros | M332: =if('Point Intercept 1'!N332 = 'Point Intercept 2'!M333, 'Point Intercept 1'!N332, "ERROR") | N332: =if('Point Intercept 1'!O332 = 'Point Intercept 2'!N333, 'Point Intercept 1'!O332, "ERROR") | O332: =if('Point Intercept 1'!P332 = 'Point Intercept 2'!O333, 'Point Intercept 1'!P332, "ERROR")
A333: =if('Point Intercept 1'!A333 = 'Point Intercept 2'!A333, 'Point Intercept 1'!A333, "ERROR") -> 4 | B333: =if('Point Intercept 1'!B333 = 'Point Intercept 2'!B333, 'Point Intercept 1'!B333, "ERROR") -> 2025 | C333: =if('Point Intercept 1'!C333 = 'Point Intercept 2'!C333, 'Point Intercept 1'!C333, "ERROR") -> 45755 | D333: =if('Point Intercept 1'!D333 = 'Point Intercept 2'!D333, 'Point Intercept 1'!D333, "ERROR") -> JC, TL | E333: =if('Point Intercept 1'!E333 = 'Point Intercept 2'!E333, 'Point Intercept 1'!E333, "ERROR") -> VB | F333: =if('Point Intercept 1'!F333 = 'Point Intercept 2'!F333, 'Point Intercept 1'!F333, "ERROR") -> 3 | G333: =if('Point Intercept 1'!G333 = 'Point Intercept 2'!G333, 'Point Intercept 1'!G333, "ERROR") -> LS | H333: =if('Point Intercept 1'!I333 = 'Point Intercept 2'!I333, 'Point Intercept 1'!I333, "ERROR") -> 8 | I333: =if('Point Intercept 1'!H333 = 'Point Intercept 2'!H333, 'Point Intercept 1'!H333, "ERROR") -> 1 | J333: =if('Point Intercept 1'!J333 = 'Point Intercept 2'!J333, 'Point Intercept 1'!J333, "ERROR") -> 3.5 | K333: =if('Point Intercept 1'!K333 = 'Point Intercept 2'!K333, 'Point Intercept 1'!K333, "ERROR") -> DEIFAS | L333: =if('Point Intercept 1'!L333 = 'Point Intercept 2'!L333, 'Point Intercept 1'!L333, "ERROR") -> Deinandra fasciculata | M333: =if('Point Intercept 1'!N333 = 'Point Intercept 2'!M334, 'Point Intercept 1'!N333, "ERROR") | N333: =if('Point Intercept 1'!O333 = 'Point Intercept 2'!N334, 'Point Intercept 1'!O333, "ERROR") | O333: =if('Point Intercept 1'!P333 = 'Point Intercept 2'!O334, 'Point Intercept 1'!P333, "ERROR")
A334: =if('Point Intercept 1'!A334 = 'Point Intercept 2'!A334, 'Point Intercept 1'!A334, "ERROR") -> 4 | B334: =if('Point Intercept 1'!B334 = 'Point Intercept 2'!B334, 'Point Intercept 1'!B334, "ERROR") -> 2025 | C334: =if('Point Intercept 1'!C334 = 'Point Intercept 2'!C334, 'Point Intercept 1'!C334, "ERROR") -> 45755 | D334: =if('Point Intercept 1'!D334 = 'Point Intercept 2'!D334, 'Point Intercept 1'!D334, "ERROR") -> JC, TL | E334: =if('Point Intercept 1'!E334 = 'Point Intercept 2'!E334, 'Point Intercept 1'!E334, "ERROR") -> VB | F334: =if('Point Intercept 1'!F334 = 'Point Intercept 2'!F334, 'Point Intercept 1'!F334, "ERROR") -> 3 | G334: =if('Point Intercept 1'!G334 = 'Point Intercept 2'!G334, 'Point Intercept 1'!G334, "ERROR") -> LS | H334: =if('Point Intercept 1'!I334 = 'Point Intercept 2'!I334, 'Point Intercept 1'!I334, "ERROR") -> 8 | I334: =if('Point Intercept 1'!H334 = 'Point Intercept 2'!H334, 'Point Intercept 1'!H334, "ERROR") -> 1 | J334: =if('Point Intercept 1'!J334 = 'Point Intercept 2'!J334, 'Point Intercept 1'!J334, "ERROR") -> 3.5 | K334: =if('Point Intercept 1'!K334 = 'Point Intercept 2'!K334, 'Point Intercept 1'!K334, "ERROR") -> MEDPOL | L334: =if('Point Intercept 1'!L334 = 'Point Intercept 2'!L334, 'Point Intercept 1'!L334, "ERROR") -> Medicago polymorpha | M334: =if('Point Intercept 1'!N334 = 'Point Intercept 2'!M335, 'Point Intercept 1'!N334, "ERROR") | N334: =if('Point Intercept 1'!O334 = 'Point Intercept 2'!N335, 'Point Intercept 1'!O334, "ERROR") | O334: =if('Point Intercept 1'!P334 = 'Point Intercept 2'!O335, 'Point Intercept 1'!P334, "ERROR")
A335: =if('Point Intercept 1'!A335 = 'Point Intercept 2'!A335, 'Point Intercept 1'!A335, "ERROR") -> 4 | B335: =if('Point Intercept 1'!B335 = 'Point Intercept 2'!B335, 'Point Intercept 1'!B335, "ERROR") -> 2025 | C335: =if('Point Intercept 1'!C335 = 'Point Intercept 2'!C335, 'Point Intercept 1'!C335, "ERROR") -> 45755 | D335: =if('Point Intercept 1'!D335 = 'Point Intercept 2'!D335, 'Point Intercept 1'!D335, "ERROR") -> JC, TL | E335: =if('Point Intercept 1'!E335 = 'Point Intercept 2'!E335, 'Point Intercept 1'!E335, "ERROR") -> VB | F335: =if('Point Intercept 1'!F335 = 'Point Intercept 2'!F335, 'Point Intercept 1'!F335, "ERROR") -> 3 | G335: =if('Point Intercept 1'!G335 = 'Point Intercept 2'!G335, 'Point Intercept 1'!G335, "ERROR") -> LS | H335: =if('Point Intercept 1'!I335 = 'Point Intercept 2'!I335, 'Point Intercept 1'!I335, "ERROR") -> 9 | I335: =if('Point Intercept 1'!H335 = 'Point Intercept 2'!H335, 'Point Intercept 1'!H335, "ERROR") -> 1 | J335: =if('Point Intercept 1'!J335 = 'Point Intercept 2'!J335, 'Point Intercept 1'!J335, "ERROR") -> 4 | K335: =if('Point Intercept 1'!K335 = 'Point Intercept 2'!K335, 'Point Intercept 1'!K335, "ERROR") -> L | L335: =if('Point Intercept 1'!L335 = 'Point Intercept 2'!L335, 'Point Intercept 1'!L335, "ERROR") -> Litter | M335: =if('Point Intercept 1'!N335 = 'Point Intercept 2'!M336, 'Point Intercept 1'!N335, "ERROR") | N335: =if('Point Intercept 1'!O335 = 'Point Intercept 2'!N336, 'Point Intercept 1'!O335, "ERROR") | O335: =if('Point Intercept 1'!P335 = 'Point Intercept 2'!O336, 'Point Intercept 1'!P335, "ERROR")
A336: =if('Point Intercept 1'!A336 = 'Point Intercept 2'!A336, 'Point Intercept 1'!A336, "ERROR") -> 4 | B336: =if('Point Intercept 1'!B336 = 'Point Intercept 2'!B336, 'Point Intercept 1'!B336, "ERROR") -> 2025 | C336: =if('Point Intercept 1'!C336 = 'Point Intercept 2'!C336, 'Point Intercept 1'!C336, "ERROR") -> 45755 | D336: =if('Point Intercept 1'!D336 = 'Point Intercept 2'!D336, 'Point Intercept 1'!D336, "ERROR") -> JC, TL | E336: =if('Point Intercept 1'!E336 = 'Point Intercept 2'!E336, 'Point Intercept 1'!E336, "ERROR") -> VB | F336: =if('Point Intercept 1'!F336 = 'Point Intercept 2'!F336, 'Point Intercept 1'!F336, "ERROR") -> 3 | G336: =if('Point Intercept 1'!G336 = 'Point Intercept 2'!G336, 'Point Intercept 1'!G336, "ERROR") -> LS | H336: =if('Point Intercept 1'!I336 = 'Point Intercept 2'!I336, 'Point Intercept 1'!I336, "ERROR") -> 9 | I336: =if('Point Intercept 1'!H336 = 'Point Intercept 2'!H336, 'Point Intercept 1'!H336, "ERROR") -> 1 | J336: =if('Point Intercept 1'!J336 = 'Point Intercept 2'!J336, 'Point Intercept 1'!J336, "ERROR") -> 4 | K336: =if('Point Intercept 1'!K336 = 'Point Intercept 2'!K336, 'Point Intercept 1'!K336, "ERROR") -> MEDPOL | L336: =if('Point Intercept 1'!L336 = 'Point Intercept 2'!L336, 'Point Intercept 1'!L336, "ERROR") -> Medicago polymorpha | M336: =if('Point Intercept 1'!N336 = 'Point Intercept 2'!M337, 'Point Intercept 1'!N336, "ERROR") | N336: =if('Point Intercept 1'!O336 = 'Point Intercept 2'!N337, 'Point Intercept 1'!O336, "ERROR") | O336: =if('Point Intercept 1'!P336 = 'Point Intercept 2'!O337, 'Point Intercept 1'!P336, "ERROR")
A337: =if('Point Intercept 1'!A337 = 'Point Intercept 2'!A337, 'Point Intercept 1'!A337, "ERROR") -> 4 | B337: =if('Point Intercept 1'!B337 = 'Point Intercept 2'!B337, 'Point Intercept 1'!B337, "ERROR") -> 2025 | C337: =if('Point Intercept 1'!C337 = 'Point Intercept 2'!C337, 'Point Intercept 1'!C337, "ERROR") -> 45755 | D337: =if('Point Intercept 1'!D337 = 'Point Intercept 2'!D337, 'Point Intercept 1'!D337, "ERROR") -> JC, TL | E337: =if('Point Intercept 1'!E337 = 'Point Intercept 2'!E337, 'Point Intercept 1'!E337, "ERROR") -> VB | F337: =if('Point Intercept 1'!F337 = 'Point Intercept 2'!F337, 'Point Intercept 1'!F337, "ERROR") -> 3 | G337: =if('Point Intercept 1'!G337 = 'Point Intercept 2'!G337, 'Point Intercept 1'!G337, "ERROR") -> LS | H337: =if('Point Intercept 1'!I337 = 'Point Intercept 2'!I337, 'Point Intercept 1'!I337, "ERROR") -> 10 | I337: =if('Point Intercept 1'!H337 = 'Point Intercept 2'!H337, 'Point Intercept 1'!H337, "ERROR") -> 1 | J337: =if('Point Intercept 1'!J337 = 'Point Intercept 2'!J337, 'Point Intercept 1'!J337, "ERROR") -> 4.5 | K337: =if('Point Intercept 1'!K337 = 'Point Intercept 2'!K337, 'Point Intercept 1'!K337, "ERROR") -> L | L337: =if('Point Intercept 1'!L337 = 'Point Intercept 2'!L337, 'Point Intercept 1'!L337, "ERROR") -> Litter | M337: =if('Point Intercept 1'!N337 = 'Point Intercept 2'!M338, 'Point Intercept 1'!N337, "ERROR") | N337: =if('Point Intercept 1'!O337 = 'Point Intercept 2'!N338, 'Point Intercept 1'!O337, "ERROR") | O337: =if('Point Intercept 1'!P337 = 'Point Intercept 2'!O338, 'Point Intercept 1'!P337, "ERROR")
A338: =if('Point Intercept 1'!A338 = 'Point Intercept 2'!A338, 'Point Intercept 1'!A338, "ERROR") -> 4 | B338: =if('Point Intercept 1'!B338 = 'Point Intercept 2'!B338, 'Point Intercept 1'!B338, "ERROR") -> 2025 | C338: =if('Point Intercept 1'!C338 = 'Point Intercept 2'!C338, 'Point Intercept 1'!C338, "ERROR") -> 45755 | D338: =if('Point Intercept 1'!D338 = 'Point Intercept 2'!D338, 'Point Intercept 1'!D338, "ERROR") -> JC, TL | E338: =if('Point Intercept 1'!E338 = 'Point Intercept 2'!E338, 'Point Intercept 1'!E338, "ERROR") -> VB | F338: =if('Point Intercept 1'!F338 = 'Point Intercept 2'!F338, 'Point Intercept 1'!F338, "ERROR") -> 3 | G338: =if('Point Intercept 1'!G338 = 'Point Intercept 2'!G338, 'Point Intercept 1'!G338, "ERROR") -> LS | H338: =if('Point Intercept 1'!I338 = 'Point Intercept 2'!I338, 'Point Intercept 1'!I338, "ERROR") -> 10 | I338: =if('Point Intercept 1'!H338 = 'Point Intercept 2'!H338, 'Point Intercept 1'!H338, "ERROR") -> 1 | J338: =if('Point Intercept 1'!J338 = 'Point Intercept 2'!J338, 'Point Intercept 1'!J338, "ERROR") -> 4.5 | K338: =if('Point Intercept 1'!K338 = 'Point Intercept 2'!K338, 'Point Intercept 1'!K338, "ERROR") -> DAUPUS | L338: =if('Point Intercept 1'!L338 = 'Point Intercept 2'!L338, 'Point Intercept 1'!L338, "ERROR") -> Daucus pusillus | M338: =if('Point Intercept 1'!N338 = 'Point Intercept 2'!M339, 'Point Intercept 1'!N338, "ERROR") | N338: =if('Point Intercept 1'!O338 = 'Point Intercept 2'!N339, 'Point Intercept 1'!O338, "ERROR") | O338: =if('Point Intercept 1'!P338 = 'Point Intercept 2'!O339, 'Point Intercept 1'!P338, "ERROR")
A339: =if('Point Intercept 1'!A339 = 'Point Intercept 2'!A339, 'Point Intercept 1'!A339, "ERROR") -> 4 | B339: =if('Point Intercept 1'!B339 = 'Point Intercept 2'!B339, 'Point Intercept 1'!B339, "ERROR") -> 2025 | C339: =if('Point Intercept 1'!C339 = 'Point Intercept 2'!C339, 'Point Intercept 1'!C339, "ERROR") -> 45755 | D339: =if('Point Intercept 1'!D339 = 'Point Intercept 2'!D339, 'Point Intercept 1'!D339, "ERROR") -> JC, TL | E339: =if('Point Intercept 1'!E339 = 'Point Intercept 2'!E339, 'Point Intercept 1'!E339, "ERROR") -> VB | F339: =if('Point Intercept 1'!F339 = 'Point Intercept 2'!F339, 'Point Intercept 1'!F339, "ERROR") -> 3 | G339: =if('Point Intercept 1'!G339 = 'Point Intercept 2'!G339, 'Point Intercept 1'!G339, "ERROR") -> LS | H339: =if('Point Intercept 1'!I339 = 'Point Intercept 2'!I339, 'Point Intercept 1'!I339, "ERROR") -> 10 | I339: =if('Point Intercept 1'!H339 = 'Point Intercept 2'!H339, 'Point Intercept 1'!H339, "ERROR") -> 1 | J339: =if('Point Intercept 1'!J339 = 'Point Intercept 2'!J339, 'Point Intercept 1'!J339, "ERROR") -> 4.5 | K339: =if('Point Intercept 1'!K339 = 'Point Intercept 2'!K339, 'Point Intercept 1'!K339, "ERROR") -> DEIFAS | L339: =if('Point Intercept 1'!L339 = 'Point Intercept 2'!L339, 'Point Intercept 1'!L339, "ERROR") -> Deinandra fasciculata | M339: =if('Point Intercept 1'!N339 = 'Point Intercept 2'!M340, 'Point Intercept 1'!N339, "ERROR") | N339: =if('Point Intercept 1'!O339 = 'Point Intercept 2'!N340, 'Point Intercept 1'!O339, "ERROR") | O339: =if('Point Intercept 1'!P339 = 'Point Intercept 2'!O340, 'Point Intercept 1'!P339, "ERROR")
A340: =if('Point Intercept 1'!A340 = 'Point Intercept 2'!A340, 'Point Intercept 1'!A340, "ERROR") -> 4 | B340: =if('Point Intercept 1'!B340 = 'Point Intercept 2'!B340, 'Point Intercept 1'!B340, "ERROR") -> 2025 | C340: =if('Point Intercept 1'!C340 = 'Point Intercept 2'!C340, 'Point Intercept 1'!C340, "ERROR") -> 45755 | D340: =if('Point Intercept 1'!D340 = 'Point Intercept 2'!D340, 'Point Intercept 1'!D340, "ERROR") -> JC, TL | E340: =if('Point Intercept 1'!E340 = 'Point Intercept 2'!E340, 'Point Intercept 1'!E340, "ERROR") -> VB | F340: =if('Point Intercept 1'!F340 = 'Point Intercept 2'!F340, 'Point Intercept 1'!F340, "ERROR") -> 3 | G340: =if('Point Intercept 1'!G340 = 'Point Intercept 2'!G340, 'Point Intercept 1'!G340, "ERROR") -> LS | H340: =if('Point Intercept 1'!I340 = 'Point Intercept 2'!I340, 'Point Intercept 1'!I340, "ERROR") -> 10 | I340: =if('Point Intercept 1'!H340 = 'Point Intercept 2'!H340, 'Point Intercept 1'!H340, "ERROR") -> 1 | J340: =if('Point Intercept 1'!J340 = 'Point Intercept 2'!J340, 'Point Intercept 1'!J340, "ERROR") -> 4.5 | K340: =if('Point Intercept 1'!K340 = 'Point Intercept 2'!K340, 'Point Intercept 1'!K340, "ERROR") -> FESMYU | L340: =if('Point Intercept 1'!L340 = 'Point Intercept 2'!L340, 'Point Intercept 1'!L340, "ERROR") -> Festuca myuros | M340: =if('Point Intercept 1'!N340 = 'Point Intercept 2'!M341, 'Point Intercept 1'!N340, "ERROR") | N340: =if('Point Intercept 1'!O340 = 'Point Intercept 2'!N341, 'Point Intercept 1'!O340, "ERROR") | O340: =if('Point Intercept 1'!P340 = 'Point Intercept 2'!O341, 'Point Intercept 1'!P340, "ERROR")
A341: =if('Point Intercept 1'!A341 = 'Point Intercept 2'!A341, 'Point Intercept 1'!A341, "ERROR") -> 4 | B341: =if('Point Intercept 1'!B341 = 'Point Intercept 2'!B341, 'Point Intercept 1'!B341, "ERROR") -> 2025 | C341: =if('Point Intercept 1'!C341 = 'Point Intercept 2'!C341, 'Point Intercept 1'!C341, "ERROR") -> 45755 | D341: =if('Point Intercept 1'!D341 = 'Point Intercept 2'!D341, 'Point Intercept 1'!D341, "ERROR") -> JC, TL | E341: =if('Point Intercept 1'!E341 = 'Point Intercept 2'!E341, 'Point Intercept 1'!E341, "ERROR") -> VB | F341: =if('Point Intercept 1'!F341 = 'Point Intercept 2'!F341, 'Point Intercept 1'!F341, "ERROR") -> 3 | G341: =if('Point Intercept 1'!G341 = 'Point Intercept 2'!G341, 'Point Intercept 1'!G341, "ERROR") -> LS | H341: =if('Point Intercept 1'!I341 = 'Point Intercept 2'!I341, 'Point Intercept 1'!I341, "ERROR") -> 11 | I341: =if('Point Intercept 1'!H341 = 'Point Intercept 2'!H341, 'Point Intercept 1'!H341, "ERROR") -> 1 | J341: =if('Point Intercept 1'!J341 = 'Point Intercept 2'!J341, 'Point Intercept 1'!J341, "ERROR") -> 5 | K341: =if('Point Intercept 1'!K341 = 'Point Intercept 2'!K341, 'Point Intercept 1'!K341, "ERROR") -> L | L341: =if('Point Intercept 1'!L341 = 'Point Intercept 2'!L341, 'Point Intercept 1'!L341, "ERROR") -> Litter | M341: =if('Point Intercept 1'!N341 = 'Point Intercept 2'!M342, 'Point Intercept 1'!N341, "ERROR") | N341: =if('Point Intercept 1'!O341 = 'Point Intercept 2'!N342, 'Point Intercept 1'!O341, "ERROR") | O341: =if('Point Intercept 1'!P341 = 'Point Intercept 2'!O342, 'Point Intercept 1'!P341, "ERROR")
A342: =if('Point Intercept 1'!A342 = 'Point Intercept 2'!A342, 'Point Intercept 1'!A342, "ERROR") -> 4 | B342: =if('Point Intercept 1'!B342 = 'Point Intercept 2'!B342, 'Point Intercept 1'!B342, "ERROR") -> 2025 | C342: =if('Point Intercept 1'!C342 = 'Point Intercept 2'!C342, 'Point Intercept 1'!C342, "ERROR") -> 45755 | D342: =if('Point Intercept 1'!D342 = 'Point Intercept 2'!D342, 'Point Intercept 1'!D342, "ERROR") -> JC, TL | E342: =if('Point Intercept 1'!E342 = 'Point Intercept 2'!E342, 'Point Intercept 1'!E342, "ERROR") -> VB | F342: =if('Point Intercept 1'!F342 = 'Point Intercept 2'!F342, 'Point Intercept 1'!F342, "ERROR") -> 3 | G342: =if('Point Intercept 1'!G342 = 'Point Intercept 2'!G342, 'Point Intercept 1'!G342, "ERROR") -> LS | H342: =if('Point Intercept 1'!I342 = 'Point Intercept 2'!I342, 'Point Intercept 1'!I342, "ERROR") -> 11 | I342: =if('Point Intercept 1'!H342 = 'Point Intercept 2'!H342, 'Point Intercept 1'!H342, "ERROR") -> 1 | J342: =if('Point Intercept 1'!J342 = 'Point Intercept 2'!J342, 'Point Intercept 1'!J342, "ERROR") -> 5 | K342: =if('Point Intercept 1'!K342 = 'Point Intercept 2'!K342, 'Point Intercept 1'!K342, "ERROR") -> FESMYU | L342: =if('Point Intercept 1'!L342 = 'Point Intercept 2'!L342, 'Point Intercept 1'!L342, "ERROR") -> Festuca myuros | M342: =if('Point Intercept 1'!N342 = 'Point Intercept 2'!M343, 'Point Intercept 1'!N342, "ERROR") | N342: =if('Point Intercept 1'!O342 = 'Point Intercept 2'!N343, 'Point Intercept 1'!O342, "ERROR") | O342: =if('Point Intercept 1'!P342 = 'Point Intercept 2'!O343, 'Point Intercept 1'!P342, "ERROR")
... A445: =if('Point Intercept 1'!A445 = 'Point Intercept 2'!A445, 'Point Intercept 1'!A445, "ERROR") -> 5 | B445: =if('Point Intercept 1'!B445 = 'Point Intercept 2'!B445, 'Point Intercept 1'!B445, "ERROR") -> 2025 | C445: =if('Point Intercept 1'!C445 = 'Point Intercept 2'!C445, 'Point Intercept 1'!C445, "ERROR") -> 45755 | D445: =if('Point Intercept 1'!D445 = 'Point Intercept 2'!D445, 'Point Intercept 1'!D445, "ERROR") -> TL, JC | E445: =if('Point Intercept 1'!E445 = 'Point Intercept 2'!E445, 'Point Intercept 1'!E445, "ERROR") -> VB | F445: =if('Point Intercept 1'!F445 = 'Point Intercept 2'!F445, 'Point Intercept 1'!F445, "ERROR") -> 3 | G445: =if('Point Intercept 1'!G445 = 'Point Intercept 2'!G445, 'Point Intercept 1'!G445, "ERROR") -> SS | H445: =if('Point Intercept 1'!I445 = 'Point Intercept 2'!I445, 'Point Intercept 1'!I445, "ERROR") -> 12 | I445: =if('Point Intercept 1'!H445 = 'Point Intercept 2'!H445, 'Point Intercept 1'!H445, "ERROR") -> 1 | J445: =if('Point Intercept 1'!J445 = 'Point Intercept 2'!J445, 'Point Intercept 1'!J445, "ERROR") -> 9 | K445: =if('Point Intercept 1'!K445 = 'Point Intercept 2'!K445, 'Point Intercept 1'!K445, "ERROR") -> L | L445: =if('Point Intercept 1'!L445 = 'Point Intercept 2'!L445, 'Point Intercept 1'!L445, "ERROR") -> Litter | M445: =if('Point Intercept 1'!N445 = 'Point Intercept 2'!M446, 'Point Intercept 1'!N445, "ERROR") | N445: =if('Point Intercept 1'!O445 = 'Point Intercept 2'!N446, 'Point Intercept 1'!O445, "ERROR") | O445: =if('Point Intercept 1'!P445 = 'Point Intercept 2'!O446, 'Point Intercept 1'!P445, "ERROR")
A446: =if('Point Intercept 1'!A446 = 'Point Intercept 2'!A446, 'Point Intercept 1'!A446, "ERROR") -> 5 | B446: =if('Point Intercept 1'!B446 = 'Point Intercept 2'!B446, 'Point Intercept 1'!B446, "ERROR") -> 2025 | C446: =if('Point Intercept 1'!C446 = 'Point Intercept 2'!C446, 'Point Intercept 1'!C446, "ERROR") -> 45755 | D446: =if('Point Intercept 1'!D446 = 'Point Intercept 2'!D446, 'Point Intercept 1'!D446, "ERROR") -> TL, JC | E446: =if('Point Intercept 1'!E446 = 'Point Intercept 2'!E446, 'Point Intercept 1'!E446, "ERROR") -> VB | F446: =if('Point Intercept 1'!F446 = 'Point Intercept 2'!F446, 'Point Intercept 1'!F446, "ERROR") -> 3 | G446: =if('Point Intercept 1'!G446 = 'Point Intercept 2'!G446, 'Point Intercept 1'!G446, "ERROR") -> SS | H446: =if('Point Intercept 1'!I446 = 'Point Intercept 2'!I446, 'Point Intercept 1'!I446, "ERROR") -> 12 | I446: =if('Point Intercept 1'!H446 = 'Point Intercept 2'!H446, 'Point Intercept 1'!H446, "ERROR") -> 1 | J446: =if('Point Intercept 1'!J446 = 'Point Intercept 2'!J446, 'Point Intercept 1'!J446, "ERROR") -> 9 | K446: =if('Point Intercept 1'!K446 = 'Point Intercept 2'!K446, 'Point Intercept 1'!K446, "ERROR") -> SONASP | L446: =if('Point Intercept 1'!L446 = 'Point Intercept 2'!L446, 'Point Intercept 1'!L446, "ERROR") -> Sonchus asper
A447: =if('Point Intercept 1'!A447 = 'Point Intercept 2'!A447, 'Point Intercept 1'!A447, "ERROR") -> 5 | B447: =if('Point Intercept 1'!B447 = 'Point Intercept 2'!B447, 'Point Intercept 1'!B447, "ERROR") -> 2025 | C447: =if('Point Intercept 1'!C447 = 'Point Intercept 2'!C447, 'Point Intercept 1'!C447, "ERROR") -> 45755 | D447: =if('Point Intercept 1'!D447 = 'Point Intercept 2'!D447, 'Point Intercept 1'!D447, "ERROR") -> TL, JC | E447: =if('Point Intercept 1'!E447 = 'Point Intercept 2'!E447, 'Point Intercept 1'!E447, "ERROR") -> VB | F447: =if('Point Intercept 1'!F447 = 'Point Intercept 2'!F447, 'Point Intercept 1'!F447, "ERROR") -> 3 | G447: =if('Point Intercept 1'!G447 = 'Point Intercept 2'!G447, 'Point Intercept 1'!G447, "ERROR") -> SS | H447: =if('Point Intercept 1'!I447 = 'Point Intercept 2'!I447, 'Point Intercept 1'!I447, "ERROR") -> 13 | I447: =if('Point Intercept 1'!H447 = 'Point Intercept 2'!H447, 'Point Intercept 1'!H447, "ERROR") -> 1 | J447: =if('Point Intercept 1'!J447 = 'Point Intercept 2'!J447, 'Point Intercept 1'!J447, "ERROR") -> 10 | K447: =if('Point Intercept 1'!K447 = 'Point Intercept 2'!K447, 'Point Intercept 1'!K447, "ERROR") -> L | L447: =if('Point Intercept 1'!L447 = 'Point Intercept 2'!L447, 'Point Intercept 1'!L447, "ERROR") -> Litter
A448: =if('Point Intercept 1'!A448 = 'Point Intercept 2'!A448, 'Point Intercept 1'!A448, "ERROR") -> 5 | B448: =if('Point Intercept 1'!B448 = 'Point Intercept 2'!B448, 'Point Intercept 1'!B448, "ERROR") -> 2025 | C448: =if('Point Intercept 1'!C448 = 'Point Intercept 2'!C448, 'Point Intercept 1'!C448, "ERROR") -> 45755 | D448: =if('Point Intercept 1'!D448 = 'Point Intercept 2'!D448, 'Point Intercept 1'!D448, "ERROR") -> TL, JC | E448: =if('Point Intercept 1'!E448 = 'Point Intercept 2'!E448, 'Point Intercept 1'!E448, "ERROR") -> VB | F448: =if('Point Intercept 1'!F448 = 'Point Intercept 2'!F448, 'Point Intercept 1'!F448, "ERROR") -> 3 | G448: =if('Point Intercept 1'!G448 = 'Point Intercept 2'!G448, 'Point Intercept 1'!G448, "ERROR") -> SS | H448: =if('Point Intercept 1'!I448 = 'Point Intercept 2'!I448, 'Point Intercept 1'!I448, "ERROR") -> 13 | I448: =if('Point Intercept 1'!H448 = 'Point Intercept 2'!H448, 'Point Intercept 1'!H448, "ERROR") -> 1 | J448: =if('Point Intercept 1'!J448 = 'Point Intercept 2'!J448, 'Point Intercept 1'!J448, "ERROR") -> 10 | K448: =if('Point Intercept 1'!K448 = 'Point Intercept 2'!K448, 'Point Intercept 1'!K448, "ERROR") -> SONASP | L448: =if('Point Intercept 1'!L448 = 'Point Intercept 2'!L448, 'Point Intercept 1'!L448, "ERROR") -> Sonchus asper
A449: =if('Point Intercept 1'!A449 = 'Point Intercept 2'!A449, 'Point Intercept 1'!A449, "ERROR") -> 5 | B449: =if('Point Intercept 1'!B449 = 'Point Intercept 2'!B449, 'Point Intercept 1'!B449, "ERROR") -> 2025 | C449: =if('Point Intercept 1'!C449 = 'Point Intercept 2'!C449, 'Point Intercept 1'!C449, "ERROR") -> 45755 | D449: =if('Point Intercept 1'!D449 = 'Point Intercept 2'!D449, 'Point Intercept 1'!D449, "ERROR") -> TL, JC | E449: =if('Point Intercept 1'!E449 = 'Point Intercept 2'!E449, 'Point Intercept 1'!E449, "ERROR") -> VB | F449: =if('Point Intercept 1'!F449 = 'Point Intercept 2'!F449, 'Point Intercept 1'!F449, "ERROR") -> 3 | G449: =if('Point Intercept 1'!G449 = 'Point Intercept 2'!G449, 'Point Intercept 1'!G449, "ERROR") -> SS | H449: =if('Point Intercept 1'!I449 = 'Point Intercept 2'!I449, 'Point Intercept 1'!I449, "ERROR") -> 14 | I449: =if('Point Intercept 1'!H449 = 'Point Intercept 2'!H449, 'Point Intercept 1'!H449, "ERROR") -> 1 | J449: =if('Point Intercept 1'!J449 = 'Point Intercept 2'!J449, 'Point Intercept 1'!J449, "ERROR") -> 11 | K449: =if('Point Intercept 1'!K449 = 'Point Intercept 2'!K449, 'Point Intercept 1'!K449, "ERROR") -> B | L449: =if('Point Intercept 1'!L449 = 'Point Intercept 2'!L449, 'Point Intercept 1'!L449, "ERROR") -> Bareground
A450: =if('Point Intercept 1'!A450 = 'Point Intercept 2'!A450, 'Point Intercept 1'!A450, "ERROR") -> 5 | B450: =if('Point Intercept 1'!B450 = 'Point Intercept 2'!B450, 'Point Intercept 1'!B450, "ERROR") -> 2025 | C450: =if('Point Intercept 1'!C450 = 'Point Intercept 2'!C450, 'Point Intercept 1'!C450, "ERROR") -> 45755 | D450: =if('Point Intercept 1'!D450 = 'Point Intercept 2'!D450, 'Point Intercept 1'!D450, "ERROR") -> TL, JC | E450: =if('Point Intercept 1'!E450 = 'Point Intercept 2'!E450, 'Point Intercept 1'!E450, "ERROR") -> VB | F450: =if('Point Intercept 1'!F450 = 'Point Intercept 2'!F450, 'Point Intercept 1'!F450, "ERROR") -> 3 | G450: =if('Point Intercept 1'!G450 = 'Point Intercept 2'!G450, 'Point Intercept 1'!G450, "ERROR") -> SS | H450: =if('Point Intercept 1'!I450 = 'Point Intercept 2'!I450, 'Point Intercept 1'!I450, "ERROR") -> 15 | I450: =if('Point Intercept 1'!H450 = 'Point Intercept 2'!H450, 'Point Intercept 1'!H450, "ERROR") -> 1 | J450: =if('Point Intercept 1'!J450 = 'Point Intercept 2'!J450, 'Point Intercept 1'!J450, "ERROR") -> 12 | K450: =if('Point Intercept 1'!K450 = 'Point Intercept 2'!K450, 'Point Intercept 1'!K450, "ERROR") -> B | L450: =if('Point Intercept 1'!L450 = 'Point Intercept 2'!L450, 'Point Intercept 1'!L450, "ERROR") -> Bareground
A451: =if('Point Intercept 1'!A451 = 'Point Intercept 2'!A451, 'Point Intercept 1'!A451, "ERROR") -> 5 | B451: =if('Point Intercept 1'!B451 = 'Point Intercept 2'!B451, 'Point Intercept 1'!B451, "ERROR") -> 2025 | C451: =if('Point Intercept 1'!C451 = 'Point Intercept 2'!C451, 'Point Intercept 1'!C451, "ERROR") -> 45755 | D451: =if('Point Intercept 1'!D451 = 'Point Intercept 2'!D451, 'Point Intercept 1'!D451, "ERROR") -> TL, JC | E451: =if('Point Intercept 1'!E451 = 'Point Intercept 2'!E451, 'Point Intercept 1'!E451, "ERROR") -> VB | F451: =if('Point Intercept 1'!F451 = 'Point Intercept 2'!F451, 'Point Intercept 1'!F451, "ERROR") -> 3 | G451: =if('Point Intercept 1'!G451 = 'Point Intercept 2'!G451, 'Point Intercept 1'!G451, "ERROR") -> SS | H451: =if('Point Intercept 1'!I451 = 'Point Intercept 2'!I451, 'Point Intercept 1'!I451, "ERROR") -> 1 | I451: =if('Point Intercept 1'!H451 = 'Point Intercept 2'!H451, 'Point Intercept 1'!H451, "ERROR") -> 2 | J451: =if('Point Intercept 1'!J451 = 'Point Intercept 2'!J451, 'Point Intercept 1'!J451, "ERROR") -> 0 | K451: =if('Point Intercept 1'!K451 = 'Point Intercept 2'!K451, 'Point Intercept 1'!K451, "ERROR") -> L | L451: =if('Point Intercept 1'!L451 = 'Point Intercept 2'!L451, 'Point Intercept 1'!L451, "ERROR") -> Litter
A452: =if('Point Intercept 1'!A452 = 'Point Intercept 2'!A452, 'Point Intercept 1'!A452, "ERROR") -> 5 | B452: =if('Point Intercept 1'!B452 = 'Point Intercept 2'!B452, 'Point Intercept 1'!B452, "ERROR") -> 2025 | C452: =if('Point Intercept 1'!C452 = 'Point Intercept 2'!C452, 'Point Intercept 1'!C452, "ERROR") -> 45755 | D452: =if('Point Intercept 1'!D452 = 'Point Intercept 2'!D452, 'Point Intercept 1'!D452, "ERROR") -> TL, JC | E452: =if('Point Intercept 1'!E452 = 'Point Intercept 2'!E452, 'Point Intercept 1'!E452, "ERROR") -> VB | F452: =if('Point Intercept 1'!F452 = 'Point Intercept 2'!F452, 'Point Intercept 1'!F452, "ERROR") -> 3 | G452: =if('Point Intercept 1'!G452 = 'Point Intercept 2'!G452, 'Point Intercept 1'!G452, "ERROR") -> SS | H452: =if('Point Intercept 1'!I452 = 'Point Intercept 2'!I452, 'Point Intercept 1'!I452, "ERROR") -> 1 | I452: =if('Point Intercept 1'!H452 = 'Point Intercept 2'!H452, 'Point Intercept 1'!H452, "ERROR") -> 2 | J452: =if('Point Intercept 1'!J452 = 'Point Intercept 2'!J452, 'Point Intercept 1'!J452, "ERROR") -> 0 | K452: =if('Point Intercept 1'!K452 = 'Point Intercept 2'!K452, 'Point Intercept 1'!K452, "ERROR") -> CYLPRO | L452: =if('Point Intercept 1'!L452 = 'Point Intercept 2'!L452, 'Point Intercept 1'!L452, "ERROR") -> Cylindropuntia prolifera
