Workbook

Sheet Data
A1: Page # | B1: Year | C1: Date | D1: Team | E1: Site | F1: Block # | G1: Treatment | H1: Point | I1: Transect | J1: Distance | K1: Code | L1: Species | N1: Notes
A2: (#) | B2: 2023 | C2: mm/dd/yy | D2: initials | E2: CU/VB/GB | F2: 43469 | G2: LS/LU/SS/SU | H2: 1-30 | I2: 1 or 2 | J2: 0-12m | K2: six-letter code | L2: full name | N2: enter as written
A3: 1 | B3: 2023 | C3: 45197 | D3: MG, TL | E3: GB | F3: 1 | G3: SS | H3: 1 | I3: 1 | J3: 0 | K3: L | L3: =VLOOKUP(K3, 'Alphabetical by species code'!A:B, 2, FALSE) -> Litter | M3: =VLOOKUP(L3, 'Alphabetical by species code'!B:C, 2, FALSE) -> Ground Cover
A4: 1 | B4: 2023 | C4: 45197 | D4: MG, TL | E4: GB | F4: 1 | G4: SS | H4: 1 | I4: 1 | J4: 0 | K4: STEDIE | L4: =VLOOKUP(K4, 'Alphabetical by species code'!A:B, 2, FALSE) -> Stephanomeria diegensis | M4: =VLOOKUP(L4, 'Alphabetical by species code'!B:C, 2, FALSE) -> Native
A5: 1 | B5: 2023 | C5: 45197 | D5: MG, TL | E5: GB | F5: 1 | G5: SS | H5: 2 | I5: 1 | J5: 1 | K5: L | L5: =VLOOKUP(K5, 'Alphabetical by species code'!A:B, 2, FALSE) -> Litter | M5: =VLOOKUP(L5, 'Alphabetical by species code'!B:C, 2, FALSE) -> Ground Cover
A6: 1 | B6: 2023 | C6: 45197 | D6: MG, TL | E6: GB | F6: 1 | G6: SS | H6: 2 | I6: 1 | J6: 1 | K6: OPULIT | L6: =VLOOKUP(K6, 'Alphabetical by species code'!A:B, 2, FALSE) -> Opuntia littoralis | M6: =VLOOKUP(L6, 'Alphabetical by species code'!B:C, 2, FALSE) -> Native
A7: 1 | B7: 2023 | C7: 45197 | D7: MG, TL | E7: GB | F7: 1 | G7: SS | H7: 2 | I7: 1 | J7: 1 | K7: NNG | L7: =VLOOKUP(K7, 'Alphabetical by species code'!A:B, 2, FALSE) -> Non Native Grass | M7: =VLOOKUP(L7, 'Alphabetical by species code'!B:C, 2, FALSE) -> Non-Native | N7: NNG - non-native grass
A8: 1 | B8: 2023 | C8: 45197 | D8: MG, TL | E8: GB | F8: 1 | G8: SS | H8: 3 | I8: 1 | J8: 1.5 | K8: R | L8: =VLOOKUP(K8, 'Alphabetical by species code'!A:B, 2, FALSE) -> Rock | M8: =VLOOKUP(L8, 'Alphabetical by species code'!B:C, 2, FALSE) -> Ground Cover
A9: 1 | B9: 2023 | C9: 45197 | D9: MG, TL | E9: GB | F9: 1 | G9: SS | H9: 3 | I9: 1 | J9: 1.5 | K9: STEDIE | L9: =VLOOKUP(K9, 'Alphabetical by species code'!A:B, 2, FALSE) -> Stephanomeria diegensis | M9: =VLOOKUP(L9, 'Alphabetical by species code'!B:C, 2, FALSE) -> Native
A10: 1 | B10: 2023 | C10: 45197 | D10: MG, TL | E10: GB | F10: 1 | G10: SS | H10: 4 | I10: 1 | J10: 2 | K10: L | L10: =VLOOKUP(K10, 'Alphabetical by species code'!A:B, 2, FALSE) -> Litter | M10: =VLOOKUP(L10, 'Alphabetical by species code'!B:C, 2, FALSE) -> Ground Cover
A11: 1 | B11: 2023 | C11: 45197 | D11: MG, TL | E11: GB | F11: 1 | G11: SS | H11: 4 | I11: 1 | J11: 2 | K11: STEDIE | L11: =VLOOKUP(K11, 'Alphabetical by species code'!A:B, 2, FALSE) -> Stephanomeria diegensis | M11: =VLOOKUP(L11, 'Alphabetical by species code'!B:C, 2, FALSE) -> Native
A12: 1 | B12: 2023 | C12: 45197 | D12: MG, TL | E12: GB | F12: 1 | G12: SS | H12: 5 | I12: 1 | J12: 3 | K12: R | L12: =VLOOKUP(K12, 'Alphabetical by species code'!A:B, 2, FALSE) -> Rock | M12: =VLOOKUP(L12, 'Alphabetical by species code'!B:C, 2, FALSE) -> Ground Cover
A13: 1 | B13: 2023 | C13: 45197 | D13: MG, TL | E13: GB | F13: 1 | G13: SS | H13: 6 | I13: 1 | J13: 3.5 | K13: R | L13: =VLOOKUP(K13, 'Alphabetical by species code'!A:B, 2, FALSE) -> Rock | M13: =VLOOKUP(L13, 'Alphabetical by species code'!B:C, 2, FALSE) -> Ground Cover
A14: 1 | B14: 2023 | C14: 45197 | D14: MG, TL | E14: GB | F14: 1 | G14: SS | H14: 6 | I14: 1 | J14: 3.5 | K14: NNG | L14: =VLOOKUP(K14, 'Alphabetical by species code'!A:B, 2, FALSE) -> Non Native Grass | M14: =VLOOKUP(L14, 'Alphabetical by species code'!B:C, 2, FALSE) -> Non-Native
A15: 1 | B15: 2023 | C15: 45197 | D15: MG, TL | E15: GB | F15: 1 | G15: SS | H15: 6 | I15: 1 | J15: 3.5 | K15: STEDIE | L15: =VLOOKUP(K15, 'Alphabetical by species code'!A:B, 2, FALSE) -> Stephanomeria diegensis | M15: =VLOOKUP(L15, 'Alphabetical by species code'!B:C, 2, FALSE) -> Native
A16: 1 | B16: 2023 | C16: 45197 | D16: MG, TL | E16: GB | F16: 1 | G16: SS | H16: 7 | I16: 1 | J16: 4 | K16: L | L16: =VLOOKUP(K16, 'Alphabetical by species code'!A:B, 2, FALSE) -> Litter | M16: =VLOOKUP(L16, 'Alphabetical by species code'!B:C, 2, FALSE) -> Ground Cover
A17: 1 | B17: 2023 | C17: 45197 | D17: MG, TL | E17: GB | F17: 1 | G17: SS | H17: 8 | I17: 1 | J17: 5 | K17: L | L17: =VLOOKUP(K17, 'Alphabetical by species code'!A:B, 2, FALSE) -> Litter | M17: =VLOOKUP(L17, 'Alphabetical by species code'!B:C, 2, FALSE) -> Ground Cover
A18: 1 | B18: 2023 | C18: 45197 | D18: MG, TL | E18: GB | F18: 1 | G18: SS | H18: 9 | I18: 1 | J18: 7 | K18: L | L18: =VLOOKUP(K18, 'Alphabetical by species code'!A:B, 2, FALSE) -> Litter | M18: =VLOOKUP(L18, 'Alphabetical by species code'!B:C, 2, FALSE) -> Ground Cover
A19: 1 | B19: 2023 | C19: 45197 | D19: MG, TL | E19: GB | F19: 1 | G19: SS | H19: 9 | I19: 1 | J19: 7 | K19: STEDIE | L19: =VLOOKUP(K19, 'Alphabetical by species code'!A:B, 2, FALSE) -> Stephanomeria diegensis | M19: =VLOOKUP(L19, 'Alphabetical by species code'!B:C, 2, FALSE) -> Native
... A61: 2 | B61: 2023 | C61: 45197 | D61: MG, TL | E61: GB | F61: 1 | G61: SU | H61: 4 | I61: 1 | J61: 2 | K61: STEDIE | L61: =VLOOKUP(K61, 'Alphabetical by species code'!A:B, 2, FALSE) -> Stephanomeria diegensis | M61: =VLOOKUP(L61, 'Alphabetical by species code'!B:C, 2, FALSE) -> Native
A62: 2 | B62: 2023 | C62: 45197 | D62: MG, TL | E62: GB | F62: 1 | G62: SU | H62: 4 | I62: 1 | J62: 2 | K62: EUPFEN | L62: =VLOOKUP(K62, 'Alphabetical by species code'!A:B, 2, FALSE) -> #N/A | M62: =VLOOKUP(L62, 'Alphabetical by species code'!B:C, 2, FALSE) -> #N/A | N62: * TL took photo
A63: 2 | B63: 2023 | C63: 45197 | D63: MG, TL | E63: GB | F63: 1 | G63: SU | H63: 5 | I63: 1 | J63: 3 | K63: L | L63: =VLOOKUP(K63, 'Alphabetical by species code'!A:B, 2, FALSE) -> Litter | M63: =VLOOKUP(L63, 'Alphabetical by species code'!B:C, 2, FALSE) -> Ground Cover
A64: 2 | B64: 2023 | C64: 45197 | D64: MG, TL | E64: GB | F64: 1 | G64: SU | H64: 5 | I64: 1 | J64: 3 | K64: STEDIE | L64: =VLOOKUP(K64, 'Alphabetical by species code'!A:B, 2, FALSE) -> Stephanomeria diegensis | M64: =VLOOKUP(L64, 'Alphabetical by species code'!B:C, 2, FALSE) -> Native
A65: 2 | B65: 2023 | C65: 45197 | D65: MG, TL | E65: GB | F65: 1 | G65: SU | H65: 6 | I65: 1 | J65: 3.5 | K65: L | L65: =VLOOKUP(K65, 'Alphabetical by species code'!A:B, 2, FALSE) -> Litter | M65: =VLOOKUP(L65, 'Alphabetical by species code'!B:C, 2, FALSE) -> Ground Cover
A66: 2 | B66: 2023 | C66: 45197 | D66: MG, TL | E66: GB | F66: 1 | G66: SU | H66: 6 | I66: 1 | J66: 3.5 | K66: EUPFEN | L66: =VLOOKUP(K66, 'Alphabetical by species code'!A:B, 2, FALSE) -> #N/A | M66: =VLOOKUP(L66, 'Alphabetical by species code'!B:C, 2, FALSE) -> #N/A
A67: 2 | B67: 2023 | C67: 45197 | D67: MG, TL | E67: GB | F67: 1 | G67: SU | H67: 7 | I67: 1 | J67: 4 | K67: B | L67: =VLOOKUP(K67, 'Alphabetical by species code'!A:B, 2, FALSE) -> Bareground | M67: =VLOOKUP(L67, 'Alphabetical by species code'!B:C, 2, FALSE) -> Ground Cover
A68: 2 | B68: 2023 | C68: 45197 | D68: MG, TL | E68: GB | F68: 1 | G68: SU | H68: 8 | I68: 1 | J68: 5 | K68: L | L68: =VLOOKUP(K68, 'Alphabetical by species code'!A:B, 2, FALSE) -> Litter | M68: =VLOOKUP(L68, 'Alphabetical by species code'!B:C, 2, FALSE) -> Ground Cover
A69: 2 | B69: 2023 | C69: 45197 | D69: MG, TL | E69: GB | F69: 1 | G69: SU | H69: 8 | I69: 1 | J69: 5 | K69: NNG | L69: =VLOOKUP(K69, 'Alphabetical by species code'!A:B, 2, FALSE) -> Non Native Grass | M69: =VLOOKUP(L69, 'Alphabetical by species code'!B:C, 2, FALSE) -> Non-Native | N69: NNG = non-native grass
A70: 2 | B70: 2023 | C70: 45197 | D70: MG, TL | E70: GB | F70: 1 | G70: SU | H70: 9 | I70: 1 | J70: 7 | K70: L | L70: =VLOOKUP(K70, 'Alphabetical by species code'!A:B, 2, FALSE) -> Litter | M70: =VLOOKUP(L70, 'Alphabetical by species code'!B:C, 2, FALSE) -> Ground Cover
A71: 2 | B71: 2023 | C71: 45197 | D71: MG, TL | E71: GB | F71: 1 | G71: SU | H71: 9 | I71: 1 | J71: 7 | K71: STEDIE | L71: =VLOOKUP(K71, 'Alphabetical by species code'!A:B, 2, FALSE) -> Stephanomeria diegensis | M71: =VLOOKUP(L71, 'Alphabetical by species code'!B:C, 2, FALSE) -> Native
A72: 2 | B72: 2023 | C72: 45197 | D72: MG, TL | E72: GB | F72: 1 | G72: SU | H72: 10 | I72: 1 | J72: 8 | K72: L | L72: =VLOOKUP(K72, 'Alphabetical by species code'!A:B, 2, FALSE) -> Litter | M72: =VLOOKUP(L72, 'Alphabetical by species code'!B:C, 2, FALSE) -> Ground Cover
A73: 2 | B73: 2023 | C73: 45197 | D73: MG, TL | E73: GB | F73: 1 | G73: SU | H73: 11 | I73: 1 | J73: 8.5 | K73: L | L73: =VLOOKUP(K73, 'Alphabetical by species code'!A:B, 2, FALSE) -> Litter | M73: =VLOOKUP(L73, 'Alphabetical by species code'!B:C, 2, FALSE) -> Ground Cover
A74: 2 | B74: 2023 | C74: 45197 | D74: MG, TL | E74: GB | F74: 1 | G74: SU | H74: 11 | I74: 1 | J74: 8.5 | K74: STEDIE | L74: =VLOOKUP(K74, 'Alphabetical by species code'!A:B, 2, FALSE) -> Stephanomeria diegensis | M74: =VLOOKUP(L74, 'Alphabetical by species code'!B:C, 2, FALSE) -> Native
A75: 2 | B75: 2023 | C75: 45197 | D75: MG, TL | E75: GB | F75: 1 | G75: SU | H75: 12 | I75: 1 | J75: 9 | K75: L | L75: =VLOOKUP(K75, 'Alphabetical by species code'!A:B, 2, FALSE) -> Litter | M75: =VLOOKUP(L75, 'Alphabetical by species code'!B:C, 2, FALSE) -> Ground Cover
A76: 2 | B76: 2023 | C76: 45197 | D76: MG, TL | E76: GB | F76: 1 | G76: SU | H76: 12 | I76: 1 | J76: 9 | K76: EUPMAC | L76: =VLOOKUP(K76, 'Alphabetical by species code'!A:B, 2, FALSE) -> #N/A | M76: =VLOOKUP(L76, 'Alphabetical by species code'!B:C, 2, FALSE) -> #N/A | N76: * Euphorbia maculata
A77: 2 | B77: 2023 | C77: 45197 | D77: MG, TL | E77: GB | F77: 1 | G77: SU | H77: 13 | I77: 1 | J77: 10 | K77: B | L77: =VLOOKUP(K77, 'Alphabetical by species code'!A:B, 2, FALSE) -> Bareground | M77: =VLOOKUP(L77, 'Alphabetical by species code'!B:C, 2, FALSE) -> Ground Cover
A78: 2 | B78: 2023 | C78: 45197 | D78: MG, TL | E78: GB | F78: 1 | G78: SU | H78: 13 | I78: 1 | J78: 10 | K78: MALLAU | L78: =VLOOKUP(K78, 'Alphabetical by species code'!A:B, 2, FALSE) -> Malosma laurina | M78: =VLOOKUP(L78, 'Alphabetical by species code'!B:C, 2, FALSE) -> Native
A79: 2 | B79: 2023 | C79: 45197 | D79: MG, TL | E79: GB | F79: 1 | G79: SU | H79: 14 | I79: 1 | J79: 11 | K79: B | L79: =VLOOKUP(K79, 'Alphabetical by species code'!A:B, 2, FALSE) -> Bareground | M79: =VLOOKUP(L79, 'Alphabetical by species code'!B:C, 2, FALSE) -> Ground Cover
A80: 2 | B80: 2023 | C80: 45197 | D80: MG, TL | E80: GB | F80: 1 | G80: SU | H80: 15 | I80: 1 | J80: 12 | K80: L | L80: =VLOOKUP(K80, 'Alphabetical by species code'!A:B, 2, FALSE) -> Litter | M80: =VLOOKUP(L80, 'Alphabetical by species code'!B:C, 2, FALSE) -> Ground Cover
A81: 2 | B81: 2023 | C81: 45197 | D81: MG, TL | E81: GB | F81: 1 | G81: SU | H81: 1 | I81: 2 | J81: 0 | K81: B | L81: =VLOOKUP(K81, 'Alphabetical by species code'!A:B, 2, FALSE) -> Bareground | M81: =VLOOKUP(L81, 'Alphabetical by species code'!B:C, 2, FALSE) -> Ground Cover
...

Sheet Entry2
A1: Page # | B1: Year | C1: Date | D1: Team | E1: Site | F1: Block # | G1: Treatment | H1: Point | I1: Transect | J1: Distance | K1: Code | L1: Species | M1: Notes
A2: (#) | B2: 2023 | C2: mm/dd/yy | D2: initials | E2: CU/VB/GB | F2: 43469 | G2: LS/LU/SS/SU | H2: 1-30 | I2: 1 or 2 | J2: 0-12m | K2: six-letter code | L2: full name | M2: enter as written
A3: 1 | B3: 2023 | C3: 45197 | D3: MG, TL | E3: GB | F3: 1 | G3: SS | H3: 1 | I3: 1 | J3: 0 | K3: L
A4: 1 | B4: 2023 | C4: 45197 | D4: MG, TL | E4: GB | F4: 1 | G4: SS | H4: 1 | I4: 1 | J4: 0 | K4: STEDIE
A5: 1 | B5: 2023 | C5: 45197 | D5: MG, TL | E5: GB | F5: 1 | G5: SS | H5: 2 | I5: 1 | J5: 1 | K5: L
A6: 1 | B6: 2023 | C6: 45197 | D6: MG, TL | E6: GB | F6: 1 | G6: SS | H6: 2 | I6: 1 | J6: 1 | K6: OPULIT
A7: 1 | B7: 2023 | C7: 45197 | D7: MG, TL | E7: GB | F7: 1 | G7: SS | H7: 2 | I7: 1 | J7: 1 | K7: NNG | M7: NNG - non-native grass
A8: 1 | B8: 2023 | C8: 45197 | D8: MG, TL | E8: GB | F8: 1 | G8: SS | H8: 3 | I8: 1 | J8: 1.5 | K8: R
A9: 1 | B9: 2023 | C9: 45197 | D9: MG, TL | E9: GB | F9: 1 | G9: SS | H9: 3 | I9: 1 | J9: 1.5 | K9: STEDIE
A10: 1 | B10: 2023 | C10: 45197 | D10: MG, TL | E10: GB | F10: 1 | G10: SS | H10: 4 | I10: 1 | J10: 2 | K10: L
A11: 1 | B11: 2023 | C11: 45197 | D11: MG, TL | E11: GB | F11: 1 | G11: SS | H11: 4 | I11: 1 | J11: 2 | K11: STEDIE
A12: 1 | B12: 2023 | C12: 45197 | D12: MG, TL | E12: GB | F12: 1 | G12: SS | H12: 5 | I12: 1 | J12: 3 | K12: R
A13: 1 | B13: 2023 | C13: 45197 | D13: MG, TL | E13: GB | F13: 1 | G13: SS | H13: 6 | I13: 1 | J13: 3.5 | K13: R
A14: 1 | B14: 2023 | C14: 45197 | D14: MG, TL | E14: GB | F14: 1 | G14: SS | H14: 6 | I14: 1 | J14: 3.5 | K14: NNG
A15: 1 | B15: 2023 | C15: 45197 | D15: MG, TL | E15: GB | F15: 1 | G15: SS | H15: 6 | I15: 1 | J15: 3.5 | K15: STEDIE
A16: 1 | B16: 2023 | C16: 45197 | D16: MG, TL | E16: GB | F16: 1 | G16: SS | H16: 7 | I16: 1 | J16: 4 | K16: L
A17: 1 | B17: 2023 | C17: 45197 | D17: MG, TL | E17: GB | F17: 1 | G17: SS | H17: 8 | I17: 1 | J17: 5 | K17: L
A18: 1 | B18: 2023 | C18: 45197 | D18: MG, TL | E18: GB | F18: 1 | G18: SS | H18: 9 | I18: 1 | J18: 7 | K18: L
A19: 1 | B19: 2023 | C19: 45197 | D19: MG, TL | E19: GB | F19: 1 | G19: SS | H19: 9 | I19: 1 | J19: 7 | K19: STEDIE
... A61: 2 | B61: 2023 | C61: 45197 | D61: MG, TL | E61: GB | F61: 1 | G61: SU | H61: 4 | I61: 1 | J61: 2 | K61: STEDIE
A62: 2 | B62: 2023 | C62: 45197 | D62: MG, TL | E62: GB | F62: 1 | G62: SU | H62: 4 | I62: 1 | J62: 2 | K62: EUPFEN | M62: TL took photo
A63: 2 | B63: 2023 | C63: 45197 | D63: MG, TL | E63: GB | F63: 1 | G63: SU | H63: 5 | I63: 1 | J63: 3 | K63: L
A64: 2 | B64: 2023 | C64: 45197 | D64: MG, TL | E64: GB | F64: 1 | G64: SU | H64: 5 | I64: 1 | J64: 3 | K64: STEDIE
A65: 2 | B65: 2023 | C65: 45197 | D65: MG, TL | E65: GB | F65: 1 | G65: SU | H65: 6 | I65: 1 | J65: 3.5 | K65: L
A66: 2 | B66: 2023 | C66: 45197 | D66: MG, TL | E66: GB | F66: 1 | G66: SU | H66: 6 | I66: 1 | J66: 3.5 | K66: EUPFEN
A67: 2 | B67: 2023 | C67: 45197 | D67: MG, TL | E67: GB | F67: 1 | G67: SU | H67: 7 | I67: 1 | J67: 4 | K67: B
A68: 2 | B68: 2023 | C68: 45197 | D68: MG, TL | E68: GB | F68: 1 | G68: SU | H68: 8 | I68: 1 | J68: 5 | K68: L
A69: 2 | B69: 2023 | C69: 45197 | D69: MG, TL | E69: GB | F69: 1 | G69: SU | H69: 8 | I69: 1 | J69: 5 | K69: NNG | M69: non native grass
A70: 2 | B70: 2023 | C70: 45197 | D70: MG, TL | E70: GB | F70: 1 | G70: SU | H70: 9 | I70: 1 | J70: 7 | K70: L
A71: 2 | B71: 2023 | C71: 45197 | D71: MG, TL | E71: GB | F71: 1 | G71: SU | H71: 9 | I71: 1 | J71: 7 | K71: STEDIE
A72: 2 | B72: 2023 | C72: 45197 | D72: MG, TL | E72: GB | F72: 1 | G72: SU | H72: 10 | I72: 1 | J72: 8 | K72: L
A73: 2 | B73: 2023 | C73: 45197 | D73: MG, TL | E73: GB | F73: 1 | G73: SU | H73: 11 | I73: 1 | J73: 8.5 | K73: L
A74: 2 | B74: 2023 | C74: 45197 | D74: MG, TL | E74: GB | F74: 1 | G74: SU | H74: 11 | I74: 1 | J74: 8.5 | K74: STEDIE
A75: 2 | B75: 2023 | C75: 45197 | D75: MG, TL | E75: GB | F75: 1 | G75: SU | H75: 12 | I75: 1 | J75: 9 | K75: L
A76: 2 | B76: 2023 | C76: 45197 | D76: MG, TL | E76: GB | F76: 1 | G76: SU | H76: 12 | I76: 1 | J76: 9 | K76: EUPMAC | M76: euphorbia masculata?
A77: 2 | B77: 2023 | C77: 45197 | D77: MG, TL | E77: GB | F77: 1 | G77: SU | H77: 13 | I77: 1 | J77: 10 | K77: B
A78: 2 | B78: 2023 | C78: 45197 | D78: MG, TL | E78: GB | F78: 1 | G78: SU | H78: 13 | I78: 1 | J78: 10 | K78: MALLAU
A79: 2 | B79: 2023 | C79: 45197 | D79: MG, TL | E79: GB | F79: 1 | G79: SU | H79: 14 | I79: 1 | J79: 11 | K79: B
A80: 2 | B80: 2023 | C80: 45197 | D80: MG, TL | E80: GB | F80: 1 | G80: SU | H80: 15 | I80: 1 | J80: 12 | K80: L
A81: 2 | B81: 2023 | C81: 45197 | D81: MG, TL | E81: GB | F81: 1 | G81: SU | H81: 1 | I81: 2 | J81: 0 | K81: B
...

Sheet Data Validation
A1: Page # | B1: Year | C1: Date | D1: Team | E1: Site | F1: Block # | G1: Treatment | H1: Point | I1: Transect | J1: Distance | K1: Code | L1: Species | M1: Notes
A2: (#) | B2: 2023 | C2: mm/dd/yy | D2: initials | E2: CU/VB/GB | F2: 43469 | G2: LS/LU/SS/SU | H2: 1-30 | I2: 1 or 2 | J2: 0-12m | K2: six-letter code | L2: full name | M2: enter as written
A3: =IF(Data!A3=Entry2!A3,Data!A3,"ERROR") -> 1 | B3: =IF(Data!B3=Entry2!B3,Data!B3,"ERROR") -> 2023 | C3: =IF(Data!C3=Entry2!C3,Data!C3,"ERROR") -> 45197 | D3: =IF(Data!D3=Entry2!D3,Data!D3,"ERROR") -> MG, TL | E3: =IF(Data!E3=Entry2!E3,Data!E3,"ERROR") -> GB | F3: =IF(Data!F3=Entry2!F3,Data!F3,"ERROR") -> 1 | G3: =IF(Data!G3=Entry2!G3,Data!G3,"ERROR") -> SS | H3: =IF(Data!H3=Entry2!H3,Data!H3,"ERROR") -> 1 | ... L3: =IF(Data!L3=Entry2!L3,Data!L3,"ERROR") -> ERROR | M3: =IF(Data!N3=Entry2!M3,Data!N3,"ERROR") -> 0
A4: =IF(Data!A4=Entry2!A4,Data!A4,"ERROR") -> 1 | B4: =IF(Data!B4=Entry2!B4,Data!B4,"ERROR") -> 2023 | C4: =IF(Data!C4=Entry2!C4,Data!C4,"ERROR") -> 45197 | D4: =IF(Data!D4=Entry2!D4,Data!D4,"ERROR") -> MG, TL | E4: =IF(Data!E4=Entry2!E4,Data!E4,"ERROR") -> GB | F4: =IF(Data!F4=Entry2!F4,Data!F4,"ERROR") -> 1 | G4: =IF(Data!G4=Entry2!G4,Data!G4,"ERROR") -> SS | H4: =IF(Data!H4=Entry2!H4,Data!H4,"ERROR") -> 1 | ... L4: =IF(Data!L4=Entry2!L4,Data!L4,"ERROR") -> ERROR | M4: =IF(Data!N4=Entry2!M4,Data!N4,"ERROR") -> 0
A5: =IF(Data!A5=Entry2!A5,Data!A5,"ERROR") -> 1 | B5: =IF(Data!B5=Entry2!B5,Data!B5,"ERROR") -> 2023 | C5: =IF(Data!C5=Entry2!C5,Data!C5,"ERROR") -> 45197 | D5: =IF(Data!D5=Entry2!D5,Data!D5,"ERROR") -> MG, TL | E5: =IF(Data!E5=Entry2!E5,Data!E5,"ERROR") -> GB | F5: =IF(Data!F5=Entry2!F5,Data!F5,"ERROR") -> 1 | G5: =IF(Data!G5=Entry2!G5,Data!G5,"ERROR") -> SS | H5: =IF(Data!H5=Entry2!H5,Data!H5,"ERROR") -> 2 | ... L5: =IF(Data!L5=Entry2!L5,Data!L5,"ERROR") -> ERROR | M5: =IF(Data!N5=Entry2!M5,Data!N5,"ERROR") -> 0
A6: =IF(Data!A6=Entry2!A6,Data!A6,"ERROR") -> 1 | B6: =IF(Data!B6=Entry2!B6,Data!B6,"ERROR") -> 2023 | C6: =IF(Data!C6=Entry2!C6,Data!C6,"ERROR") -> 45197 | D6: =IF(Data!D6=Entry2!D6,Data!D6,"ERROR") -> MG, TL | E6: =IF(Data!E6=Entry2!E6,Data!E6,"ERROR") -> GB | F6: =IF(Data!F6=Entry2!F6,Data!F6,"ERROR") -> 1 | G6: =IF(Data!G6=Entry2!G6,Data!G6,"ERROR") -> SS | H6: =IF(Data!H6=Entry2!H6,Data!H6,"ERROR") -> 2 | ... L6: =IF(Data!L6=Entry2!L6,Data!L6,"ERROR") -> ERROR | M6: =IF(Data!N6=Entry2!M6,Data!N6,"ERROR") -> 0
A7: =IF(Data!A7=Entry2!A7,Data!A7,"ERROR") -> 1 | B7: =IF(Data!B7=Entry2!B7,Data!B7,"ERROR") -> 2023 | C7: =IF(Data!C7=Entry2!C7,Data!C7,"ERROR") -> 45197 | D7: =IF(Data!D7=Entry2!D7,Data!D7,"ERROR") -> MG, TL | E7: =IF(Data!E7=Entry2!E7,Data!E7,"ERROR") -> GB | F7: =IF(Data!F7=Entry2!F7,Data!F7,"ERROR") -> 1 | G7: =IF(Data!G7=Entry2!G7,Data!G7,"ERROR") -> SS | H7: =IF(Data!H7=Entry2!H7,Data!H7,"ERROR") -> 2 | ... L7: =IF(Data!L7=Entry2!L7,Data!L7,"ERROR") -> ERROR | M7: =IF(Data!N7=Entry2!M7,Data!N7,"ERROR") -> NNG - non-native grass
A8: =IF(Data!A8=Entry2!A8,Data!A8,"ERROR") -> 1 | B8: =IF(Data!B8=Entry2!B8,Data!B8,"ERROR") -> 2023 | C8: =IF(Data!C8=Entry2!C8,Data!C8,"ERROR") -> 45197 | D8: =IF(Data!D8=Entry2!D8,Data!D8,"ERROR") -> MG, TL | E8: =IF(Data!E8=Entry2!E8,Data!E8,"ERROR") -> GB | F8: =IF(Data!F8=Entry2!F8,Data!F8,"ERROR") -> 1 | G8: =IF(Data!G8=Entry2!G8,Data!G8,"ERROR") -> SS | H8: =IF(Data!H8=Entry2!H8,Data!H8,"ERROR") -> 3 | ... L8: =IF(Data!L8=Entry2!L8,Data!L8,"ERROR") -> ERROR | M8: =IF(Data!N8=Entry2!M8,Data!N8,"ERROR") -> 0
A9: =IF(Data!A9=Entry2!A9,Data!A9,"ERROR") -> 1 | B9: =IF(Data!B9=Entry2!B9,Data!B9,"ERROR") -> 2023 | C9: =IF(Data!C9=Entry2!C9,Data!C9,"ERROR") -> 45197 | D9: =IF(Data!D9=Entry2!D9,Data!D9,"ERROR") -> MG, TL | E9: =IF(Data!E9=Entry2!E9,Data!E9,"ERROR") -> GB | F9: =IF(Data!F9=Entry2!F9,Data!F9,"ERROR") -> 1 | G9: =IF(Data!G9=Entry2!G9,Data!G9,"ERROR") -> SS | H9: =IF(Data!H9=Entry2!H9,Data!H9,"ERROR") -> 3 | ... L9: =IF(Data!L9=Entry2!L9,Data!L9,"ERROR") -> ERROR | M9: =IF(Data!N9=Entry2!M9,Data!N9,"ERROR") -> 0
A10: =IF(Data!A10=Entry2!A10,Data!A10,"ERROR") -> 1 | B10: =IF(Data!B10=Entry2!B10,Data!B10,"ERROR") -> 2023 | C10: =IF(Data!C10=Entry2!C10,Data!C10,"ERROR") -> 45197 | D10: =IF(Data!D10=Entry2!D10,Data!D10,"ERROR") -> MG, TL | E10: =IF(Data!E10=Entry2!E10,Data!E10,"ERROR") -> GB | F10: =IF(Data!F10=Entry2!F10,Data!F10,"ERROR") -> 1 | G10: =IF(Data!G10=Entry2!G10,Data!G10,"ERROR") -> SS | H10: =IF(Data!H10=Entry2!H10,Data!H10,"ERROR") -> 4 | ... L10: =IF(Data!L10=Entry2!L10,Data!L10,"ERROR") -> ERROR | M10: =IF(Data!N10=Entry2!M10,Data!N10,"ERROR") -> 0
A11: =IF(Data!A11=Entry2!A11,Data!A11,"ERROR") -> 1 | B11: =IF(Data!B11=Entry2!B11,Data!B11,"ERROR") -> 2023 | C11: =IF(Data!C11=Entry2!C11,Data!C11,"ERROR") -> 45197 | D11: =IF(Data!D11=Entry2!D11,Data!D11,"ERROR") -> MG, TL | E11: =IF(Data!E11=Entry2!E11,Data!E11,"ERROR") -> GB | F11: =IF(Data!F11=Entry2!F11,Data!F11,"ERROR") -> 1 | G11: =IF(Data!G11=Entry2!G11,Data!G11,"ERROR") -> SS | H11: =IF(Data!H11=Entry2!H11,Data!H11,"ERROR") -> 4 | ... L11: =IF(Data!L11=Entry2!L11,Data!L11,"ERROR") -> ERROR | M11: =IF(Data!N11=Entry2!M11,Data!N11,"ERROR") -> 0
A12: =IF(Data!A12=Entry2!A12,Data!A12,"ERROR") -> 1 | B12: =IF(Data!B12=Entry2!B12,Data!B12,"ERROR") -> 2023 | C12: =IF(Data!C12=Entry2!C12,Data!C12,"ERROR") -> 45197 | D12: =IF(Data!D12=Entry2!D12,Data!D12,"ERROR") -> MG, TL | E12: =IF(Data!E12=Entry2!E12,Data!E12,"ERROR") -> GB | F12: =IF(Data!F12=Entry2!F12,Data!F12,"ERROR") -> 1 | G12: =IF(Data!G12=Entry2!G12,Data!G12,"ERROR") -> SS | H12: =IF(Data!H12=Entry2!H12,Data!H12,"ERROR") -> 5 | ... L12: =IF(Data!L12=Entry2!L12,Data!L12,"ERROR") -> ERROR | M12: =IF(Data!N12=Entry2!M12,Data!N12,"ERROR") -> 0
A13: =IF(Data!A13=Entry2!A13,Data!A13,"ERROR") -> 1 | B13: =IF(Data!B13=Entry2!B13,Data!B13,"ERROR") -> 2023 | C13: =IF(Data!C13=Entry2!C13,Data!C13,"ERROR") -> 45197 | D13: =IF(Data!D13=Entry2!D13,Data!D13,"ERROR") -> MG, TL | E13: =IF(Data!E13=Entry2!E13,Data!E13,"ERROR") -> GB | F13: =IF(Data!F13=Entry2!F13,Data!F13,"ERROR") -> 1 | G13: =IF(Data!G13=Entry2!G13,Data!G13,"ERROR") -> SS | H13: =IF(Data!H13=Entry2!H13,Data!H13,"ERROR") -> 6 | ... L13: =IF(Data!L13=Entry2!L13,Data!L13,"ERROR") -> ERROR | M13: =IF(Data!N13=Entry2!M13,Data!N13,"ERROR") -> 0
A14: =IF(Data!A14=Entry2!A14,Data!A14,"ERROR") -> 1 | B14: =IF(Data!B14=Entry2!B14,Data!B14,"ERROR") -> 2023 | C14: =IF(Data!C14=Entry2!C14,Data!C14,"ERROR") -> 45197 | D14: =IF(Data!D14=Entry2!D14,Data!D14,"ERROR") -> MG, TL | E14: =IF(Data!E14=Entry2!E14,Data!E14,"ERROR") -> GB | F14: =IF(Data!F14=Entry2!F14,Data!F14,"ERROR") -> 1 | G14: =IF(Data!G14=Entry2!G14,Data!G14,"ERROR") -> SS | H14: =IF(Data!H14=Entry2!H14,Data!H14,"ERROR") -> 6 | ... L14: =IF(Data!L14=Entry2!L14,Data!L14,"ERROR") -> ERROR | M14: =IF(Data!N14=Entry2!M14,Data!N14,"ERROR") -> 0
... A978: =IF(Data!A978=Entry2!A978,Data!A978,"ERROR") -> 20 | B978: =IF(Data!B978=Entry2!B978,Data!B978,"ERROR") -> 2023 | C978: =IF(Data!C978=Entry2!C978,Data!C978,"ERROR") -> 45197 | D978: =IF(Data!D978=Entry2!D978,Data!D978,"ERROR") -> MP, TL | E978: =IF(Data!E978=Entry2!E978,Data!E978,"ERROR") -> VB | F978: =IF(Data!F978=Entry2!F978,Data!F978,"ERROR") -> 1 | G978: =IF(Data!G978=Entry2!G978,Data!G978,"ERROR") -> LU | H978: =IF(Data!H978=Entry2!H978,Data!H978,"ERROR") -> 8 | ... L978: =IF(Data!L978=Entry2!L978,Data!L978,"ERROR") -> ERROR | M978: =IF(Data!N978=Entry2!M978,Data!N978,"ERROR") -> 0
A979: =IF(Data!A1038=Entry2!A986,Data!A1038,"ERROR") -> 0 | B979: =IF(Data!B1038=Entry2!B986,Data!B1038,"ERROR") -> 0 | C979: =IF(Data!C1038=Entry2!C986,Data!C1038,"ERROR") -> 0 | D979: =IF(Data!D1038=Entry2!D986,Data!D1038,"ERROR") -> 0 | E979: =IF(Data!E1038=Entry2!E986,Data!E1038,"ERROR") -> 0 | F979: =IF(Data!F1038=Entry2!F986,Data!F1038,"ERROR") -> 0 | G979: =IF(Data!G1038=Entry2!G986,Data!G1038,"ERROR") -> 0 | H979: =IF(Data!H1038=Entry2!H986,Data!H1038,"ERROR") -> 0 | ... K979: =IF(Data!K1038=Entry2!K986,Data!K1038,"ERROR") -> 0 | L979: =IF(Data!L1038=Entry2!L985,Data!L1038,"ERROR") -> 0 | M979: =IF(Data!N1038=Entry2!M985,Data!N1038,"ERROR") -> 0

Sheet Example Data
A1: Page # | B1: Year | C1: Date | D1: Team | E1: Site | F1: Block # | G1: Treatment | H1: Point | I1: Transect | J1: Distance | K1: Code | L1: Species | M1: Notes
A2: (#) | B2: 2023 | C2: mm/dd/yy | D2: initials | E2: CU/VB/GB | F2: 43469 | G2: LS/LU/SS/SU | H2: 1-30 | I2: 1 or 2 | J2: 0-12m | K2: six-letter code | L2: full name | M2: enter as written
A3: 1 | B3: 2023 | C3: 45197 | D3: MG, TL | E3: GB | F3: 1 | G3: SS | H3: 1 | I3: 1 | J3: 0 | K3: L
A4: 1 | B4: 2023 | C4: 45197 | D4: MG, TL | E4: GB | F4: 1 | G4: SS | H4: 1 | I4: 1 | J4: 0 | K4: STEDIE
A5: 1 | B5: 2023 | C5: 45197 | D5: MG, TL | E5: GB | F5: 1 | G5: SS | H5: 2 | I5: 1 | J5: 1 | K5: L
A6: 1 | B6: 2023 | C6: 45197 | D6: MG, TL | E6: GB | F6: 1 | G6: SS | H6: 2 | I6: 1 | J6: 1 | K6: OPULIT
A7: 1 | B7: 2023 | C7: 45197 | D7: MG, TL | E7: GB | F7: 1 | G7: SS | H7: 2 | I7: 1 | J7: 1 | K7: NNG | M7: NNG - non-native grass
A8: 1 | B8: 2023 | C8: 45197 | D8: MG, TL | E8: GB | F8: 1 | G8: SS | H8: 3 | I8: 1 | J8: 1.5 | K8: R
A9: 1 | B9: 2023 | C9: 45197 | D9: MG, TL | E9: GB | F9: 1 | G9: SS | H9: 3 | I9: 1 | J9: 1.5 | K9: STEDIE
A10: 1 | B10: 2023 | C10: 45197 | D10: MG, TL | E10: GB | F10: 1 | G10: SS | H10: 4 | I10: 1 | J10: 2 | K10: L
A11: 1 | B11: 2023 | C11: 45197 | D11: MG, TL | E11: GB | F11: 1 | G11: SS | H11: 4 | I11: 1 | J11: 2 | K11: STEDIE
A12: 1 | B12: 2023 | C12: 45197 | D12: MG, TL | E12: GB | F12: 1 | G12: SS | H12: 5 | I12: 1 | J12: 3 | K12: R
A13: 1 | B13: 2023 | C13: 45197 | D13: MG, TL | E13: GB | F13: 1 | G13: SS | H13: 6 | I13: 1 | J13: 3.5 | K13: R
A14: 1 | B14: 2023 | C14: 45197 | D14: MG, TL | E14: GB | F14: 1 | G14: SS | H14: 6 | I14: 1 | J14: 3.5 | K14: NNG
A15: 1 | B15: 2023 | C15: 45197 | D15: MG, TL | E15: GB | F15: 1 | G15: SS | H15: 6 | I15: 1 | J15: 3.5 | K15: STEDIE
A16: 1 | B16: 2023 | C16: 45197 | D16: MG, TL | E16: GB | F16: 1 | G16: SS | H16: 7 | I16: 1 | J16: 4 | K16: L
A17: 1 | B17: 2023 | C17: 45197 | D17: MG, TL | E17: GB | F17: 1 | G17: SS | H17: 8 | I17: 1 | J17: 5 | K17: L
A18: 1 | B18: 2023 | C18: 45197 | D18: MG, TL | E18: GB | F18: 1 | G18: SS | H18: 9 | I18: 1 | J18: 7 | K18: L
A19: 1 | B19: 2023 | C19: 45197 | D19: MG, TL | E19: GB | F19: 1 | G19: SS | H19: 9 | I19: 1 | J19: 7 | K19: STEDIE
... A52: 1 | B52: 2023 | C52: 45197 | D52: MG, TL | E52: GB | F52: 1 | G52: SS | H52: 15 | I52: 2 | J52: 12 | K52: L

Sheet Species List
A1: AMAALB
A2: B | B2: Bare ground
A3: C | B3: Cryptobiotic crust
A4: CALMAC | B4: Calystegia macrostegia
A5: CYLPRO | B5: Cylindropuntia prolifera
A6: ERIFAS | B6: Eriogonum fasciculatum
A7: F | B7: Fine woody debris
A8: L | B8: Litter
A9: LAECOU | B9: Laennecia coulteri
A10: M | B10: Moss
A11: OPULIT | B11: Opuntia littoralis
A12: PSECAL | B12: Pseudognaphalium californicum
A13: R | B13: Rock
... A17: W | B17: Coarse woody debris

Sheet Alphabetical by species code
A1: Species Code (A-Z) | B1: Full Scientific Name (Genus species) | C1: Native/Non-Native | D1: Common Name | E1: other scientific names | F1: Plant Family
A2: . | B2: . | C2: . | D2: . | E2: . | F2: .
A3: ACHMIL | B3: Achillea millefolium | C3: Native | D3: Yarrow | E3: . | F3: Asteraceae
A4: ACMAME | B4: Acmispon americanus | C4: Native | D4: American bird's foot trefoil | E4: Lotus purshianus | F4: Fabaceae
A5: ACMGLA | B5: Acmispon glaber | C5: Native | D5: Deerweed, California Broom | E5: Lotus scoparius | F5: Fabaceae
A6: ACMMAR | B6: Acmispon maritimus | C6: Native | D6: Coastal Lotus | E6: Lotus salsuginosus | F6: Fabaceae
A7: ACMMIC | B7: Acmicspon micranthus | C7: Native | D7: Small flowered lotus, grab lotus | E7: Lotus hamatus | F7: Fabaceae
A8: ACMPRO | B8: Acmispon prostratus | C8: Native | D8: prostrate lotus | F8: Fabaceae
A9: ACMSPP | B9: Acmispon species | C9: Native | D9: bird's foot trefoil | E9: . | F9: Fabaceae
A10: ACMSTR | B10: Acmispon strigosus | C10: Native | D10: Strigose lotus | E10: Lotus strigosus | F10: Fabaceae
A11: ACMWRA | B11: Acmispon wrangelianus | C11: Native | F11: Fabaceae
A12: ACOMIC | B12: Acourtia microcephala | C12: Native | D12: Sacapellote | E12: . | F12: Asteraceae
A13: ADEFAS | B13: Adenostoma fasciculatum | C13: Native | D13: Chamise | E13: . | F13: Rosaceae
A14: AGOGRA | B14: Agoseris grandiflora | C14: Native | D14: Large-flowered Mountain Dandelion | F14: Asteraceae
A15: AGOSPP | B15: Agoseris species | C15: Native | F15: Asteraceae
A16: AGRPAL | B16: Agrostis pallens | C16: Native | D16: bent grass | E16: . | F16: Poaceae
A17: ALLAMP | B17: Allium amplectens | C17: Native | D17: onion | F17: Alliaceae
A18: ALLGLU | B18: Allophyllum glutinosum | C18: Native | D18: sticky false gilia | F18: Polemoniaceae
A19: ALLPEN | B19: Allium peninsulare | C19: Native | D19: onion | F19: Alliaceae
A20: ALLPRA | B20: Allium praecox | C20: Native | D20: onion | F20: Alliaceae
A21: ALLSPP | B21: Allium species | C21: Native | D21: onion | F21: Alliaceae
A22: AMAALB | B22: Amaranthus albus | C22: Non-Native | D22: pigweed | E22: . | F22: Amaranthaceae
A23: AMBACA | B23: Ambrosia acanthicarpa | C23: Native | D23: ragweed | E23: . | F23: Asteraceae
A24: AMBCON | B24: Ambrosia confertiflora | C24: Native | D24: weak leaf burweed/ragweed | F24: Asteraceae
A25: AMBPSI | B25: Ambrosia psilostachya | C25: Native | D25: ragweed | E25: . | F25: Asteraceae
A26: AMOCAL | B26: Amorpha californica | C26: Native | D26: false indigo | E26: . | F26: Fabaceae
A27: AMOFRU | B27: Amorpha fruticosa | C27: Native | D27: western false indigo | E27: . | F27: Fabaceae
A28: AMSINT | B28: Amsinckia intermedia | C28: Native | D28: common fiddleneck | E28: . | F28: Boraginaceae
A29: AMSMEN | B29: Amsinckia menziesii | C29: Native | D29: fiddleneck | E29: . | F29: Boraginaceae
A30: AMSRET | B30: Amsinckia retrorsa | C30: Native | D30: Gray Fiddleneck | F30: Boraginaceae
A31: ANAARV | B31: Anagallis arvensis | C31: Non-Native | D31: scarlet pimpernel | E31: . | F31: Primulaceae
A32: ANECAL | B32: Anemopsis californica | C32: Native | D32: Yerba mansa | E32: . | F32: Saururaceae
A33: ANTCAU | B33: Anthriscus caucalis | C33: Non-Native | D33: Bur chervil | E33: . | F33: Apiaceae
A34: ANTCOU | B34: Antirrhinum coulterianum | C34: Native | D34: Coulter's snapdragon | E34: . | F34: Plantaginaceae
A35: ANTKEL | B35: Antirrhinum kelloggii | C35: Native | D35: climbing snapdragon | E35: . | F35: Plantaginaceae
A36: ANTNUT | B36: Antirrhinum nuttallianum | C36: Native | D36: Nuttall's snapdragon | E36: . | F36: Plantaginaceae
A37: APIANG | B37: Apiastrum angustifolium | C37: Native | D37: wild celery | E37: . | F37: Apiaceae
A38: APIGRA | B38: Apium graveolens | C38: Non-Native | D38: celery | E38: . | F38: Apiaceae
A39: APOCAN | B39: Apocynum cannabinum | C39: Native | D39: Indian hemp | E39: . | F39: Apocynaceae
A40: ARASER | B40: Araujia sericifera | C40: Non-Native | D40: bladder flower | E40: . | F40: Apocynaceae
...
