Workbook

Sheet Data
A1: Page # | B1: Year | C1: Date | D1: Team | E1: Site | F1: Block # | G1: Treatment | H1: Transect | I1: Point | J1: Distance | K1: Code | L1: Species | M1: Native/Non-Native | N1: Notes
A2: (#) | B2: 2025 | C2: mm/dd/yy | D2: initials | E2: CU/VB/GB | F2: 43469 | G2: LS/LU/SS/SU | H2: 1 or 2 | I2: 1-30 | J2: 0-12m | K2: six-letter code | L2: do not enter - autofill formula | N2: enter as written
A3: 1 | B3: 2025 | C3: 45764 | D3: TL, CG, BN | E3: VB | F3: 1 | G3: LS | H3: 1 | I3: 1 | J3: 0 | K3: L | L3: =VLOOKUP(K3, 'Alphabetical by species code'!A:B, 2, FALSE) -> Litter | M3: =VLOOKUP(L3, 'Alphabetical by species code'!B:C, 2, FALSE) -> Ground Cover
A4: 1 | B4: 2025 | C4: 45764 | D4: TL, CG, BN | E4: VB | F4: 1 | G4: LS | H4: 1 | I4: 1 | J4: 0 | K4: OPULIT | L4: =VLOOKUP(K4, 'Alphabetical by species code'!A:B, 2, FALSE) -> Opuntia littoralis | M4: =VLOOKUP(L4, 'Alphabetical by species code'!B:C, 2, FALSE) -> Native | N4: =VLOOKUP(L4, 'Alphabetical by species code'!B:C, 2, FALSE) -> Native
A5: 1 | B5: 2025 | C5: 45764 | D5: TL, CG, BN | E5: VB | F5: 1 | G5: LS | H5: 1 | I5: 1 | J5: 0 | K5: EROMOS | L5: =VLOOKUP(K5, 'Alphabetical by species code'!A:B, 2, FALSE) -> Erodium moschatum | M5: =VLOOKUP(L5, 'Alphabetical by species code'!B:C, 2, FALSE) -> Non-Native
A6: 1 | B6: 2025 | C6: 45764 | D6: TL, CG, BN | E6: VB | F6: 1 | G6: LS | H6: 1 | I6: 1 | J6: 0 | K6: FESMYU | L6: =VLOOKUP(K6, 'Alphabetical by species code'!A:B, 2, FALSE) -> Festuca myuros | M6: =VLOOKUP(L6, 'Alphabetical by species code'!B:C, 2, FALSE) -> Non-Native
A7: 1 | B7: 2025 | C7: 45764 | D7: TL, CG, BN | E7: VB | F7: 1 | G7: LS | H7: 1 | I7: 2 | J7: 0.5 | K7: L | L7: =VLOOKUP(K7, 'Alphabetical by species code'!A:B, 2, FALSE) -> Litter | M7: =VLOOKUP(L7, 'Alphabetical by species code'!B:C, 2, FALSE) -> Ground Cover
A8: 1 | B8: 2025 | C8: 45764 | D8: TL, CG, BN | E8: VB | F8: 1 | G8: LS | H8: 1 | I8: 2 | J8: 0.5 | K8: MEDPOL | L8: =VLOOKUP(K8, 'Alphabetical by species code'!A:B, 2, FALSE) -> Medicago polymorpha | M8: =VLOOKUP(L8, 'Alphabetical by species code'!B:C, 2, FALSE) -> Non-Native
A9: 1 | B9: 2025 | C9: 45764 | D9: TL, CG, BN | E9: VB | F9: 1 | G9: LS | H9: 1 | I9: 2 | J9: 0.5 | K9: OPULIT | L9: =VLOOKUP(K9, 'Alphabetical by species code'!A:B, 2, FALSE) -> Opuntia littoralis | M9: =VLOOKUP(L9, 'Alphabetical by species code'!B:C, 2, FALSE) -> Native
A10: 1 | B10: 2025 | C10: 45764 | D10: TL, CG, BN | E10: VB | F10: 1 | G10: LS | H10: 1 | I10: 2 | J10: 0.5 | K10: UNKNNGRASS | L10: =VLOOKUP(K10, 'Alphabetical by species code'!A:B, 2, FALSE) -> Unknown non-native grass | M10: =VLOOKUP(L10, 'Alphabetical by species code'!B:C, 2, FALSE) -> 0
A11: 1 | B11: 2025 | C11: 45764 | D11: TL, CG, BN | E11: VB | F11: 1 | G11: LS | H11: 1 | I11: 3 | J11: 1 | K11: L | L11: =VLOOKUP(K11, 'Alphabetical by species code'!A:B, 2, FALSE) -> Litter | M11: =VLOOKUP(L11, 'Alphabetical by species code'!B:C, 2, FALSE) -> Ground Cover
A12: 1 | B12: 2025 | C12: 45764 | D12: TL, CG, BN | E12: VB | F12: 1 | G12: LS | H12: 1 | I12: 3 | J12: 1 | K12: MEDPOL | L12: =VLOOKUP(K12, 'Alphabetical by species code'!A:B, 2, FALSE) -> Medicago polymorpha | M12: =VLOOKUP(L12, 'Alphabetical by species code'!B:C, 2, FALSE) -> Non-Native
A13: 1 | B13: 2025 | C13: 45764 | D13: TL, CG, BN | E13: VB | F13: 1 | G13: LS | H13: 1 | I13: 3 | J13: 1 | K13: FESMYU | L13: =VLOOKUP(K13, 'Alphabetical by species code'!A:B, 2, FALSE) -> Festuca myuros | M13: =VLOOKUP(L13, 'Alphabetical by species code'!B:C, 2, FALSE) -> Non-Native
A14: 1 | B14: 2025 | C14: 45764 | D14: TL, CG, BN | E14: VB | F14: 1 | G14: LS | H14: 1 | I14: 3 | J14: 1 | K14: EROCIC | L14: =VLOOKUP(K14, 'Alphabetical by species code'!A:B, 2, FALSE) -> Erodium cicutarium | M14: =VLOOKUP(L14, 'Alphabetical by species code'!B:C, 2, FALSE) -> Non-Native
A15: 1 | B15: 2025 | C15: 45764 | D15: TL, CG, BN | E15: VB | F15: 1 | G15: LS | H15: 1 | I15: 4 | J15: 1.5 | K15: L | L15: =VLOOKUP(K15, 'Alphabetical by species code'!A:B, 2, FALSE) -> Litter | M15: =VLOOKUP(L15, 'Alphabetical by species code'!B:C, 2, FALSE) -> Ground Cover
A16: 1 | B16: 2025 | C16: 45764 | D16: TL, CG, BN | E16: VB | F16: 1 | G16: LS | H16: 1 | I16: 4 | J16: 1.5 | K16: OPULIT | L16: =VLOOKUP(K16, 'Alphabetical by species code'!A:B, 2, FALSE) -> Opuntia littoralis | M16: =VLOOKUP(L16, 'Alphabetical by species code'!B:C, 2, FALSE) -> Native
... A1374: 16 | B1374: 2025 | C1374: 45790 | D1374: JV, MP | E1374: GB | F1374: 3 | G1374: SU | H1374: 2 | I1374: 15 | J1374: 12 | K1374: UNKPLANT | L1374: =VLOOKUP(K1374, 'Alphabetical by species code'!A:B, 2, FALSE) -> #N/A | M1374: =VLOOKUP(L1374, 'Alphabetical by species code'!B:C, 2, FALSE) -> #N/A

Sheet Point Intercept 2
A1: Page # | B1: Year | C1: Date | D1: Team | E1: Site | F1: Block # | G1: Treatment | H1: Transect | I1: Point | J1: Distance | K1: Code | L1: Species | M1: Notes
A2: (#) | B2: 2025 | C2: mm/dd/yy | D2: initials | E2: CU/VB/GB | F2: 43469 | G2: LS/LU/SS/SU | H2: 1 or 2 | I2: 1-30 | J2: 0-12m | K2: six-letter code | L2: full name | M2: enter as written
A3: 1 | B3: 2025 | C3: 45764 | D3: TL, CG, BN | E3: VB | F3: 1 | G3: LS | H3: 1 | I3: 1 | J3: 0 | K3: L | L3: =VLOOKUP(K3, 'Alphabetical by species code'!A:B, 2, FALSE) -> Litter
A4: 1 | B4: 2025 | C4: 45764 | D4: TL, CG, BN | E4: VB | F4: 1 | G4: LS | H4: 1 | I4: 1 | J4: 0 | K4: OPULIT | L4: =VLOOKUP(K4, 'Alphabetical by species code'!A:B, 2, FALSE) -> Opuntia littoralis
A5: 1 | B5: 2025 | C5: 45764 | D5: TL, CG, BN | E5: VB | F5: 1 | G5: LS | H5: 1 | I5: 1 | J5: 0 | K5: EROMOS | L5: =VLOOKUP(K5, 'Alphabetical by species code'!A:B, 2, FALSE) -> Erodium moschatum
A6: 1 | B6: 2025 | C6: 45764 | D6: TL, CG, BN | E6: VB | F6: 1 | G6: LS | H6: 1 | I6: 1 | J6: 0 | K6: FESMYU | L6: =VLOOKUP(K6, 'Alphabetical by species code'!A:B, 2, FALSE) -> Festuca myuros
A7: 1 | B7: 2025 | C7: 45764 | D7: TL, CG, BN | E7: VB | F7: 1 | G7: LS | H7: 1 | I7: 2 | J7: 0.5 | K7: L | L7: =VLOOKUP(K7, 'Alphabetical by species code'!A:B, 2, FALSE) -> Litter
A8: 1 | B8: 2025 | C8: 45764 | D8: TL, CG, BN | E8: VB | F8: 1 | G8: LS | H8: 1 | I8: 2 | J8: 0.5 | K8: MEDPOL | L8: =VLOOKUP(K8, 'Alphabetical by species code'!A:B, 2, FALSE) -> Medicago polymorpha
A9: 1 | B9: 2025 | C9: 45764 | D9: TL, CG, BN | E9: VB | F9: 1 | G9: LS | H9: 1 | I9: 2 | J9: 0.5 | K9: OPULIT | L9: =VLOOKUP(K9, 'Alphabetical by species code'!A:B, 2, FALSE) -> Opuntia littoralis
A10: 1 | B10: 2025 | C10: 45764 | D10: TL, CG, BN | E10: VB | F10: 1 | G10: LS | H10: 1 | I10: 2 | J10: 0.5 | K10: UNKNNGRASS | L10: =VLOOKUP(K10, 'Alphabetical by species code'!A:B, 2, FALSE) -> Unknown non-native grass
A11: 1 | B11: 2025 | C11: 45764 | D11: TL, CG, BN | E11: VB | F11: 1 | G11: LS | H11: 1 | I11: 3 | J11: 1 | K11: L | L11: =VLOOKUP(K11, 'Alphabetical by species code'!A:B, 2, FALSE) -> Litter
A12: 1 | B12: 2025 | C12: 45764 | D12: TL, CG, BN | E12: VB | F12: 1 | G12: LS | H12: 1 | I12: 3 | J12: 1 | K12: MEDPOL | L12: =VLOOKUP(K12, 'Alphabetical by species code'!A:B, 2, FALSE) -> Medicago polymorpha
A13: 1 | B13: 2025 | C13: 45764 | D13: TL, CG, BN | E13: VB | F13: 1 | G13: LS | H13: 1 | I13: 3 | J13: 1 | K13: FESMYU | L13: =VLOOKUP(K13, 'Alphabetical by species code'!A:B, 2, FALSE) -> Festuca myuros
A14: 1 | B14: 2025 | C14: 45764 | D14: TL, CG, BN | E14: VB | F14: 1 | G14: LS | H14: 1 | I14: 3 | J14: 1 | K14: EROCIC | L14: =VLOOKUP(K14, 'Alphabetical by species code'!A:B, 2, FALSE) -> Erodium cicutarium
... A901: 10 | B901: 2025 | C901: 45777 | D901: CG, JD | E901: CU | F901: 1 | G901: LU | H901: 1 | I901: 14 | J901: 7 | K901: R | L901: =VLOOKUP(K901, 'Alphabetical by species code'!A:B, 2, FALSE) -> Rock
A902: 10 | B902: 2025 | C902: 45777 | D902: CG, JD | E902: CU | F902: 1 | G902: LU | H902: 1 | I902: 14 | J902: 7 | K902: LICHEN | L902: =VLOOKUP(K902, 'Alphabetical by species code'!A:B, 2, FALSE) -> #N/A | M902: Moss? No Hit?
A903: 10 | B903: 2025 | C903: 45777 | D903: CG, JD | E903: CU | F903: 1 | G903: LU | H903: 1 | I903: 15 | J903: 7.5 | K903: L | L903: =VLOOKUP(K903, 'Alphabetical by species code'!A:B, 2, FALSE) -> Litter
A904: 10 | B904: 2025 | C904: 45777 | D904: CG, JD | E904: CU | F904: 1 | G904: LU | H904: 1 | I904: 15 | J904: 7.5 | K904: BRANIG | L904: =VLOOKUP(K904, 'Alphabetical by species code'!A:B, 2, FALSE) -> Brassica nigra
A905: 10 | B905: 2025 | C905: 45777 | D905: CG, JD | E905: CU | F905: 1 | G905: LU | H905: 1 | I905: 15 | J905: 7.5 | K905: CENMEL | L905: =VLOOKUP(K905, 'Alphabetical by species code'!A:B, 2, FALSE) -> Centaurea melitensis
A906: 10 | B906: 2025 | C906: 45777 | D906: CG, JD | E906: CU | F906: 1 | G906: LU | H906: 2 | I906: 1 | J906: 0 | K906: R | L906: =VLOOKUP(K906, 'Alphabetical by species code'!A:B, 2, FALSE) -> Rock
A907: 10 | B907: 2025 | C907: 45777 | D907: CG, JD | E907: CU | F907: 1 | G907: LU | H907: 2 | I907: 2 | J907: 0.5 | K907: L | L907: =VLOOKUP(K907, 'Alphabetical by species code'!A:B, 2, FALSE) -> Litter
A908: 10 | B908: 2025 | C908: 45777 | D908: CG, JD | E908: CU | F908: 1 | G908: LU | H908: 2 | I908: 2 | J908: 0.5 | K908: BROMAD | L908: =VLOOKUP(K908, 'Alphabetical by species code'!A:B, 2, FALSE) -> Bromus madritensis
A909: 10 | B909: 2025 | C909: 45777 | D909: CG, JD | E909: CU | F909: 1 | G909: LU | H909: 2 | I909: 3 | J909: 1 | K909: B | L909: =VLOOKUP(K909, 'Alphabetical by species code'!A:B, 2, FALSE) -> Bareground
A910: 10 | B910: 2025 | C910: 45777 | D910: CG, JD | E910: CU | F910: 1 | G910: LU | H910: 2 | I910: 3 | J910: 1 | K910: SENVIL | L910: =VLOOKUP(K910, 'Alphabetical by species code'!A:B, 2, FALSE) -> #N/A
A911: 10 | B911: 2025 | C911: 45777 | D911: CG, JD | E911: CU | F911: 1 | G911: LU | H911: 2 | I911: 3 | J911: 1 | K911: EROSPP | L911: =VLOOKUP(K911, 'Alphabetical by species code'!A:B, 2, FALSE) -> Erodium species
A912: 10 | B912: 2025 | C912: 45777 | D912: CG, JD | E912: CU | F912: 1 | G912: LU | H912: 2 | I912: 4 | J912: 1.5 | K912: L | L912: =VLOOKUP(K912, 'Alphabetical by species code'!A:B, 2, FALSE) -> Litter
A913: 10 | B913: 2025 | C913: 45777 | D913: CG, JD | E913: CU | F913: 1 | G913: LU | H913: 2 | I913: 4 | J913: 1.5 | K913: DEIFAS | L913: =VLOOKUP(K913, 'Alphabetical by species code'!A:B, 2, FALSE) -> Deinandra fasciculata
A914: 10 | B914: 2025 | C914: 45777 | D914: CG, JD | E914: CU | F914: 1 | G914: LU | H914: 2 | I914: 5 | J914: 2.5 | K914: L | L914: =VLOOKUP(K914, 'Alphabetical by species code'!A:B, 2, FALSE) -> Litter
... A1375: 16 | B1375: 2025 | C1375: 45790 | D1375: MP, JV | E1375: GB | F1375: 3 | G1375: SU | H1375: 2 | I1375: 15 | J1375: 12 | K1375: UNKPLANT | L1375: =VLOOKUP(K1375, 'Alphabetical by species code'!A:B, 2, FALSE) -> #N/A

Sheet Data Validation DO NOT EDIT
A1: =IF(Data!A1 = 'Point Intercept 2'!A1, Data!A1, "ERROR") -> Page # | B1: =IF(Data!B1 = 'Point Intercept 2'!B1, Data!B1, "ERROR") -> Year | C1: =IF(Data!C1 = 'Point Intercept 2'!C1, Data!C1, "ERROR") -> Date | D1: =IF(Data!D1 = 'Point Intercept 2'!D1, Data!D1, "ERROR") -> Team | E1: =IF(Data!E1 = 'Point Intercept 2'!E1, Data!E1, "ERROR") -> Site | F1: =IF(Data!F1 = 'Point Intercept 2'!F1, Data!F1, "ERROR") -> Block # | G1: =IF(Data!G1 = 'Point Intercept 2'!G1, Data!G1, "ERROR") -> Treatment | H1: =IF(Data!I1 = 'Point Intercept 2'!I1, Data!I1, "ERROR") -> Point | I1: =IF(Data!H1 = 'Point Intercept 2'!H1, Data!H1, "ERROR") -> Transect | J1: =IF(Data!J1 = 'Point Intercept 2'!J1, Data!J1, "ERROR") -> Distance | K1: =IF(Data!K1 = 'Point Intercept 2'!K1, Data!K1, "ERROR") -> Code | L1: =IF(Data!L1 = 'Point Intercept 2'!L1, Data!L1, "ERROR") -> Species | M1: =IF(Data!N1 = 'Point Intercept 2'!M1, Data!N1, "ERROR") -> Notes | N1: =IF(Data!O1 = 'Point Intercept 2'!N1, Data!O1, "ERROR") -> 0 | O1: =IF(Data!P1 = 'Point Intercept 2'!O1, Data!P1, "ERROR") -> 0
A2: =IF(Data!A2 = 'Point Intercept 2'!A2, Data!A2, "ERROR") -> (#) | B2: =IF(Data!B2 = 'Point Intercept 2'!B2, Data!B2, "ERROR") -> 2025 | C2: =IF(Data!C2 = 'Point Intercept 2'!C2, Data!C2, "ERROR") -> mm/dd/yy | D2: =IF(Data!D2 = 'Point Intercept 2'!D2, Data!D2, "ERROR") -> initials | E2: =IF(Data!E2 = 'Point Intercept 2'!E2, Data!E2, "ERROR") -> CU/VB/GB | F2: =IF(Data!F2 = 'Point Intercept 2'!F2, Data!F2, "ERROR") -> 43469 | G2: =IF(Data!G2 = 'Point Intercept 2'!G2, Data!G2, "ERROR") -> LS/LU/SS/SU | H2: =IF(Data!I2 = 'Point Intercept 2'!I2, Data!I2, "ERROR") -> 1-30 | I2: =IF(Data!H2 = 'Point Intercept 2'!H2, Data!H2, "ERROR") -> 1 or 2 | J2: =IF(Data!J2 = 'Point Intercept 2'!J2, Data!J2, "ERROR") -> 0-12m | K2: =IF(Data!K2 = 'Point Intercept 2'!K2, Data!K2, "ERROR") -> six-letter code | L2: =IF(Data!L2 = 'Point Intercept 2'!L2, Data!L2, "ERROR") -> ERROR | M2: =IF(Data!N2 = 'Point Intercept 2'!M2, Data!N2, "ERROR") -> enter as written | N2: =IF(Data!O2 = 'Point Intercept 2'!N2, Data!O2, "ERROR") -> 0 | O2: =IF(Data!P2 = 'Point Intercept 2'!O2, Data!P2, "ERROR") -> 0
A3: =IF(Data!A3 = 'Point Intercept 2'!A3, Data!A3, "ERROR") -> 1 | B3: =IF(Data!B3 = 'Point Intercept 2'!B3, Data!B3, "ERROR") -> 2025 | C3: =IF(Data!C3 = 'Point Intercept 2'!C3, Data!C3, "ERROR") -> 45764 | D3: =IF(Data!D3 = 'Point Intercept 2'!D3, Data!D3, "ERROR") -> TL, CG, BN | E3: =IF(Data!E3 = 'Point Intercept 2'!E3, Data!E3, "ERROR") -> VB | F3: =IF(Data!F3 = 'Point Intercept 2'!F3, Data!F3, "ERROR") -> 1 | G3: =IF(Data!G3 = 'Point Intercept 2'!G3, Data!G3, "ERROR") -> LS | H3: =IF(Data!I3 = 'Point Intercept 2'!I3, Data!I3, "ERROR") -> 1 | I3: =IF(Data!H3 = 'Point Intercept 2'!H3, Data!H3, "ERROR") -> 1 | J3: =IF(Data!J3 = 'Point Intercept 2'!J3, Data!J3, "ERROR") -> 0 | K3: =IF(Data!K3 = 'Point Intercept 2'!K3, Data!K3, "ERROR") -> L | L3: =IF(Data!L3 = 'Point Intercept 2'!L3, Data!L3, "ERROR") -> Litter | M3: =IF(Data!N3 = 'Point Intercept 2'!M3, Data!N3, "ERROR") -> 0 | N3: =IF(Data!O3 = 'Point Intercept 2'!N3, Data!O3, "ERROR") -> 0 | O3: =IF(Data!P3 = 'Point Intercept 2'!O3, Data!P3, "ERROR") -> 0
A4: =IF(Data!A4 = 'Point Intercept 2'!A4, Data!A4, "ERROR") -> 1 | B4: =IF(Data!B4 = 'Point Intercept 2'!B4, Data!B4, "ERROR") -> 2025 | C4: =IF(Data!C4 = 'Point Intercept 2'!C4, Data!C4, "ERROR") -> 45764 | D4: =IF(Data!D4 = 'Point Intercept 2'!D4, Data!D4, "ERROR") -> TL, CG, BN | E4: =IF(Data!E4 = 'Point Intercept 2'!E4, Data!E4, "ERROR") -> VB | F4: =IF(Data!F4 = 'Point Intercept 2'!F4, Data!F4, "ERROR") -> 1 | G4: =IF(Data!G4 = 'Point Intercept 2'!G4, Data!G4, "ERROR") -> LS | H4: =IF(Data!I4 = 'Point Intercept 2'!I4, Data!I4, "ERROR") -> 1 | I4: =IF(Data!H4 = 'Point Intercept 2'!H4, Data!H4, "ERROR") -> 1 | J4: =IF(Data!J4 = 'Point Intercept 2'!J4, Data!J4, "ERROR") -> 0 | K4: =IF(Data!K4 = 'Point Intercept 2'!K4, Data!K4, "ERROR") -> OPULIT | L4: =IF(Data!L4 = 'Point Intercept 2'!L4, Data!L4, "ERROR") -> Opuntia littoralis | M4: =IF(Data!N4 = 'Point Intercept 2'!M4, Data!N4, "ERROR") -> ERROR | N4: =IF(Data!O4 = 'Point Intercept 2'!N4, Data!O4, "ERROR") -> 0 | O4: =IF(Data!P4 = 'Point Intercept 2'!O4, Data!P4, "ERROR") -> 0
A5: =IF(Data!A5 = 'Point Intercept 2'!A5, Data!A5, "ERROR") -> 1 | B5: =IF(Data!B5 = 'Point Intercept 2'!B5, Data!B5, "ERROR") -> 2025 | C5: =IF(Data!C5 = 'Point Intercept 2'!C5, Data!C5, "ERROR") -> 45764 | D5: =IF(Data!D5 = 'Point Intercept 2'!D5, Data!D5, "ERROR") -> TL, CG, BN | E5: =IF(Data!E5 = 'Point Intercept 2'!E5, Data!E5, "ERROR") -> VB | F5: =IF(Data!F5 = 'Point Intercept 2'!F5, Data!F5, "ERROR") -> 1 | G5: =IF(Data!G5 = 'Point Intercept 2'!G5, Data!G5, "ERROR") -> LS | H5: =IF(Data!I5 = 'Point Intercept 2'!I5, Data!I5, "ERROR") -> 1 | I5: =IF(Data!H5 = 'Point Intercept 2'!H5, Data!H5, "ERROR") -> 1 | J5: =IF(Data!J5 = 'Point Intercept 2'!J5, Data!J5, "ERROR") -> 0 | K5: =IF(Data!K5 = 'Point Intercept 2'!K5, Data!K5, "ERROR") -> EROMOS | L5: =IF(Data!L5 = 'Point Intercept 2'!L5, Data!L5, "ERROR") -> Erodium moschatum | M5: =IF(Data!N5 = 'Point Intercept 2'!M5, Data!N5, "ERROR") -> 0 | N5: =IF(Data!O5 = 'Point Intercept 2'!N5, Data!O5, "ERROR") -> 0 | O5: =IF(Data!P5 = 'Point Intercept 2'!O5, Data!P5, "ERROR") -> 0
A6: =IF(Data!A6 = 'Point Intercept 2'!A6, Data!A6, "ERROR") -> 1 | B6: =IF(Data!B6 = 'Point Intercept 2'!B6, Data!B6, "ERROR") -> 2025 | C6: =IF(Data!C6 = 'Point Intercept 2'!C6, Data!C6, "ERROR") -> 45764 | D6: =IF(Data!D6 = 'Point Intercept 2'!D6, Data!D6, "ERROR") -> TL, CG, BN | E6: =IF(Data!E6 = 'Point Intercept 2'!E6, Data!E6, "ERROR") -> VB | F6: =IF(Data!F6 = 'Point Intercept 2'!F6, Data!F6, "ERROR") -> 1 | G6: =IF(Data!G6 = 'Point Intercept 2'!G6, Data!G6, "ERROR") -> LS | H6: =IF(Data!I6 = 'Point Intercept 2'!I6, Data!I6, "ERROR") -> 1 | I6: =IF(Data!H6 = 'Point Intercept 2'!H6, Data!H6, "ERROR") -> 1 | J6: =IF(Data!J6 = 'Point Intercept 2'!J6, Data!J6, "ERROR") -> 0 | K6: =IF(Data!K6 = 'Point Intercept 2'!K6, Data!K6, "ERROR") -> FESMYU | L6: =IF(Data!L6 = 'Point Intercept 2'!L6, Data!L6, "ERROR") -> Festuca myuros | M6: =IF(Data!N6 = 'Point Intercept 2'!M6, Data!N6, "ERROR") -> 0 | N6: =IF(Data!O6 = 'Point Intercept 2'!N6, Data!O6, "ERROR") -> 0 | O6: =IF(Data!P6 = 'Point Intercept 2'!O6, Data!P6, "ERROR") -> 0
A7: =IF(Data!A7 = 'Point Intercept 2'!A7, Data!A7, "ERROR") -> 1 | B7: =IF(Data!B7 = 'Point Intercept 2'!B7, Data!B7, "ERROR") -> 2025 | C7: =IF(Data!C7 = 'Point Intercept 2'!C7, Data!C7, "ERROR") -> 45764 | D7: =IF(Data!D7 = 'Point Intercept 2'!D7, Data!D7, "ERROR") -> TL, CG, BN | E7: =IF(Data!E7 = 'Point Intercept 2'!E7, Data!E7, "ERROR") -> VB | F7: =IF(Data!F7 = 'Point Intercept 2'!F7, Data!F7, "ERROR") -> 1 | G7: =IF(Data!G7 = 'Point Intercept 2'!G7, Data!G7, "ERROR") -> LS | H7: =IF(Data!I7 = 'Point Intercept 2'!I7, Data!I7, "ERROR") -> 2 | I7: =IF(Data!H7 = 'Point Intercept 2'!H7, Data!H7, "ERROR") -> 1 | J7: =IF(Data!J7 = 'Point Intercept 2'!J7, Data!J7, "ERROR") -> 0.5 | K7: =IF(Data!K7 = 'Point Intercept 2'!K7, Data!K7, "ERROR") -> L | L7: =IF(Data!L7 = 'Point Intercept 2'!L7, Data!L7, "ERROR") -> Litter | M7: =IF(Data!N7 = 'Point Intercept 2'!M7, Data!N7, "ERROR") -> 0 | N7: =IF(Data!O7 = 'Point Intercept 2'!N7, Data!O7, "ERROR") -> 0 | O7: =IF(Data!P7 = 'Point Intercept 2'!O7, Data!P7, "ERROR") -> 0
A8: =IF(Data!A8 = 'Point Intercept 2'!A8, Data!A8, "ERROR") -> 1 | B8: =IF(Data!B8 = 'Point Intercept 2'!B8, Data!B8, "ERROR") -> 2025 | C8: =IF(Data!C8 = 'Point Intercept 2'!C8, Data!C8, "ERROR") -> 45764 | D8: =IF(Data!D8 = 'Point Intercept 2'!D8, Data!D8, "ERROR") -> TL, CG, BN | E8: =IF(Data!E8 = 'Point Intercept 2'!E8, Data!E8, "ERROR") -> VB | F8: =IF(Data!F8 = 'Point Intercept 2'!F8, Data!F8, "ERROR") -> 1 | G8: =IF(Data!G8 = 'Point Intercept 2'!G8, Data!G8, "ERROR") -> LS | H8: =IF(Data!I8 = 'Point Intercept 2'!I8, Data!I8, "ERROR") -> 2 | I8: =IF(Data!H8 = 'Point Intercept 2'!H8, Data!H8, "ERROR") -> 1 | J8: =IF(Data!J8 = 'Point Intercept 2'!J8, Data!J8, "ERROR") -> 0.5 | K8: =IF(Data!K8 = 'Point Intercept 2'!K8, Data!K8, "ERROR") -> MEDPOL | L8: =IF(Data!L8 = 'Point Intercept 2'!L8, Data!L8, "ERROR") -> Medicago polymorpha | M8: =IF(Data!N8 = 'Point Intercept 2'!M8, Data!N8, "ERROR") -> 0 | N8: =IF(Data!O8 = 'Point Intercept 2'!N8, Data!O8, "ERROR") -> 0 | O8: =IF(Data!P8 = 'Point Intercept 2'!O8, Data!P8, "ERROR") -> 0
A9: =IF(Data!A9 = 'Point Intercept 2'!A9, Data!A9, "ERROR") -> 1 | B9: =IF(Data!B9 = 'Point Intercept 2'!B9, Data!B9, "ERROR") -> 2025 | C9: =IF(Data!C9 = 'Point Intercept 2'!C9, Data!C9, "ERROR") -> 45764 | D9: =IF(Data!D9 = 'Point Intercept 2'!D9, Data!D9, "ERROR") -> TL, CG, BN | E9: =IF(Data!E9 = 'Point Intercept 2'!E9, Data!E9, "ERROR") -> VB | F9: =IF(Data!F9 = 'Point Intercept 2'!F9, Data!F9, "ERROR") -> 1 | G9: =IF(Data!G9 = 'Point Intercept 2'!G9, Data!G9, "ERROR") -> LS | H9: =IF(Data!I9 = 'Point Intercept 2'!I9, Data!I9, "ERROR") -> 2 | I9: =IF(Data!H9 = 'Point Intercept 2'!H9, Data!H9, "ERROR") -> 1 | J9: =IF(Data!J9 = 'Point Intercept 2'!J9, Data!J9, "ERROR") -> 0.5 | K9: =IF(Data!K9 = 'Point Intercept 2'!K9, Data!K9, "ERROR") -> OPULIT | L9: =IF(Data!L9 = 'Point Intercept 2'!L9, Data!L9, "ERROR") -> Opuntia littoralis | M9: =IF(Data!N9 = 'Point Intercept 2'!M9, Data!N9, "ERROR") -> 0 | N9: =IF(Data!O9 = 'Point Intercept 2'!N9, Data!O9, "ERROR") -> 0 | O9: =IF(Data!P9 = 'Point Intercept 2'!O9, Data!P9, "ERROR") -> 0
A10: =IF(Data!A10 = 'Point Intercept 2'!A10, Data!A10, "ERROR") -> 1 | B10: =IF(Data!B10 = 'Point Intercept 2'!B10, Data!B10, "ERROR") -> 2025 | C10: =IF(Data!C10 = 'Point Intercept 2'!C10, Data!C10, "ERROR") -> 45764 | D10: =IF(Data!D10 = 'Point Intercept 2'!D10, Data!D10, "ERROR") -> TL, CG, BN | E10: =IF(Data!E10 = 'Point Intercept 2'!E10, Data!E10, "ERROR") -> VB | F10: =IF(Data!F10 = 'Point Intercept 2'!F10, Data!F10, "ERROR") -> 1 | G10: =IF(Data!G10 = 'Point Intercept 2'!G10, Data!G10, "ERROR") -> LS | H10: =IF(Data!I10 = 'Point Intercept 2'!I10, Data!I10, "ERROR") -> 2 | I10: =IF(Data!H10 = 'Point Intercept 2'!H10, Data!H10, "ERROR") -> 1 | J10: =IF(Data!J10 = 'Point Intercept 2'!J10, Data!J10, "ERROR") -> 0.5 | K10: =IF(Data!K10 = 'Point Intercept 2'!K10, Data!K10, "ERROR") -> UNKNNGRASS | L10: =IF(Data!L10 = 'Point Intercept 2'!L10, Data!L10, "ERROR") -> Unknown non-native grass | M10: =IF(Data!N10 = 'Point Intercept 2'!M10, Data!N10, "ERROR") -> 0 | N10: =IF(Data!O10 = 'Point Intercept 2'!N10, Data!O10, "ERROR") -> 0 | O10: =IF(Data!P10 = 'Point Intercept 2'!O10, Data!P10, "ERROR") -> 0
A11: =IF(Data!A11 = 'Point Intercept 2'!A11, Data!A11, "ERROR") -> 1 | B11: =IF(Data!B11 = 'Point Intercept 2'!B11, Data!B11, "ERROR") -> 2025 | C11: =IF(Data!C11 = 'Point Intercept 2'!C11, Data!C11, "ERROR") -> 45764 | D11: =IF(Data!D11 = 'Point Intercept 2'!D11, Data!D11, "ERROR") -> TL, CG, BN | E11: =IF(Data!E11 = 'Point Intercept 2'!E11, Data!E11, "ERROR") -> VB | F11: =IF(Data!F11 = 'Point Intercept 2'!F11, Data!F11, "ERROR") -> 1 | G11: =IF(Data!G11 = 'Point Intercept 2'!G11, Data!G11, "ERROR") -> LS | H11: =IF(Data!I11 = 'Point Intercept 2'!I11, Data!I11, "ERROR") -> 3 | I11: =IF(Data!H11 = 'Point Intercept 2'!H11, Data!H11, "ERROR") -> 1 | J11: =IF(Data!J11 = 'Point Intercept 2'!J11, Data!J11, "ERROR") -> 1 | K11: =IF(Data!K11 = 'Point Intercept 2'!K11, Data!K11, "ERROR") -> L | L11: =IF(Data!L11 = 'Point Intercept 2'!L11, Data!L11, "ERROR") -> Litter | M11: =IF(Data!N11 = 'Point Intercept 2'!M11, Data!N11, "ERROR") -> 0 | N11: =IF(Data!O11 = 'Point Intercept 2'!N11, Data!O11, "ERROR") -> 0 | O11: =IF(Data!P11 = 'Point Intercept 2'!O11, Data!P11, "ERROR") -> 0
A12: =IF(Data!A12 = 'Point Intercept 2'!A12, Data!A12, "ERROR") -> 1 | B12: =IF(Data!B12 = 'Point Intercept 2'!B12, Data!B12, "ERROR") -> 2025 | C12: =IF(Data!C12 = 'Point Intercept 2'!C12, Data!C12, "ERROR") -> 45764 | D12: =IF(Data!D12 = 'Point Intercept 2'!D12, Data!D12, "ERROR") -> TL, CG, BN | E12: =IF(Data!E12 = 'Point Intercept 2'!E12, Data!E12, "ERROR") -> VB | F12: =IF(Data!F12 = 'Point Intercept 2'!F12, Data!F12, "ERROR") -> 1 | G12: =IF(Data!G12 = 'Point Intercept 2'!G12, Data!G12, "ERROR") -> LS | H12: =IF(Data!I12 = 'Point Intercept 2'!I12, Data!I12, "ERROR") -> 3 | I12: =IF(Data!H12 = 'Point Intercept 2'!H12, Data!H12, "ERROR") -> 1 | J12: =IF(Data!J12 = 'Point Intercept 2'!J12, Data!J12, "ERROR") -> 1 | K12: =IF(Data!K12 = 'Point Intercept 2'!K12, Data!K12, "ERROR") -> MEDPOL | L12: =IF(Data!L12 = 'Point Intercept 2'!L12, Data!L12, "ERROR") -> Medicago polymorpha | M12: =IF(Data!N12 = 'Point Intercept 2'!M12, Data!N12, "ERROR") -> 0 | N12: =IF(Data!O12 = 'Point Intercept 2'!N12, Data!O12, "ERROR") -> 0 | O12: =IF(Data!P12 = 'Point Intercept 2'!O12, Data!P12, "ERROR") -> 0
... A330: =IF(Data!A330 = 'Point Intercept 2'!A330, Data!A330, "ERROR") -> 4 | B330: =IF(Data!B330 = 'Point Intercept 2'!B330, Data!B330, "ERROR") -> 2025 | C330: =IF(Data!C330 = 'Point Intercept 2'!C330, Data!C330, "ERROR") -> 45755 | D330: =IF(Data!D330 = 'Point Intercept 2'!D330, Data!D330, "ERROR") -> JC, TL | E330: =IF(Data!E330 = 'Point Intercept 2'!E330, Data!E330, "ERROR") -> VB | F330: =IF(Data!F330 = 'Point Intercept 2'!F330, Data!F330, "ERROR") -> 3 | G330: =IF(Data!G330 = 'Point Intercept 2'!G330, Data!G330, "ERROR") -> LS | H330: =IF(Data!I330 = 'Point Intercept 2'!I330, Data!I330, "ERROR") -> 7 | I330: =IF(Data!H330 = 'Point Intercept 2'!H330, Data!H330, "ERROR") -> 1 | J330: =IF(Data!J330 = 'Point Intercept 2'!J330, Data!J330, "ERROR") -> 3 | K330: =IF(Data!K330 = 'Point Intercept 2'!K330, Data!K330, "ERROR") -> SONOLE | L330: =IF(Data!L330 = 'Point Intercept 2'!L330, Data!L330, "ERROR") -> Sonchus oleraceus | M330: =IF(Data!N330 = 'Point Intercept 2'!M330, Data!N330, "ERROR") -> 0 | N330: =IF(Data!O330 = 'Point Intercept 2'!N330, Data!O330, "ERROR") -> 0 | O330: =IF(Data!P330 = 'Point Intercept 2'!O330, Data!P330, "ERROR") -> 0
A331: =IF(Data!A331 = 'Point Intercept 2'!A331, Data!A331, "ERROR") -> 4 | B331: =IF(Data!B331 = 'Point Intercept 2'!B331, Data!B331, "ERROR") -> 2025 | C331: =IF(Data!C331 = 'Point Intercept 2'!C331, Data!C331, "ERROR") -> 45755 | D331: =IF(Data!D331 = 'Point Intercept 2'!D331, Data!D331, "ERROR") -> JC, TL | E331: =IF(Data!E331 = 'Point Intercept 2'!E331, Data!E331, "ERROR") -> VB | F331: =IF(Data!F331 = 'Point Intercept 2'!F331, Data!F331, "ERROR") -> 3 | G331: =IF(Data!G331 = 'Point Intercept 2'!G331, Data!G331, "ERROR") -> LS | H331: =IF(Data!I331 = 'Point Intercept 2'!I331, Data!I331, "ERROR") -> 8 | I331: =IF(Data!H331 = 'Point Intercept 2'!H331, Data!H331, "ERROR") -> 1 | J331: =IF(Data!J331 = 'Point Intercept 2'!J331, Data!J331, "ERROR") -> 3.5 | K331: =IF(Data!K331 = 'Point Intercept 2'!K331, Data!K331, "ERROR") -> L | L331: =IF(Data!L331 = 'Point Intercept 2'!L331, Data!L331, "ERROR") -> Litter | M331: =IF(Data!N331 = 'Point Intercept 2'!M332, Data!N331, "ERROR") -> 0 | N331: =IF(Data!O331 = 'Point Intercept 2'!N332, Data!O331, "ERROR") -> 0 | O331: =IF(Data!P331 = 'Point Intercept 2'!O332, Data!P331, "ERROR") -> 0
A332: =IF(Data!A332 = 'Point Intercept 2'!A332, Data!A332, "ERROR") -> 4 | B332: =IF(Data!B332 = 'Point Intercept 2'!B332, Data!B332, "ERROR") -> 2025 | C332: =IF(Data!C332 = 'Point Intercept 2'!C332, Data!C332, "ERROR") -> 45755 | D332: =IF(Data!D332 = 'Point Intercept 2'!D332, Data!D332, "ERROR") -> JC, TL | E332: =IF(Data!E332 = 'Point Intercept 2'!E332, Data!E332, "ERROR") -> VB | F332: =IF(Data!F332 = 'Point Intercept 2'!F332, Data!F332, "ERROR") -> 3 | G332: =IF(Data!G332 = 'Point Intercept 2'!G332, Data!G332, "ERROR") -> LS | H332: =IF(Data!I332 = 'Point Intercept 2'!I332, Data!I332, "ERROR") -> 8 | I332: =IF(Data!H332 = 'Point Intercept 2'!H332, Data!H332, "ERROR") -> 1 | J332: =IF(Data!J332 = 'Point Intercept 2'!J332, Data!J332, "ERROR") -> 3.5 | K332: =IF(Data!K332 = 'Point Intercept 2'!K332, Data!K332, "ERROR") -> FESMYU | L332: =IF(Data!L332 = 'Point Intercept 2'!L332, Data!L332, "ERROR") -> Festuca myuros | M332: =IF(Data!N332 = 'Point Intercept 2'!M333, Data!N332, "ERROR") -> 0 | N332: =IF(Data!O332 = 'Point Intercept 2'!N333, Data!O332, "ERROR") -> 0 | O332: =IF(Data!P332 = 'Point Intercept 2'!O333, Data!P332, "ERROR") -> 0
A333: =IF(Data!A333 = 'Point Intercept 2'!A333, Data!A333, "ERROR") -> 4 | B333: =IF(Data!B333 = 'Point Intercept 2'!B333, Data!B333, "ERROR") -> 2025 | C333: =IF(Data!C333 = 'Point Intercept 2'!C333, Data!C333, "ERROR") -> 45755 | D333: =IF(Data!D333 = 'Point Intercept 2'!D333, Data!D333, "ERROR") -> JC, TL | E333: =IF(Data!E333 = 'Point Intercept 2'!E333, Data!E333, "ERROR") -> VB | F333: =IF(Data!F333 = 'Point Intercept 2'!F333, Data!F333, "ERROR") -> 3 | G333: =IF(Data!G333 = 'Point Intercept 2'!G333, Data!G333, "ERROR") -> LS | H333: =IF(Data!I333 = 'Point Intercept 2'!I333, Data!I333, "ERROR") -> 8 | I333: =IF(Data!H333 = 'Point Intercept 2'!H333, Data!H333, "ERROR") -> 1 | J333: =IF(Data!J333 = 'Point Intercept 2'!J333, Data!J333, "ERROR") -> 3.5 | K333: =IF(Data!K333 = 'Point Intercept 2'!K333, Data!K333, "ERROR") -> DEIFAS | L333: =IF(Data!L333 = 'Point Intercept 2'!L333, Data!L333, "ERROR") -> Deinandra fasciculata | M333: =IF(Data!N333 = 'Point Intercept 2'!M334, Data!N333, "ERROR") -> 0 | N333: =IF(Data!O333 = 'Point Intercept 2'!N334, Data!O333, "ERROR") -> 0 | O333: =IF(Data!P333 = 'Point Intercept 2'!O334, Data!P333, "ERROR") -> 0
A334: =IF(Data!A334 = 'Point Intercept 2'!A334, Data!A334, "ERROR") -> 4 | B334: =IF(Data!B334 = 'Point Intercept 2'!B334, Data!B334, "ERROR") -> 2025 | C334: =IF(Data!C334 = 'Point Intercept 2'!C334, Data!C334, "ERROR") -> 45755 | D334: =IF(Data!D334 = 'Point Intercept 2'!D334, Data!D334, "ERROR") -> JC, TL | E334: =IF(Data!E334 = 'Point Intercept 2'!E334, Data!E334, "ERROR") -> VB | F334: =IF(Data!F334 = 'Point Intercept 2'!F334, Data!F334, "ERROR") -> 3 | G334: =IF(Data!G334 = 'Point Intercept 2'!G334, Data!G334, "ERROR") -> LS | H334: =IF(Data!I334 = 'Point Intercept 2'!I334, Data!I334, "ERROR") -> 8 | I334: =IF(Data!H334 = 'Point Intercept 2'!H334, Data!H334, "ERROR") -> 1 | J334: =IF(Data!J334 = 'Point Intercept 2'!J334, Data!J334, "ERROR") -> 3.5 | K334: =IF(Data!K334 = 'Point Intercept 2'!K334, Data!K334, "ERROR") -> MEDPOL | L334: =IF(Data!L334 = 'Point Intercept 2'!L334, Data!L334, "ERROR") -> Medicago polymorpha | M334: =IF(Data!N334 = 'Point Intercept 2'!M335, Data!N334, "ERROR") -> 0 | N334: =IF(Data!O334 = 'Point Intercept 2'!N335, Data!O334, "ERROR") -> 0 | O334: =IF(Data!P334 = 'Point Intercept 2'!O335, Data!P334, "ERROR") -> 0
A335: =IF(Data!A335 = 'Point Intercept 2'!A335, Data!A335, "ERROR") -> 4 | B335: =IF(Data!B335 = 'Point Intercept 2'!B335, Data!B335, "ERROR") -> 2025 | C335: =IF(Data!C335 = 'Point Intercept 2'!C335, Data!C335, "ERROR") -> 45755 | D335: =IF(Data!D335 = 'Point Intercept 2'!D335, Data!D335, "ERROR") -> JC, TL | E335: =IF(Data!E335 = 'Point Intercept 2'!E335, Data!E335, "ERROR") -> VB | F335: =IF(Data!F335 = 'Point Intercept 2'!F335, Data!F335, "ERROR") -> 3 | G335: =IF(Data!G335 = 'Point Intercept 2'!G335, Data!G335, "ERROR") -> LS | H335: =IF(Data!I335 = 'Point Intercept 2'!I335, Data!I335, "ERROR") -> 9 | I335: =IF(Data!H335 = 'Point Intercept 2'!H335, Data!H335, "ERROR") -> 1 | J335: =IF(Data!J335 = 'Point Intercept 2'!J335, Data!J335, "ERROR") -> 4 | K335: =IF(Data!K335 = 'Point Intercept 2'!K335, Data!K335, "ERROR") -> L | L335: =IF(Data!L335 = 'Point Intercept 2'!L335, Data!L335, "ERROR") -> Litter | M335: =IF(Data!N335 = 'Point Intercept 2'!M336, Data!N335, "ERROR") -> 0 | N335: =IF(Data!O335 = 'Point Intercept 2'!N336, Data!O335, "ERROR") -> 0 | O335: =IF(Data!P335 = 'Point Intercept 2'!O336, Data!P335, "ERROR") -> 0
A336: =IF(Data!A336 = 'Point Intercept 2'!A336, Data!A336, "ERROR") -> 4 | B336: =IF(Data!B336 = 'Point Intercept 2'!B336, Data!B336, "ERROR") -> 2025 | C336: =IF(Data!C336 = 'Point Intercept 2'!C336, Data!C336, "ERROR") -> 45755 | D336: =IF(Data!D336 = 'Point Intercept 2'!D336, Data!D336, "ERROR") -> JC, TL | E336: =IF(Data!E336 = 'Point Intercept 2'!E336, Data!E336, "ERROR") -> VB | F336: =IF(Data!F336 = 'Point Intercept 2'!F336, Data!F336, "ERROR") -> 3 | G336: =IF(Data!G336 = 'Point Intercept 2'!G336, Data!G336, "ERROR") -> LS | H336: =IF(Data!I336 = 'Point Intercept 2'!I336, Data!I336, "ERROR") -> 9 | I336: =IF(Data!H336 = 'Point Intercept 2'!H336, Data!H336, "ERROR") -> 1 | J336: =IF(Data!J336 = 'Point Intercept 2'!J336, Data!J336, "ERROR") -> 4 | K336: =IF(Data!K336 = 'Point Intercept 2'!K336, Data!K336, "ERROR") -> MEDPOL | L336: =IF(Data!L336 = 'Point Intercept 2'!L336, Data!L336, "ERROR") -> Medicago polymorpha | M336: =IF(Data!N336 = 'Point Intercept 2'!M337, Data!N336, "ERROR") -> 0 | N336: =IF(Data!O336 = 'Point Intercept 2'!N337, Data!O336, "ERROR") -> 0 | O336: =IF(Data!P336 = 'Point Intercept 2'!O337, Data!P336, "ERROR") -> 0
A337: =IF(Data!A337 = 'Point Intercept 2'!A337, Data!A337, "ERROR") -> 4 | B337: =IF(Data!B337 = 'Point Intercept 2'!B337, Data!B337, "ERROR") -> 2025 | C337: =IF(Data!C337 = 'Point Intercept 2'!C337, Data!C337, "ERROR") -> 45755 | D337: =IF(Data!D337 = 'Point Intercept 2'!D337, Data!D337, "ERROR") -> JC, TL | E337: =IF(Data!E337 = 'Point Intercept 2'!E337, Data!E337, "ERROR") -> VB | F337: =IF(Data!F337 = 'Point Intercept 2'!F337, Data!F337, "ERROR") -> 3 | G337: =IF(Data!G337 = 'Point Intercept 2'!G337, Data!G337, "ERROR") -> LS | H337: =IF(Data!I337 = 'Point Intercept 2'!I337, Data!I337, "ERROR") -> 10 | I337: =IF(Data!H337 = 'Point Intercept 2'!H337, Data!H337, "ERROR") -> 1 | J337: =IF(Data!J337 = 'Point Intercept 2'!J337, Data!J337, "ERROR") -> 4.5 | K337: =IF(Data!K337 = 'Point Intercept 2'!K337, Data!K337, "ERROR") -> L | L337: =IF(Data!L337 = 'Point Intercept 2'!L337, Data!L337, "ERROR") -> Litter | M337: =IF(Data!N337 = 'Point Intercept 2'!M338, Data!N337, "ERROR") -> 0 | N337: =IF(Data!O337 = 'Point Intercept 2'!N338, Data!O337, "ERROR") -> 0 | O337: =IF(Data!P337 = 'Point Intercept 2'!O338, Data!P337, "ERROR") -> 0
A338: =IF(Data!A338 = 'Point Intercept 2'!A338, Data!A338, "ERROR") -> 4 | B338: =IF(Data!B338 = 'Point Intercept 2'!B338, Data!B338, "ERROR") -> 2025 | C338: =IF(Data!C338 = 'Point Intercept 2'!C338, Data!C338, "ERROR") -> 45755 | D338: =IF(Data!D338 = 'Point Intercept 2'!D338, Data!D338, "ERROR") -> JC, TL | E338: =IF(Data!E338 = 'Point Intercept 2'!E338, Data!E338, "ERROR") -> VB | F338: =IF(Data!F338 = 'Point Intercept 2'!F338, Data!F338, "ERROR") -> 3 | G338: =IF(Data!G338 = 'Point Intercept 2'!G338, Data!G338, "ERROR") -> LS | H338: =IF(Data!I338 = 'Point Intercept 2'!I338, Data!I338, "ERROR") -> 10 | I338: =IF(Data!H338 = 'Point Intercept 2'!H338, Data!H338, "ERROR") -> 1 | J338: =IF(Data!J338 = 'Point Intercept 2'!J338, Data!J338, "ERROR") -> 4.5 | K338: =IF(Data!K338 = 'Point Intercept 2'!K338, Data!K338, "ERROR") -> DAUPUS | L338: =IF(Data!L338 = 'Point Intercept 2'!L338, Data!L338, "ERROR") -> Daucus pusillus | M338: =IF(Data!N338 = 'Point Intercept 2'!M339, Data!N338, "ERROR") -> 0 | N338: =IF(Data!O338 = 'Point Intercept 2'!N339, Data!O338, "ERROR") -> 0 | O338: =IF(Data!P338 = 'Point Intercept 2'!O339, Data!P338, "ERROR") -> 0
A339: =IF(Data!A339 = 'Point Intercept 2'!A339, Data!A339, "ERROR") -> 4 | B339: =IF(Data!B339 = 'Point Intercept 2'!B339, Data!B339, "ERROR") -> 2025 | C339: =IF(Data!C339 = 'Point Intercept 2'!C339, Data!C339, "ERROR") -> 45755 | D339: =IF(Data!D339 = 'Point Intercept 2'!D339, Data!D339, "ERROR") -> JC, TL | E339: =IF(Data!E339 = 'Point Intercept 2'!E339, Data!E339, "ERROR") -> VB | F339: =IF(Data!F339 = 'Point Intercept 2'!F339, Data!F339, "ERROR") -> 3 | G339: =IF(Data!G339 = 'Point Intercept 2'!G339, Data!G339, "ERROR") -> LS | H339: =IF(Data!I339 = 'Point Intercept 2'!I339, Data!I339, "ERROR") -> 10 | I339: =IF(Data!H339 = 'Point Intercept 2'!H339, Data!H339, "ERROR") -> 1 | J339: =IF(Data!J339 = 'Point Intercept 2'!J339, Data!J339, "ERROR") -> 4.5 | K339: =IF(Data!K339 = 'Point Intercept 2'!K339, Data!K339, "ERROR") -> DEIFAS | L339: =IF(Data!L339 = 'Point Intercept 2'!L339, Data!L339, "ERROR") -> Deinandra fasciculata | M339: =IF(Data!N339 = 'Point Intercept 2'!M340, Data!N339, "ERROR") -> 0 | N339: =IF(Data!O339 = 'Point Intercept 2'!N340, Data!O339, "ERROR") -> 0 | O339: =IF(Data!P339 = 'Point Intercept 2'!O340, Data!P339, "ERROR") -> 0
A340: =IF(Data!A340 = 'Point Intercept 2'!A340, Data!A340, "ERROR") -> 4 | B340: =IF(Data!B340 = 'Point Intercept 2'!B340, Data!B340, "ERROR") -> 2025 | C340: =IF(Data!C340 = 'Point Intercept 2'!C340, Data!C340, "ERROR") -> 45755 | D340: =IF(Data!D340 = 'Point Intercept 2'!D340, Data!D340, "ERROR") -> JC, TL | E340: =IF(Data!E340 = 'Point Intercept 2'!E340, Data!E340, "ERROR") -> VB | F340: =IF(Data!F340 = 'Point Intercept 2'!F340, Data!F340, "ERROR") -> 3 | G340: =IF(Data!G340 = 'Point Intercept 2'!G340, Data!G340, "ERROR") -> LS | H340: =IF(Data!I340 = 'Point Intercept 2'!I340, Data!I340, "ERROR") -> 10 | I340: =IF(Data!H340 = 'Point Intercept 2'!H340, Data!H340, "ERROR") -> 1 | J340: =IF(Data!J340 = 'Point Intercept 2'!J340, Data!J340, "ERROR") -> 4.5 | K340: =IF(Data!K340 = 'Point Intercept 2'!K340, Data!K340, "ERROR") -> FESMYU | L340: =IF(Data!L340 = 'Point Intercept 2'!L340, Data!L340, "ERROR") -> Festuca myuros | M340: =IF(Data!N340 = 'Point Intercept 2'!M341, Data!N340, "ERROR") -> 0 | N340: =IF(Data!O340 = 'Point Intercept 2'!N341, Data!O340, "ERROR") -> 0 | O340: =IF(Data!P340 = 'Point Intercept 2'!O341, Data!P340, "ERROR") -> 0
A341: =IF(Data!A341 = 'Point Intercept 2'!A341, Data!A341, "ERROR") -> 4 | B341: =IF(Data!B341 = 'Point Intercept 2'!B341, Data!B341, "ERROR") -> 2025 | C341: =IF(Data!C341 = 'Point Intercept 2'!C341, Data!C341, "ERROR") -> 45755 | D341: =IF(Data!D341 = 'Point Intercept 2'!D341, Data!D341, "ERROR") -> JC, TL | E341: =IF(Data!E341 = 'Point Intercept 2'!E341, Data!E341, "ERROR") -> VB | F341: =IF(Data!F341 = 'Point Intercept 2'!F341, Data!F341, "ERROR") -> 3 | G341: =IF(Data!G341 = 'Point Intercept 2'!G341, Data!G341, "ERROR") -> LS | H341: =IF(Data!I341 = 'Point Intercept 2'!I341, Data!I341, "ERROR") -> 11 | I341: =IF(Data!H341 = 'Point Intercept 2'!H341, Data!H341, "ERROR") -> 1 | J341: =IF(Data!J341 = 'Point Intercept 2'!J341, Data!J341, "ERROR") -> 5 | K341: =IF(Data!K341 = 'Point Intercept 2'!K341, Data!K341, "ERROR") -> L | L341: =IF(Data!L341 = 'Point Intercept 2'!L341, Data!L341, "ERROR") -> Litter | M341: =IF(Data!N341 = 'Point Intercept 2'!M342, Data!N341, "ERROR") -> 0 | N341: =IF(Data!O341 = 'Point Intercept 2'!N342, Data!O341, "ERROR") -> 0 | O341: =IF(Data!P341 = 'Point Intercept 2'!O342, Data!P341, "ERROR") -> 0
A342: =IF(Data!A342 = 'Point Intercept 2'!A342, Data!A342, "ERROR") -> 4 | B342: =IF(Data!B342 = 'Point Intercept 2'!B342, Data!B342, "ERROR") -> 2025 | C342: =IF(Data!C342 = 'Point Intercept 2'!C342, Data!C342, "ERROR") -> 45755 | D342: =IF(Data!D342 = 'Point Intercept 2'!D342, Data!D342, "ERROR") -> JC, TL | E342: =IF(Data!E342 = 'Point Intercept 2'!E342, Data!E342, "ERROR") -> VB | F342: =IF(Data!F342 = 'Point Intercept 2'!F342, Data!F342, "ERROR") -> 3 | G342: =IF(Data!G342 = 'Point Intercept 2'!G342, Data!G342, "ERROR") -> LS | H342: =IF(Data!I342 = 'Point Intercept 2'!I342, Data!I342, "ERROR") -> 11 | I342: =IF(Data!H342 = 'Point Intercept 2'!H342, Data!H342, "ERROR") -> 1 | J342: =IF(Data!J342 = 'Point Intercept 2'!J342, Data!J342, "ERROR") -> 5 | K342: =IF(Data!K342 = 'Point Intercept 2'!K342, Data!K342, "ERROR") -> FESMYU | L342: =IF(Data!L342 = 'Point Intercept 2'!L342, Data!L342, "ERROR") -> Festuca myuros | M342: =IF(Data!N342 = 'Point Intercept 2'!M343, Data!N342, "ERROR") -> 0 | N342: =IF(Data!O342 = 'Point Intercept 2'!N343, Data!O342, "ERROR") -> 0 | O342: =IF(Data!P342 = 'Point Intercept 2'!O343, Data!P342, "ERROR") -> 0
... A445: =IF(Data!A445 = 'Point Intercept 2'!A445, Data!A445, "ERROR") -> 5 | B445: =IF(Data!B445 = 'Point Intercept 2'!B445, Data!B445, "ERROR") -> 2025 | C445: =IF(Data!C445 = 'Point Intercept 2'!C445, Data!C445, "ERROR") -> 45755 | D445: =IF(Data!D445 = 'Point Intercept 2'!D445, Data!D445, "ERROR") -> TL, JC | E445: =IF(Data!E445 = 'Point Intercept 2'!E445, Data!E445, "ERROR") -> VB | F445: =IF(Data!F445 = 'Point Intercept 2'!F445, Data!F445, "ERROR") -> 3 | G445: =IF(Data!G445 = 'Point Intercept 2'!G445, Data!G445, "ERROR") -> SS | H445: =IF(Data!I445 = 'Point Intercept 2'!I445, Data!I445, "ERROR") -> 12 | I445: =IF(Data!H445 = 'Point Intercept 2'!H445, Data!H445, "ERROR") -> 1 | J445: =IF(Data!J445 = 'Point Intercept 2'!J445, Data!J445, "ERROR") -> 9 | K445: =IF(Data!K445 = 'Point Intercept 2'!K445, Data!K445, "ERROR") -> L | L445: =IF(Data!L445 = 'Point Intercept 2'!L445, Data!L445, "ERROR") -> Litter | M445: =IF(Data!N445 = 'Point Intercept 2'!M446, Data!N445, "ERROR") -> 0 | N445: =IF(Data!O445 = 'Point Intercept 2'!N446, Data!O445, "ERROR") -> 0 | O445: =IF(Data!P445 = 'Point Intercept 2'!O446, Data!P445, "ERROR") -> 0
A446: =IF(Data!A446 = 'Point Intercept 2'!A446, Data!A446, "ERROR") -> 5 | B446: =IF(Data!B446 = 'Point Intercept 2'!B446, Data!B446, "ERROR") -> 2025 | C446: =IF(Data!C446 = 'Point Intercept 2'!C446, Data!C446, "ERROR") -> 45755 | D446: =IF(Data!D446 = 'Point Intercept 2'!D446, Data!D446, "ERROR") -> TL, JC | E446: =IF(Data!E446 = 'Point Intercept 2'!E446, Data!E446, "ERROR") -> VB | F446: =IF(Data!F446 = 'Point Intercept 2'!F446, Data!F446, "ERROR") -> 3 | G446: =IF(Data!G446 = 'Point Intercept 2'!G446, Data!G446, "ERROR") -> SS | H446: =IF(Data!I446 = 'Point Intercept 2'!I446, Data!I446, "ERROR") -> 12 | I446: =IF(Data!H446 = 'Point Intercept 2'!H446, Data!H446, "ERROR") -> 1 | J446: =IF(Data!J446 = 'Point Intercept 2'!J446, Data!J446, "ERROR") -> 9 | K446: =IF(Data!K446 = 'Point Intercept 2'!K446, Data!K446, "ERROR") -> SONASP | L446: =IF(Data!L446 = 'Point Intercept 2'!L446, Data!L446, "ERROR") -> Sonchus asper
A447: =IF(Data!A447 = 'Point Intercept 2'!A447, Data!A447, "ERROR") -> 5 | B447: =IF(Data!B447 = 'Point Intercept 2'!B447, Data!B447, "ERROR") -> 2025 | C447: =IF(Data!C447 = 'Point Intercept 2'!C447, Data!C447, "ERROR") -> 45755 | D447: =IF(Data!D447 = 'Point Intercept 2'!D447, Data!D447, "ERROR") -> TL, JC | E447: =IF(Data!E447 = 'Point Intercept 2'!E447, Data!E447, "ERROR") -> VB | F447: =IF(Data!F447 = 'Point Intercept 2'!F447, Data!F447, "ERROR") -> 3 | G447: =IF(Data!G447 = 'Point Intercept 2'!G447, Data!G447, "ERROR") -> SS | H447: =IF(Data!I447 = 'Point Intercept 2'!I447, Data!I447, "ERROR") -> 13 | I447: =IF(Data!H447 = 'Point Intercept 2'!H447, Data!H447, "ERROR") -> 1 | J447: =IF(Data!J447 = 'Point Intercept 2'!J447, Data!J447, "ERROR") -> 10 | K447: =IF(Data!K447 = 'Point Intercept 2'!K447, Data!K447, "ERROR") -> L | L447: =IF(Data!L447 = 'Point Intercept 2'!L447, Data!L447, "ERROR") -> Litter
A448: =IF(Data!A448 = 'Point Intercept 2'!A448, Data!A448, "ERROR") -> 5 | B448: =IF(Data!B448 = 'Point Intercept 2'!B448, Data!B448, "ERROR") -> 2025 | C448: =IF(Data!C448 = 'Point Intercept 2'!C448, Data!C448, "ERROR") -> 45755 | D448: =IF(Data!D448 = 'Point Intercept 2'!D448, Data!D448, "ERROR") -> TL, JC | E448: =IF(Data!E448 = 'Point Intercept 2'!E448, Data!E448, "ERROR") -> VB | F448: =IF(Data!F448 = 'Point Intercept 2'!F448, Data!F448, "ERROR") -> 3 | G448: =IF(Data!G448 = 'Point Intercept 2'!G448, Data!G448, "ERROR") -> SS | H448: =IF(Data!I448 = 'Point Intercept 2'!I448, Data!I448, "ERROR") -> 13 | I448: =IF(Data!H448 = 'Point Intercept 2'!H448, Data!H448, "ERROR") -> 1 | J448: =IF(Data!J448 = 'Point Intercept 2'!J448, Data!J448, "ERROR") -> 10 | K448: =IF(Data!K448 = 'Point Intercept 2'!K448, Data!K448, "ERROR") -> SONASP | L448: =IF(Data!L448 = 'Point Intercept 2'!L448, Data!L448, "ERROR") -> Sonchus asper
A449: =IF(Data!A449 = 'Point Intercept 2'!A449, Data!A449, "ERROR") -> 5 | B449: =IF(Data!B449 = 'Point Intercept 2'!B449, Data!B449, "ERROR") -> 2025 | C449: =IF(Data!C449 = 'Point Intercept 2'!C449, Data!C449, "ERROR") -> 45755 | D449: =IF(Data!D449 = 'Point Intercept 2'!D449, Data!D449, "ERROR") -> TL, JC | E449: =IF(Data!E449 = 'Point Intercept 2'!E449, Data!E449, "ERROR") -> VB | F449: =IF(Data!F449 = 'Point Intercept 2'!F449, Data!F449, "ERROR") -> 3 | G449: =IF(Data!G449 = 'Point Intercept 2'!G449, Data!G449, "ERROR") -> SS | H449: =IF(Data!I449 = 'Point Intercept 2'!I449, Data!I449, "ERROR") -> 14 | I449: =IF(Data!H449 = 'Point Intercept 2'!H449, Data!H449, "ERROR") -> 1 | J449: =IF(Data!J449 = 'Point Intercept 2'!J449, Data!J449, "ERROR") -> 11 | K449: =IF(Data!K449 = 'Point Intercept 2'!K449, Data!K449, "ERROR") -> B | L449: =IF(Data!L449 = 'Point Intercept 2'!L449, Data!L449, "ERROR") -> Bareground
A450: =IF(Data!A450 = 'Point Intercept 2'!A450, Data!A450, "ERROR") -> 5 | B450: =IF(Data!B450 = 'Point Intercept 2'!B450, Data!B450, "ERROR") -> 2025 | C450: =IF(Data!C450 = 'Point Intercept 2'!C450, Data!C450, "ERROR") -> 45755 | D450: =IF(Data!D450 = 'Point Intercept 2'!D450, Data!D450, "ERROR") -> TL, JC | E450: =IF(Data!E450 = 'Point Intercept 2'!E450, Data!E450, "ERROR") -> VB | F450: =IF(Data!F450 = 'Point Intercept 2'!F450, Data!F450, "ERROR") -> 3 | G450: =IF(Data!G450 = 'Point Intercept 2'!G450, Data!G450, "ERROR") -> SS | H450: =IF(Data!I450 = 'Point Intercept 2'!I450, Data!I450, "ERROR") -> 15 | I450: =IF(Data!H450 = 'Point Intercept 2'!H450, Data!H450, "ERROR") -> 1 | J450: =IF(Data!J450 = 'Point Intercept 2'!J450, Data!J450, "ERROR") -> 12 | K450: =IF(Data!K450 = 'Point Intercept 2'!K450, Data!K450, "ERROR") -> B | L450: =IF(Data!L450 = 'Point Intercept 2'!L450, Data!L450, "ERROR") -> Bareground
A451: =IF(Data!A451 = 'Point Intercept 2'!A451, Data!A451, "ERROR") -> 5 | B451: =IF(Data!B451 = 'Point Intercept 2'!B451, Data!B451, "ERROR") -> 2025 | C451: =IF(Data!C451 = 'Point Intercept 2'!C451, Data!C451, "ERROR") -> 45755 | D451: =IF(Data!D451 = 'Point Intercept 2'!D451, Data!D451, "ERROR") -> TL, JC | E451: =IF(Data!E451 = 'Point Intercept 2'!E451, Data!E451, "ERROR") -> VB | F451: =IF(Data!F451 = 'Point Intercept 2'!F451, Data!F451, "ERROR") -> 3 | G451: =IF(Data!G451 = 'Point Intercept 2'!G451, Data!G451, "ERROR") -> SS | H451: =IF(Data!I451 = 'Point Intercept 2'!I451, Data!I451, "ERROR") -> 1 | I451: =IF(Data!H451 = 'Point Intercept 2'!H451, Data!H451, "ERROR") -> 2 | J451: =IF(Data!J451 = 'Point Intercept 2'!J451, Data!J451, "ERROR") -> 0 | K451: =IF(Data!K451 = 'Point Intercept 2'!K451, Data!K451, "ERROR") -> L | L451: =IF(Data!L451 = 'Point Intercept 2'!L451, Data!L451, "ERROR") -> Litter
A452: =IF(Data!A452 = 'Point Intercept 2'!A452, Data!A452, "ERROR") -> 5 | B452: =IF(Data!B452 = 'Point Intercept 2'!B452, Data!B452, "ERROR") -> 2025 | C452: =IF(Data!C452 = 'Point Intercept 2'!C452, Data!C452, "ERROR") -> 45755 | D452: =IF(Data!D452 = 'Point Intercept 2'!D452, Data!D452, "ERROR") -> TL, JC | E452: =IF(Data!E452 = 'Point Intercept 2'!E452, Data!E452, "ERROR") -> VB | F452: =IF(Data!F452 = 'Point Intercept 2'!F452, Data!F452, "ERROR") -> 3 | G452: =IF(Data!G452 = 'Point Intercept 2'!G452, Data!G452, "ERROR") -> SS | H452: =IF(Data!I452 = 'Point Intercept 2'!I452, Data!I452, "ERROR") -> 1 | I452: =IF(Data!H452 = 'Point Intercept 2'!H452, Data!H452, "ERROR") -> 2 | J452: =IF(Data!J452 = 'Point Intercept 2'!J452, Data!J452, "ERROR") -> 0 | K452: =IF(Data!K452 = 'Point Intercept 2'!K452, Data!K452, "ERROR") -> CYLPRO | L452: =IF(Data!L452 = 'Point Intercept 2'!L452, Data!L452, "ERROR") -> Cylindropuntia prolifera
A453: =IF(Data!A453 = 'Point Intercept 2'!A453, Data!A453, "ERROR") -> 5 | B453: =IF(Data!B453 = 'Point Intercept 2'!B453, Data!B453, "ERROR") -> 2025 | C453: =IF(Data!C453 = 'Point Intercept 2'!C453, Data!C453, "ERROR") -> 45755 | D453: =IF(Data!D453 = 'Point Intercept 2'!D453, Data!D453, "ERROR") -> TL, JC | E453: =IF(Data!E453 = 'Point Intercept 2'!E453, Data!E453, "ERROR") -> VB | F453: =IF(Data!F453 = 'Point Intercept 2'!F453, Data!F453, "ERROR") -> 3 | G453: =IF(Data!G453 = 'Point Intercept 2'!G453, Data!G453, "ERROR") -> SS | H453: =IF(Data!I453 = 'Point Intercept 2'!I453, Data!I453, "ERROR") -> 1 | I453: =IF(Data!H453 = 'Point Intercept 2'!H453, Data!H453, "ERROR") -> 2 | J453: =IF(Data!J453 = 'Point Intercept 2'!J453, Data!J453, "ERROR") -> 0 | K453: =IF(Data!K453 = 'Point Intercept 2'!K453, Data!K453, "ERROR") -> MEDPOL | L453: =IF(Data!L453 = 'Point Intercept 2'!L453, Data!L453, "ERROR") -> Medicago polymorpha
A454: =IF(Data!A454 = 'Point Intercept 2'!A454, Data!A454, "ERROR") -> 5 | B454: =IF(Data!B454 = 'Point Intercept 2'!B454, Data!B454, "ERROR") -> 2025 | C454: =IF(Data!C454 = 'Point Intercept 2'!C454, Data!C454, "ERROR") -> 45755 | D454: =IF(Data!D454 = 'Point Intercept 2'!D454, Data!D454, "ERROR") -> TL, JC | E454: =IF(Data!E454 = 'Point Intercept 2'!E454, Data!E454, "ERROR") -> VB | F454: =IF(Data!F454 = 'Point Intercept 2'!F454, Data!F454, "ERROR") -> 3 | G454: =IF(Data!G454 = 'Point Intercept 2'!G454, Data!G454, "ERROR") -> SS | H454: =IF(Data!I454 = 'Point Intercept 2'!I454, Data!I454, "ERROR") -> 1 | I454: =IF(Data!H454 = 'Point Intercept 2'!H454, Data!H454, "ERROR") -> 2 | J454: =IF(Data!J454 = 'Point Intercept 2'!J454, Data!J454, "ERROR") -> 0 | K454: =IF(Data!K454 = 'Point Intercept 2'!K454, Data!K454, "ERROR") -> FESMYU | L454: =IF(Data!L454 = 'Point Intercept 2'!L454, Data!L454, "ERROR") -> Festuca myuros
A455: =IF(Data!A455 = 'Point Intercept 2'!A455, Data!A455, "ERROR") -> 5 | B455: =IF(Data!B455 = 'Point Intercept 2'!B455, Data!B455, "ERROR") -> 2025 | C455: =IF(Data!C455 = 'Point Intercept 2'!C455, Data!C455, "ERROR") -> 45755 | D455: =IF(Data!D455 = 'Point Intercept 2'!D455, Data!D455, "ERROR") -> TL, JC | E455: =IF(Data!E455 = 'Point Intercept 2'!E455, Data!E455, "ERROR") -> VB | F455: =IF(Data!F455 = 'Point Intercept 2'!F455, Data!F455, "ERROR") -> 3 | G455: =IF(Data!G455 = 'Point Intercept 2'!G455, Data!G455, "ERROR") -> SS | H455: =IF(Data!I455 = 'Point Intercept 2'!I455, Data!I455, "ERROR") -> 1 | I455: =IF(Data!H455 = 'Point Intercept 2'!H455, Data!H455, "ERROR") -> 2 | J455: =IF(Data!J455 = 'Point Intercept 2'!J455, Data!J455, "ERROR") -> 0 | K455: =IF(Data!K455 = 'Point Intercept 2'!K455, Data!K455, "ERROR") -> SONOLE | L455: =IF(Data!L455 = 'Point Intercept 2'!L455, Data!L455, "ERROR") -> Sonchus oleraceus
A456: =IF(Data!A456 = 'Point Intercept 2'!A456, Data!A456, "ERROR") -> 5 | B456: =IF(Data!B456 = 'Point Intercept 2'!B456, Data!B456, "ERROR") -> 2025 | C456: =IF(Data!C456 = 'Point Intercept 2'!C456, Data!C456, "ERROR") -> 45755 | D456: =IF(Data!D456 = 'Point Intercept 2'!D456, Data!D456, "ERROR") -> TL, JC | E456: =IF(Data!E456 = 'Point Intercept 2'!E456, Data!E456, "ERROR") -> VB | F456: =IF(Data!F456 = 'Point Intercept 2'!F456, Data!F456, "ERROR") -> 3 | G456: =IF(Data!G456 = 'Point Intercept 2'!G456, Data!G456, "ERROR") -> SS | H456: =IF(Data!I456 = 'Point Intercept 2'!I456, Data!I456, "ERROR") -> 2 | I456: =IF(Data!H456 = 'Point Intercept 2'!H456, Data!H456, "ERROR") -> 2 | J456: =IF(Data!J456 = 'Point Intercept 2'!J456, Data!J456, "ERROR") -> 1 | K456: =IF(Data!K456 = 'Point Intercept 2'!K456, Data!K456, "ERROR") -> L | L456: =IF(Data!L456 = 'Point Intercept 2'!L456, Data!L456, "ERROR") -> Litter
A457: =IF(Data!A457 = 'Point Intercept 2'!A457, Data!A457, "ERROR") -> 5 | B457: =IF(Data!B457 = 'Point Intercept 2'!B457, Data!B457, "ERROR") -> 2025 | C457: =IF(Data!C457 = 'Point Intercept 2'!C457, Data!C457, "ERROR") -> 45755 | D457: =IF(Data!D457 = 'Point Intercept 2'!D457, Data!D457, "ERROR") -> TL, JC | E457: =IF(Data!E457 = 'Point Intercept 2'!E457, Data!E457, "ERROR") -> VB | F457: =IF(Data!F457 = 'Point Intercept 2'!F457, Data!F457, "ERROR") -> 3 | G457: =IF(Data!G457 = 'Point Intercept 2'!G457, Data!G457, "ERROR") -> SS | H457: =IF(Data!I457 = 'Point Intercept 2'!I457, Data!I457, "ERROR") -> 2 | I457: =IF(Data!H457 = 'Point Intercept 2'!H457, Data!H457, "ERROR") -> 2 | J457: =IF(Data!J457 = 'Point Intercept 2'!J457, Data!J457, "ERROR") -> 1 | K457: =IF(Data!K457 = 'Point Intercept 2'!K457, Data!K457, "ERROR") -> SONOLE | L457: =IF(Data!L457 = 'Point Intercept 2'!L457, Data!L457, "ERROR") -> Sonchus oleraceus
... A861: =IF(Data!A861 = 'Point Intercept 2'!A861, Data!A861, "ERROR") -> 10 | B861: =IF(Data!B861 = 'Point Intercept 2'!B861, Data!B861, "ERROR") -> 2025 | C861: =IF(Data!C861 = 'Point Intercept 2'!C861, Data!C861, "ERROR") -> 45777 | D861: =IF(Data!D861 = 'Point Intercept 2'!D861, Data!D861, "ERROR") -> CG, JD | E861: =IF(Data!E861 = 'Point Intercept 2'!E861, Data!E861, "ERROR") -> CU | F861: =IF(Data!F861 = 'Point Intercept 2'!F861, Data!F861, "ERROR") -> 1 | G861: =IF(Data!G861 = 'Point Intercept 2'!G861, Data!G861, "ERROR") -> LU | H861: =IF(Data!I861 = 'Point Intercept 2'!I861, Data!I861, "ERROR") -> 1 | I861: =IF(Data!H861 = 'Point Intercept 2'!H861, Data!H861, "ERROR") -> 1 | J861: =IF(Data!J861 = 'Point Intercept 2'!J861, Data!J861, "ERROR") -> 0 | K861: =IF(Data!K861 = 'Point Intercept 2'!K861, Data!K861, "ERROR") -> EROMOS | L861: =IF(Data!L861 = 'Point Intercept 2'!L861, Data!L861, "ERROR") -> Erodium moschatum
A862: =IF(Data!A863 = 'Point Intercept 2'!A862, Data!A863, "ERROR") -> 10 | B862: =IF(Data!B863 = 'Point Intercept 2'!B862, Data!B863, "ERROR") -> 2025 | C862: =IF(Data!C863 = 'Point Intercept 2'!C862, Data!C863, "ERROR") -> 45777 | D862: =IF(Data!D863 = 'Point Intercept 2'!D862, Data!D863, "ERROR") -> CG, JD | E862: =IF(Data!E863 = 'Point Intercept 2'!E862, Data!E863, "ERROR") -> CU | F862: =IF(Data!F863 = 'Point Intercept 2'!F862, Data!F863, "ERROR") -> 1 | G862: =IF(Data!G862 = 'Point Intercept 2'!G862, Data!G862, "ERROR") -> LU | H862: =IF(Data!I862 = 'Point Intercept 2'!I862, Data!I862, "ERROR") -> 1 | I862: =IF(Data!H862 = 'Point Intercept 2'!H862, Data!H862, "ERROR") -> 1 | J862: =IF(Data!J862 = 'Point Intercept 2'!J862, Data!J862, "ERROR") -> 0 | K862: =IF(Data!K862 = 'Point Intercept 2'!K862, Data!K862, "ERROR") -> FESMYU | L862: =IF(Data!L862 = 'Point Intercept 2'!L862, Data!L862, "ERROR") -> Festuca myuros
...

Sheet Alphabetical by species code
A1: Species Code (A-Z) | B1: Full Scientific Name (Genus species) | C1: Native/Non-Native | D1: Common Name | E1: other scientific names | F1: Plant Family
A2: . | B2: . | C2: . | D2: . | E2: . | F2: .
A3: ACHMIL | B3: Achillea millefolium | C3: Native | D3: Yarrow | E3: . | F3: Asteraceae
A4: ACMAME | B4: Acmispon americanus | C4: Native | D4: American bird's foot trefoil | E4: Lotus purshianus | F4: Fabaceae
A5: ACMGLA | B5: Acmispon glaber | C5: Native | D5: Deerweed, California Broom | E5: Lotus scoparius | F5: Fabaceae
A6: ACMMAR | B6: Acmispon maritimus | C6: Native | D6: Coastal Lotus | E6: Lotus salsuginosus | F6: Fabaceae
A7: ACMMIC | B7: Acmicspon micranthus | C7: Native | D7: Small flowered lotus, grab lotus | E7: Lotus hamatus | F7: Fabaceae
A8: ACMPRO | B8: Acmispon prostratus | C8: Native | D8: prostrate lotus | F8: Fabaceae
A9: ACMSPP | B9: Acmispon species | C9: Native | D9: bird's foot trefoil | E9: . | F9: Fabaceae
A10: ACMSTR | B10: Acmispon strigosus | C10: Native | D10: Strigose lotus | E10: Lotus strigosus | F10: Fabaceae
A11: ACMWRA | B11: Acmispon wrangelianus | C11: Native | F11: Fabaceae
A12: ACOMIC | B12: Acourtia microcephala | C12: Native | D12: Sacapellote | E12: . | F12: Asteraceae
A13: ADEFAS | B13: Adenostoma fasciculatum | C13: Native | D13: Chamise | E13: . | F13: Rosaceae
A14: AGOGRA | B14: Agoseris grandiflora | C14: Native | D14: Large-flowered Mountain Dandelion | F14: Asteraceae
A15: AGOSPP | B15: Agoseris species | C15: Native | F15: Asteraceae
A16: AGRPAL | B16: Agrostis pallens | C16: Native | D16: bent grass | E16: . | F16: Poaceae
A17: ALLAMP | B17: Allium amplectens | C17: Native | D17: onion | F17: Alliaceae
A18: ALLGLU | B18: Allophyllum glutinosum | C18: Native | D18: sticky false gilia | F18: Polemoniaceae
A19: ALLPEN | B19: Allium peninsulare | C19: Native | D19: onion | F19: Alliaceae
A20: ALLPRA | B20: Allium praecox | C20: Native | D20: onion | F20: Alliaceae
A21: ALLSPP | B21: Allium species | C21: Native | D21: onion | F21: Alliaceae
A22: AMAALB | B22: Amaranthus albus | C22: Non-Native | D22: pigweed | E22: . | F22: Amaranthaceae
A23: AMBACA | B23: Ambrosia acanthicarpa | C23: Native | D23: ragweed | E23: . | F23: Asteraceae
A24: AMBCON | B24: Ambrosia confertiflora | C24: Native | D24: weak leaf burweed/ragweed | F24: Asteraceae
A25: AMBPSI | B25: Ambrosia psilostachya | C25: Native | D25: ragweed | E25: . | F25: Asteraceae
A26: AMOCAL | B26: Amorpha californica | C26: Native | D26: false indigo | E26: . | F26: Fabaceae
A27: AMOFRU | B27: Amorpha fruticosa | C27: Native | D27: western false indigo | E27: . | F27: Fabaceae
A28: AMSINT | B28: Amsinckia intermedia | C28: Native | D28: common fiddleneck | E28: . | F28: Boraginaceae
A29: AMSMEN | B29: Amsinckia menziesii | C29: Native | D29: fiddleneck | E29: . | F29: Boraginaceae
A30: AMSRET | B30: Amsinckia retrorsa | C30: Native | D30: Gray Fiddleneck | F30: Boraginaceae
A31: ANAARV | B31: Anagallis arvensis | C31: Non-Native | D31: scarlet pimpernel | E31: . | F31: Primulaceae
A32: ANECAL | B32: Anemopsis californica | C32: Native | D32: Yerba mansa | E32: . | F32: Saururaceae
A33: ANTCAU | B33: Anthriscus caucalis | C33: Non-Native | D33: Bur chervil | E33: . | F33: Apiaceae
A34: ANTCOU | B34: Antirrhinum coulterianum | C34: Native | D34: Coulter's snapdragon | E34: . | F34: Plantaginaceae
A35: ANTKEL | B35: Antirrhinum kelloggii | C35: Native | D35: climbing snapdragon | E35: . | F35: Plantaginaceae
A36: ANTNUT | B36: Antirrhinum nuttallianum | C36: Native | D36: Nuttall's snapdragon | E36: . | F36: Plantaginaceae
A37: APIANG | B37: Apiastrum angustifolium | C37: Native | D37: wild celery | E37: . | F37: Apiaceae
A38: APIGRA | B38: Apium graveolens | C38: Non-Native | D38: celery | E38: . | F38: Apiaceae
A39: APOCAN | B39: Apocynum cannabinum | C39: Native | D39: Indian hemp | E39: . | F39: Apocynaceae
A40: ARASER | B40: Araujia sericifera | C40: Non-Native | D40: bladder flower | E40: . | F40: Apocynaceae
...
